IsOTGPlus:true

Author: PG85

Description: No description given

Version: MCW104

SettingsMode: WriteDisable

Tree: false

Frequency: 1

RotateRandomly: false

SpawnHeight: highestBlock

MinHeight: 0

MaxHeight: 256

ExcludedBiomes: All

SourceBlocks: AIR

MaxPercentageOutsideSourceBlock: 100

OutsideSourceBlock: placeAnyway

InheritBO3: 

OverrideChildSettings: true

CanOverride: true

MustBeBelowOther: false

MustBeInside: we-jungletempledungeon16x16x8, we-jungletempledungeon16x16x8B

CannotBeInside:

CanSpawnOnWater: true

SpawnOnWaterOnly: false

SpawnUnderWater: false

SpawnAtWaterLevel: false

HeightOffset: 0

RemoveAir: false

ReplaceAbove: NONE

ReplaceBelow: 

ReplaceWithBiomeBlocks: true

ReplaceWithGroundBlock: DIRT

ReplaceWithSurfaceBlock: GRASS

SmoothRadius: -1

SmoothHeightOffset: 0

SmoothStartTop: false

SmoothStartWood: false

SmoothingSurfaceBlock: 

SmoothingGroundBlock: 

BO3Group: 

IsSpawnPoint: false

SpawnPointX: 8

SpawnPointY: -1

SpawnPointZ: 7

Block(-8,0,-7,MOSSY_COBBLESTONE,50,COBBLESTONE,100)
Block(-8,0,-6,MOSSY_COBBLESTONE,50,COBBLESTONE,100)
Block(-8,0,-5,MOSSY_COBBLESTONE,50,COBBLESTONE,100)
Block(-8,1,-7,MOSSY_COBBLESTONE,50,COBBLESTONE,100)
Block(-8,1,-6,MOSSY_COBBLESTONE,50,COBBLESTONE,100)
Block(-8,1,-5,MOSSY_COBBLESTONE,50,COBBLESTONE,100)
Block(-8,2,-7,MOSSY_COBBLESTONE,50,COBBLESTONE,100)
Block(-8,2,-6,MOSSY_COBBLESTONE,50,COBBLESTONE,100)
Block(-8,2,-5,98:3)
Block(-8,3,-7,MOSSY_COBBLESTONE,50,COBBLESTONE,100)
Block(-8,3,-6,MOSSY_COBBLESTONE,50,COBBLESTONE,100)
Block(-8,3,-5,98:3)
Block(-7,0,-7,MOSSY_COBBLESTONE,50,COBBLESTONE,100)
Block(-7,0,-6,MOSSY_COBBLESTONE,50,COBBLESTONE,100)
Block(-7,0,-5,MOSSY_COBBLESTONE,50,COBBLESTONE,100)
Block(-7,1,-7,MOSSY_COBBLESTONE,50,COBBLESTONE,100)
Block(-7,1,-6,MOSSY_COBBLESTONE,50,COBBLESTONE,100)
Block(-7,1,-5,109:1)
Block(-7,2,-7,MOSSY_COBBLESTONE,50,COBBLESTONE,100)
Block(-7,2,-6,118)
Block(-7,2,-5,106:2)
Block(-7,3,-7,MOSSY_COBBLESTONE,50,COBBLESTONE,100)
Block(-7,3,-6,106:2)
Block(-7,3,-5,106:2)
Block(-6,0,-7,MOSSY_COBBLESTONE,50,COBBLESTONE,100)
Block(-6,0,-6,MOSSY_COBBLESTONE,50,COBBLESTONE,100)
Block(-6,1,-7,MOSSY_COBBLESTONE,50,COBBLESTONE,100)
Block(-6,1,-6,109:3)
Block(-6,2,-7,98:3)
Block(-6,2,-6,106:4)
Block(-6,3,-7,98:3)
Block(-6,3,-6,106:4)
Block(-5,0,-7,MOSSY_COBBLESTONE,50,COBBLESTONE,100)
Block(-5,0,-6,MOSSY_COBBLESTONE,50,COBBLESTONE,100)
Block(-5,1,-7,109:1)
Block(-5,1,-6,109:1)
Block(-5,2,-7,106:2)
Block(-5,2,-6,0)
Block(-5,3,-7,106:2)
Block(-5,3,-6,0)
RandomBlock(-4,0,-7,STONEBRICK:1,50,STONEBRICK:2,100)
RandomBlock(-4,0,-6,STONEBRICK:1,50,STONEBRICK:2,100)
Block(-4,1,-7,0)
Block(-4,1,-6,0)
Block(-4,2,-7,0)
Block(-4,2,-6,0)
Block(-4,3,-7,0)
Block(-4,3,-6,0)
RandomBlock(-3,0,-7,STONEBRICK:1,50,STONEBRICK:2,100)
RandomBlock(-3,0,-6,STONEBRICK:1,50,STONEBRICK:2,100)
Block(-3,1,-7,0)
Block(-3,1,-6,0)
Block(-3,2,-7,0)
Block(-3,2,-6,0)
Block(-3,3,-7,0)
Block(-3,3,-6,0)
RandomBlock(-2,0,-7,STONEBRICK:1,50,STONEBRICK:2,100)
RandomBlock(-2,0,-6,STONEBRICK:1,50,STONEBRICK:2,100)
Block(-2,1,-7,0)
Block(-2,1,-6,0)
Block(-2,1,-5,0)
Block(-2,1,-4,0)
Block(-2,2,-7,0)
Block(-2,2,-6,0)
Block(-2,2,-5,0)
Block(-2,2,-4,0)
Block(-2,3,-7,0)
Block(-2,3,-6,0)
Block(-2,3,-5,0)
Block(-2,3,-4,0)
RandomBlock(-1,0,-7,STONEBRICK:1,50,STONEBRICK:2,100)
RandomBlock(-1,0,-6,STONEBRICK:1,50,STONEBRICK:2,100)
Block(-1,1,-7,0)
Block(-1,1,-6,0)
Block(-1,2,-7,0)
Block(-1,2,-6,0)
Block(-1,2,-5,0)
Block(-1,3,-7,0)
Block(-1,3,-6,0)
Block(-1,3,-5,0)
RandomBlock(0,0,-7,STONEBRICK:1,50,STONEBRICK:2,100)
RandomBlock(0,0,-6,STONEBRICK:1,50,STONEBRICK:2,100)
Block(0,1,-7,0)
Block(0,1,-6,0)
Block(0,2,-7,0)
Block(0,2,-6,0)
Block(0,2,-5,0)
Block(0,3,-7,0)
Block(0,3,-6,0)
Block(0,3,-5,0)
RandomBlock(1,0,-7,STONEBRICK:1,50,STONEBRICK:2,100)
RandomBlock(1,0,-6,STONEBRICK:1,50,STONEBRICK:2,100)
Block(1,1,-7,0)
Block(1,1,-6,0)
Block(1,1,-5,0)
Block(1,1,-4,0)
Block(1,2,-7,0)
Block(1,2,-6,0)
Block(1,2,-5,0)
Block(1,2,-4,0)
Block(1,3,-7,0)
Block(1,3,-6,0)
Block(1,3,-5,0)
Block(1,3,-4,0)
RandomBlock(2,0,-7,STONEBRICK:1,50,STONEBRICK:2,100)
RandomBlock(2,0,-6,STONEBRICK:1,50,STONEBRICK:2,100)
Block(2,1,-7,0)
Block(2,1,-6,0)
Block(2,2,-7,0)
Block(2,2,-6,0)
Block(2,3,-7,0)
Block(2,3,-6,0)
RandomBlock(3,0,-7,STONEBRICK:1,50,STONEBRICK:2,100)
RandomBlock(3,0,-6,STONEBRICK:1,50,STONEBRICK:2,100)
Block(3,1,-7,0)
Block(3,1,-6,0)
Block(3,2,-7,0)
Block(3,2,-6,0)
Block(3,3,-7,0)
Block(3,3,-6,0)
Block(4,0,-7,MOSSY_COBBLESTONE,50,COBBLESTONE,100)
Block(4,0,-6,MOSSY_COBBLESTONE,50,COBBLESTONE,100)
Block(4,1,-7,109)
Block(4,1,-6,109)
Block(4,2,-7,106:8)
Block(4,2,-6,0)
Block(4,3,-7,106:8)
Block(4,3,-6,0)
Block(5,0,-7,MOSSY_COBBLESTONE,50,COBBLESTONE,100)
Block(5,0,-6,MOSSY_COBBLESTONE,50,COBBLESTONE,100)
Block(5,1,-7,MOSSY_COBBLESTONE,50,COBBLESTONE,100)
Block(5,1,-6,109:3)
Block(5,2,-7,98:3)
Block(5,2,-6,106:4)
Block(5,3,-7,98:3)
Block(5,3,-6,106:4)
Block(6,0,-7,MOSSY_COBBLESTONE,50,COBBLESTONE,100)
Block(6,0,-6,MOSSY_COBBLESTONE,50,COBBLESTONE,100)
Block(6,0,-5,MOSSY_COBBLESTONE,50,COBBLESTONE,100)
Block(6,1,-7,MOSSY_COBBLESTONE,50,COBBLESTONE,100)
Block(6,1,-6,MOSSY_COBBLESTONE,50,COBBLESTONE,100)
Block(6,1,-5,109)
Block(6,2,-7,MOSSY_COBBLESTONE,50,COBBLESTONE,100)
Block(6,2,-6,118)
Block(6,2,-5,106:8)
Block(6,3,-7,MOSSY_COBBLESTONE,50,COBBLESTONE,100)
Block(6,3,-6,106:4)
Block(6,3,-5,106:8)
Block(7,0,-7,MOSSY_COBBLESTONE,50,COBBLESTONE,100)
Block(7,0,-6,MOSSY_COBBLESTONE,50,COBBLESTONE,100)
Block(7,0,-5,MOSSY_COBBLESTONE,50,COBBLESTONE,100)
Block(7,1,-7,MOSSY_COBBLESTONE,50,COBBLESTONE,100)
Block(7,1,-6,MOSSY_COBBLESTONE,50,COBBLESTONE,100)
Block(7,1,-5,MOSSY_COBBLESTONE,50,COBBLESTONE,100)
Block(7,2,-7,MOSSY_COBBLESTONE,50,COBBLESTONE,100)
Block(7,2,-6,MOSSY_COBBLESTONE,50,COBBLESTONE,100)
Block(7,2,-5,98:3)
Block(7,3,-7,MOSSY_COBBLESTONE,50,COBBLESTONE,100)
Block(7,3,-6,MOSSY_COBBLESTONE,50,COBBLESTONE,100)
Block(7,3,-5,98:3)