IsOTGPlus:true

Author: PG85

Description: No description given

Version: MCW104

SettingsMode: WriteDisable

Tree: false

Frequency: 1

RotateRandomly: false

SpawnHeight: highestBlock

MinHeight: 0

MaxHeight: 256

ExcludedBiomes: All

SourceBlocks: AIR

MaxPercentageOutsideSourceBlock: 100

OutsideSourceBlock: placeAnyway

InheritBO3: 

OverrideChildSettings: true

CanOverride: true

MustBeBelowOther: false

CanSpawnOnWater: true

SpawnOnWaterOnly: false

SpawnUnderWater: false

SpawnAtWaterLevel: false

HeightOffset: 0

RemoveAir: false

ReplaceAbove: NONE

ReplaceBelow: 

ReplaceWithBiomeBlocks: true

ReplaceWithGroundBlock: DIRT

ReplaceWithSurfaceBlock: GRASS

SmoothRadius: -1

SmoothHeightOffset: 0

SmoothStartTop: false

SmoothStartWood: false

SmoothingSurfaceBlock: 

SmoothingGroundBlock: 

BO3Group: 

IsSpawnPoint: false

SpawnPointX: 8

SpawnPointY: -1

SpawnPointZ: 7

Block(-8,0,-2,MOSSY_COBBLESTONE,50,COBBLESTONE,100)
Block(-8,0,-1,MOSSY_COBBLESTONE,50,COBBLESTONE,100)
Block(-8,0,0,MOSSY_COBBLESTONE,50,COBBLESTONE,100)
Block(-8,0,1,MOSSY_COBBLESTONE,50,COBBLESTONE,100)
Block(-8,0,2,MOSSY_COBBLESTONE,50,COBBLESTONE,100)
Block(-8,0,3,MOSSY_COBBLESTONE,50,COBBLESTONE,100)
Block(-8,1,-2,MOSSY_COBBLESTONE,50,COBBLESTONE,100)
Block(-8,1,-1,MOSSY_COBBLESTONE,50,COBBLESTONE,100)
Block(-8,1,0,MOSSY_COBBLESTONE,50,COBBLESTONE,100)
Block(-8,1,1,MOSSY_COBBLESTONE,50,COBBLESTONE,100)
Block(-8,1,2,MOSSY_COBBLESTONE,50,COBBLESTONE,100)
Block(-8,1,3,MOSSY_COBBLESTONE,50,COBBLESTONE,100)
Block(-8,2,-2,SMOOTH_BRICK:3)
Block(-8,2,-1,MOSSY_COBBLESTONE,50,COBBLESTONE,100)
Block(-8,2,0,MOSSY_COBBLESTONE,50,COBBLESTONE,100)
Block(-8,2,1,MOSSY_COBBLESTONE,50,COBBLESTONE,100)
Block(-8,2,2,MOSSY_COBBLESTONE,50,COBBLESTONE,100)
Block(-8,2,3,SMOOTH_BRICK:3)
Block(-8,3,-2,SMOOTH_BRICK:3)
Block(-8,3,-1,MOSSY_COBBLESTONE,50,COBBLESTONE,100)
Block(-8,3,0,MOSSY_COBBLESTONE,50,COBBLESTONE,100)
Block(-8,3,1,MOSSY_COBBLESTONE,50,COBBLESTONE,100)
Block(-8,3,2,MOSSY_COBBLESTONE,50,COBBLESTONE,100)
Block(-8,3,3,SMOOTH_BRICK:3)
Block(-8,4,-2,MOSSY_COBBLESTONE,50,COBBLESTONE,100)
Block(-8,4,-1,MOSSY_COBBLESTONE,50,COBBLESTONE,100)
Block(-8,4,0,MOSSY_COBBLESTONE,50,COBBLESTONE,100)
Block(-8,4,1,MOSSY_COBBLESTONE,50,COBBLESTONE,100)
Block(-8,4,2,MOSSY_COBBLESTONE,50,COBBLESTONE,100)
Block(-8,4,3,MOSSY_COBBLESTONE,50,COBBLESTONE,100)
Block(-8,5,-2,MOSSY_COBBLESTONE,50,COBBLESTONE,100)
Block(-8,5,-1,MOSSY_COBBLESTONE,50,COBBLESTONE,100)
Block(-8,5,0,MOSSY_COBBLESTONE,50,COBBLESTONE,100)
Block(-8,5,1,MOSSY_COBBLESTONE,50,COBBLESTONE,100)
Block(-8,5,2,MOSSY_COBBLESTONE,50,COBBLESTONE,100)
Block(-8,5,3,MOSSY_COBBLESTONE,50,COBBLESTONE,100)
Block(-8,6,-2,MOSSY_COBBLESTONE,50,COBBLESTONE,100)
Block(-8,6,-1,MOSSY_COBBLESTONE,50,COBBLESTONE,100)
Block(-8,6,0,MOSSY_COBBLESTONE,50,COBBLESTONE,100)
Block(-8,6,1,MOSSY_COBBLESTONE,50,COBBLESTONE,100)
Block(-8,6,2,MOSSY_COBBLESTONE,50,COBBLESTONE,100)
Block(-8,6,3,MOSSY_COBBLESTONE,50,COBBLESTONE,100)
Block(-8,7,-2,MOSSY_COBBLESTONE,50,COBBLESTONE,100)
Block(-8,7,-1,MOSSY_COBBLESTONE,50,COBBLESTONE,100)
Block(-8,7,0,MOSSY_COBBLESTONE,50,COBBLESTONE,100)
Block(-8,7,1,MOSSY_COBBLESTONE,50,COBBLESTONE,100)
Block(-8,7,2,MOSSY_COBBLESTONE,50,COBBLESTONE,100)
Block(-8,7,3,MOSSY_COBBLESTONE,50,COBBLESTONE,100)
Block(-7,0,-2,MOSSY_COBBLESTONE,50,COBBLESTONE,100)
Block(-7,0,-1,MOSSY_COBBLESTONE,50,COBBLESTONE,100)
Block(-7,0,0,MOSSY_COBBLESTONE,50,COBBLESTONE,100)
Block(-7,0,1,MOSSY_COBBLESTONE,50,COBBLESTONE,100)
Block(-7,0,2,MOSSY_COBBLESTONE,50,COBBLESTONE,100)
Block(-7,0,3,MOSSY_COBBLESTONE,50,COBBLESTONE,100)
Block(-7,1,-2,SMOOTH_STAIRS:1)
Block(-7,1,-1,MOSSY_COBBLESTONE,50,COBBLESTONE,100)
Block(-7,1,0,MOSSY_COBBLESTONE,50,COBBLESTONE,100)
Block(-7,1,1,MOSSY_COBBLESTONE,50,COBBLESTONE,100)
Block(-7,1,2,MOSSY_COBBLESTONE,50,COBBLESTONE,100)
Block(-7,1,3,SMOOTH_STAIRS:1)
Block(-7,2,-2,AIR,25,VINE:2,100)
Block(-7,2,-1,CAULDRON)
Block(-7,2,0,MOSSY_COBBLESTONE,50,COBBLESTONE,100)
Block(-7,2,1,MOSSY_COBBLESTONE,50,COBBLESTONE,100)
Block(-7,2,2,CAULDRON)
Block(-7,2,3,AIR,25,VINE:2,100)
Block(-7,3,-2,AIR,25,VINE:2,100)
Block(-7,3,-1,AIR,25,VINE:1,100)
Block(-7,3,0,MOSSY_COBBLESTONE,50,COBBLESTONE,100)
Block(-7,3,1,MOSSY_COBBLESTONE,50,COBBLESTONE,100)
Block(-7,3,2,AIR,25,VINE:2,100)
Block(-7,3,3,AIR,25,VINE:2,100)
Block(-7,4,-2,SMOOTH_STAIRS:5)
Block(-7,4,-1,MOSSY_COBBLESTONE,50,COBBLESTONE,100)
Block(-7,4,0,MOSSY_COBBLESTONE,50,COBBLESTONE,100)
Block(-7,4,1,MOSSY_COBBLESTONE,50,COBBLESTONE,100)
Block(-7,4,2,MOSSY_COBBLESTONE,50,COBBLESTONE,100)
Block(-7,4,3,SMOOTH_STAIRS:5)
Block(-7,5,-2,MOSSY_COBBLESTONE,50,COBBLESTONE,100)
Block(-7,5,-1,MOSSY_COBBLESTONE,50,COBBLESTONE,100)
Block(-7,5,0,MOSSY_COBBLESTONE,50,COBBLESTONE,100)
Block(-7,5,1,MOSSY_COBBLESTONE,50,COBBLESTONE,100)
Block(-7,5,2,MOSSY_COBBLESTONE,50,COBBLESTONE,100)
Block(-7,5,3,MOSSY_COBBLESTONE,50,COBBLESTONE,100)
Block(-7,6,-2,MOSSY_COBBLESTONE,50,COBBLESTONE,100)
Block(-7,6,-1,MOSSY_COBBLESTONE,50,COBBLESTONE,100)
Block(-7,6,0,MOSSY_COBBLESTONE,50,COBBLESTONE,100)
Block(-7,6,1,MOSSY_COBBLESTONE,50,COBBLESTONE,100)
Block(-7,6,2,MOSSY_COBBLESTONE,50,COBBLESTONE,100)
Block(-7,6,3,MOSSY_COBBLESTONE,50,COBBLESTONE,100)
Block(-7,7,-2,MOSSY_COBBLESTONE,50,COBBLESTONE,100)
Block(-7,7,-1,MOSSY_COBBLESTONE,50,COBBLESTONE,100)
Block(-7,7,0,MOSSY_COBBLESTONE,50,COBBLESTONE,100)
Block(-7,7,1,MOSSY_COBBLESTONE,50,COBBLESTONE,100)
Block(-7,7,2,MOSSY_COBBLESTONE,50,COBBLESTONE,100)
Block(-7,7,3,MOSSY_COBBLESTONE,50,COBBLESTONE,100)
Block(-6,0,-1,MOSSY_COBBLESTONE,50,COBBLESTONE,100)
Block(-6,0,0,MOSSY_COBBLESTONE,50,COBBLESTONE,100)
Block(-6,0,1,MOSSY_COBBLESTONE,50,COBBLESTONE,100)
Block(-6,0,2,MOSSY_COBBLESTONE,50,COBBLESTONE,100)
Block(-6,1,-1,SMOOTH_STAIRS:2)
Block(-6,1,0,MOSSY_COBBLESTONE,50,COBBLESTONE,100)
Block(-6,1,1,MOSSY_COBBLESTONE,50,COBBLESTONE,100)
Block(-6,1,2,SMOOTH_STAIRS:3)
Block(-6,2,-2,AIR)
Block(-6,2,-1,AIR,25,VINE:1,100)
Block(-6,2,0,SMOOTH_BRICK:3)
Block(-6,2,1,SMOOTH_BRICK:3)
Block(-6,2,2,AIR,25,VINE:4,100)
Block(-6,2,3,AIR)
Block(-6,3,-2,AIR)
Block(-6,3,-1,AIR,25,VINE:1,100)
Block(-6,3,0,SMOOTH_BRICK:3)
Block(-6,3,1,SMOOTH_BRICK:3)
Block(-6,3,2,AIR,25,VINE:4,100)
Block(-6,3,3,AIR)
Block(-6,4,-2,AIR)
Block(-6,4,-1,SMOOTH_STAIRS:6)
Block(-6,4,0,MOSSY_COBBLESTONE,50,COBBLESTONE,100)
Block(-6,4,1,MOSSY_COBBLESTONE,50,COBBLESTONE,100)
Block(-6,4,2,SMOOTH_STAIRS:7)
Block(-6,4,3,AIR)
Block(-6,5,-2,STONE)
Block(-6,5,-1,MOSSY_COBBLESTONE,50,COBBLESTONE,100)
Block(-6,5,0,MOSSY_COBBLESTONE,50,COBBLESTONE,100)
Block(-6,5,1,MOSSY_COBBLESTONE,50,COBBLESTONE,100)
Block(-6,5,2,MOSSY_COBBLESTONE,50,COBBLESTONE,100)
Block(-6,5,3,STONE)
Block(-6,6,-2,MOSSY_COBBLESTONE,50,COBBLESTONE,100)
Block(-6,6,-1,MOSSY_COBBLESTONE,50,COBBLESTONE,100)
Block(-6,6,0,MOSSY_COBBLESTONE,50,COBBLESTONE,100)
Block(-6,6,1,MOSSY_COBBLESTONE,50,COBBLESTONE,100)
Block(-6,6,2,MOSSY_COBBLESTONE,50,COBBLESTONE,100)
Block(-6,6,3,MOSSY_COBBLESTONE,50,COBBLESTONE,100)
Block(-6,7,-2,MOSSY_COBBLESTONE,50,COBBLESTONE,100)
Block(-6,7,-1,MOSSY_COBBLESTONE,50,COBBLESTONE,100)
Block(-6,7,0,MOSSY_COBBLESTONE,50,COBBLESTONE,100)
Block(-6,7,1,MOSSY_COBBLESTONE,50,COBBLESTONE,100)
Block(-6,7,2,MOSSY_COBBLESTONE,50,COBBLESTONE,100)
Block(-6,7,3,MOSSY_COBBLESTONE,50,COBBLESTONE,100)
Block(-5,0,-1,MOSSY_COBBLESTONE,50,COBBLESTONE,100)
Block(-5,0,0,MOSSY_COBBLESTONE,50,COBBLESTONE,100)
Block(-5,0,1,MOSSY_COBBLESTONE,50,COBBLESTONE,100)
Block(-5,0,2,MOSSY_COBBLESTONE,50,COBBLESTONE,100)
Block(-5,1,-1,SMOOTH_STAIRS:1)
Block(-5,1,0,SMOOTH_STAIRS:1)
Block(-5,1,1,SMOOTH_STAIRS:1)
Block(-5,1,2,SMOOTH_STAIRS:1)
Block(-5,2,-2,AIR)
Block(-5,2,0,AIR,25,VINE:2,100)
Block(-5,2,1,AIR,25,VINE:2,100)
Block(-5,2,3,AIR)
Block(-5,3,-2,AIR)
Block(-5,3,0,AIR,25,VINE:2,100)
Block(-5,3,1,AIR,25,VINE:2,100)
Block(-5,3,3,AIR)
Block(-5,4,-2,AIR)
Block(-5,4,-1,SMOOTH_STAIRS:5)
Block(-5,4,0,SMOOTH_STAIRS:5)
Block(-5,4,1,SMOOTH_STAIRS:5)
Block(-5,4,2,SMOOTH_STAIRS:5)
Block(-5,4,3,AIR)
Block(-5,5,-2,COBBLESTONE_STAIRS:6)
Block(-5,5,-1,MOSSY_COBBLESTONE,50,COBBLESTONE,100)
Block(-5,5,0,MOSSY_COBBLESTONE,50,COBBLESTONE,100)
Block(-5,5,1,MOSSY_COBBLESTONE,50,COBBLESTONE,100)
Block(-5,5,2,MOSSY_COBBLESTONE,50,COBBLESTONE,100)
Block(-5,5,3,COBBLESTONE_STAIRS:7)
Block(-5,6,-2,STONE)
Block(-5,6,-1,MOSSY_COBBLESTONE,50,COBBLESTONE,100)
Block(-5,6,0,MOSSY_COBBLESTONE,50,COBBLESTONE,100)
Block(-5,6,1,MOSSY_COBBLESTONE,50,COBBLESTONE,100)
Block(-5,6,2,MOSSY_COBBLESTONE,50,COBBLESTONE,100)
Block(-5,6,3,MOSSY_COBBLESTONE,50,COBBLESTONE,100)
Block(-5,7,-2,MOSSY_COBBLESTONE,50,COBBLESTONE,100)
Block(-5,7,-1,MOSSY_COBBLESTONE,50,COBBLESTONE,100)
Block(-5,7,0,MOSSY_COBBLESTONE,50,COBBLESTONE,100)
Block(-5,7,1,MOSSY_COBBLESTONE,50,COBBLESTONE,100)
Block(-5,7,2,MOSSY_COBBLESTONE,50,COBBLESTONE,100)
Block(-5,7,3,MOSSY_COBBLESTONE,50,COBBLESTONE,100)
RandomBlock(-4,0,-1,STONEBRICK:1,50,STONEBRICK:2,100)
RandomBlock(-4,0,0,STONEBRICK:1,50,STONEBRICK:2,100)
RandomBlock(-4,0,1,STONEBRICK:1,50,STONEBRICK:2,100)
RandomBlock(-4,0,2,STONEBRICK:1,50,STONEBRICK:2,100)
Block(-4,1,-1,AIR)
Block(-4,1,0,AIR)
Block(-4,1,1,AIR)
Block(-4,1,2,AIR)
Block(-4,2,-2,AIR)
Block(-4,2,-1,AIR)
Block(-4,2,0,AIR)
Block(-4,2,1,AIR)
Block(-4,2,2,AIR)
Block(-4,2,3,AIR)
Block(-4,3,-2,AIR)
Block(-4,3,-1,AIR)
Block(-4,3,0,AIR)
Block(-4,3,1,AIR)
Block(-4,3,2,AIR)
Block(-4,3,3,AIR)
Block(-4,4,-2,AIR)
Block(-4,4,-1,AIR)
Block(-4,4,0,AIR)
Block(-4,4,1,AIR)
Block(-4,4,2,AIR)
Block(-4,4,3,AIR)
Block(-4,5,-4,AIR)
Block(-4,5,-3,AIR)
Block(-4,5,-2,COBBLESTONE_STAIRS:6)
Block(-4,5,-1,COBBLESTONE_STAIRS:5)
Block(-4,5,0,COBBLESTONE_STAIRS:5)
Block(-4,5,1,COBBLESTONE_STAIRS:5)
Block(-4,5,2,COBBLESTONE_STAIRS:5)
Block(-4,5,3,COBBLESTONE_STAIRS:7)
Block(-4,5,4,AIR)
Block(-4,5,5,AIR)
Block(-4,6,-4,COBBLESTONE_STAIRS:7)
Block(-4,6,-3,COBBLESTONE_STAIRS:6)
Block(-4,6,-2,STONE)
Block(-4,6,-1,STONE)
Block(-4,6,0,MOSSY_COBBLESTONE,50,COBBLESTONE,100)
Block(-4,6,1,MOSSY_COBBLESTONE,50,COBBLESTONE,100)
Block(-4,6,2,MOSSY_COBBLESTONE,50,COBBLESTONE,100)
Block(-4,6,3,MOSSY_COBBLESTONE,50,COBBLESTONE,100)
Block(-4,6,4,COBBLESTONE_STAIRS:7)
Block(-4,6,5,COBBLESTONE_STAIRS:6)
Block(-4,7,-4,MOSSY_COBBLESTONE,50,COBBLESTONE,100)
Block(-4,7,-3,MOSSY_COBBLESTONE,50,COBBLESTONE,100)
Block(-4,7,-2,MOSSY_COBBLESTONE,50,COBBLESTONE,100)
Block(-4,7,-1,MOSSY_COBBLESTONE,50,COBBLESTONE,100)
Block(-4,7,0,MOSSY_COBBLESTONE,50,COBBLESTONE,100)
Block(-4,7,1,MOSSY_COBBLESTONE,50,COBBLESTONE,100)
Block(-4,7,2,MOSSY_COBBLESTONE,50,COBBLESTONE,100)
Block(-4,7,3,MOSSY_COBBLESTONE,50,COBBLESTONE,100)
Block(-4,7,4,MOSSY_COBBLESTONE,50,COBBLESTONE,100)
Block(-4,7,5,MOSSY_COBBLESTONE,50,COBBLESTONE,100)
RandomBlock(-3,0,-1,STONEBRICK:1,50,STONEBRICK:2,100)
RandomBlock(-3,0,0,STONEBRICK:1,50,STONEBRICK:2,100)
RandomBlock(-3,0,1,STONEBRICK:1,50,STONEBRICK:2,100)
RandomBlock(-3,0,2,STONEBRICK:1,50,STONEBRICK:2,100)
Block(-3,1,-1,AIR)
Block(-3,1,0,AIR)
Block(-3,1,1,AIR)
Block(-3,1,2,AIR)
Block(-3,2,-2,AIR)
Block(-3,2,-1,AIR)
Block(-3,2,0,AIR)
Block(-3,2,1,AIR)
Block(-3,2,2,AIR)
Block(-3,2,3,AIR)
Block(-3,3,-2,AIR)
Block(-3,3,-1,AIR)
Block(-3,3,0,AIR)
Block(-3,3,1,AIR)
Block(-3,3,2,AIR)
Block(-3,3,3,AIR)
Block(-3,4,-2,AIR)
Block(-3,4,-1,AIR)
Block(-3,4,0,AIR)
Block(-3,4,1,AIR)
Block(-3,4,2,AIR)
Block(-3,4,3,AIR)
Block(-3,5,-4,AIR)
Block(-3,5,-3,AIR)
Block(-3,5,-2,AIR)
Block(-3,5,-1,AIR)
Block(-3,5,0,AIR)
Block(-3,5,1,AIR)
Block(-3,5,2,AIR)
Block(-3,5,3,AIR)
Block(-3,5,4,AIR)
Block(-3,5,5,AIR)
Block(-3,6,-4,COBBLESTONE_STAIRS:7)
Block(-3,6,-3,COBBLESTONE_STAIRS:6)
Block(-3,6,-2,COBBLESTONE_STAIRS:5)
Block(-3,6,-1,COBBLESTONE_STAIRS:5)
Block(-3,6,0,COBBLESTONE_STAIRS:5)
Block(-3,6,1,COBBLESTONE_STAIRS:5)
Block(-3,6,2,COBBLESTONE_STAIRS:5)
Block(-3,6,3,COBBLESTONE_STAIRS:5)
Block(-3,6,4,COBBLESTONE_STAIRS:7)
Block(-3,6,5,COBBLESTONE_STAIRS:6)
Block(-3,7,-4,MOSSY_COBBLESTONE,50,COBBLESTONE,100)
Block(-3,7,-3,MOSSY_COBBLESTONE,50,COBBLESTONE,100)
Block(-3,7,-2,MOSSY_COBBLESTONE,50,COBBLESTONE,100)
Block(-3,7,-1,MOSSY_COBBLESTONE,50,COBBLESTONE,100)
Block(-3,7,0,MOSSY_COBBLESTONE,50,COBBLESTONE,100)
Block(-3,7,1,MOSSY_COBBLESTONE,50,COBBLESTONE,100)
Block(-3,7,2,MOSSY_COBBLESTONE,50,COBBLESTONE,100)
Block(-3,7,3,MOSSY_COBBLESTONE,50,COBBLESTONE,100)
Block(-3,7,4,MOSSY_COBBLESTONE,50,COBBLESTONE,100)
Block(-3,7,5,MOSSY_COBBLESTONE,50,COBBLESTONE,100)
RandomBlock(-2,0,-3,STONEBRICK:1,50,STONEBRICK:2,100)
RandomBlock(-2,0,-2,STONEBRICK:1,50,STONEBRICK:2,100)
RandomBlock(-2,0,-1,STONEBRICK:1,50,STONEBRICK:2,100)
RandomBlock(-2,0,0,STONEBRICK:1,50,STONEBRICK:2,100)
RandomBlock(-2,0,1,STONEBRICK:1,50,STONEBRICK:2,100)
RandomBlock(-2,0,2,STONEBRICK:1,50,STONEBRICK:2,100)
RandomBlock(-2,0,3,STONEBRICK:1,50,STONEBRICK:2,100)
RandomBlock(-2,0,4,STONEBRICK:1,50,STONEBRICK:2,100)
Block(-2,1,-3,AIR)
Block(-2,1,-2,AIR)
Block(-2,1,-1,AIR)
Block(-2,1,0,AIR)
Block(-2,1,1,AIR)
Block(-2,1,2,AIR)
Block(-2,1,3,AIR)
Block(-2,1,4,AIR)
Block(-2,2,-2,AIR)
Block(-2,2,-1,AIR)
Block(-2,2,0,AIR)
Block(-2,2,1,AIR)
Block(-2,2,2,AIR)
Block(-2,2,3,AIR)
Block(-2,3,-2,AIR)
Block(-2,3,-1,AIR)
Block(-2,3,0,AIR)
Block(-2,3,1,AIR)
Block(-2,3,2,AIR)
Block(-2,3,3,AIR)
Block(-2,4,-2,AIR)
Block(-2,4,-1,AIR)
Block(-2,4,0,AIR)
Block(-2,4,1,AIR)
Block(-2,4,2,AIR)
Block(-2,4,3,AIR)
Block(-2,5,-4,AIR)
Block(-2,5,-3,AIR)
Block(-2,5,-2,AIR)
Block(-2,5,-1,AIR)
Block(-2,5,0,AIR)
Block(-2,5,1,AIR)
Block(-2,5,2,AIR)
Block(-2,5,3,AIR)
Block(-2,5,4,AIR)
Block(-2,5,5,AIR)
Block(-2,6,-4,MOSSY_COBBLESTONE,50,COBBLESTONE,100)
Block(-2,6,-3,COBBLESTONE_STAIRS:7)
Block(-2,6,-2,AIR)
Block(-2,6,-1,AIR)
Block(-2,6,0,AIR)
Block(-2,6,1,AIR)
Block(-2,6,2,AIR)
Block(-2,6,3,AIR)
Block(-2,6,4,COBBLESTONE_STAIRS:6)
Block(-2,6,5,MOSSY_COBBLESTONE,50,COBBLESTONE,100)
Block(-2,7,-4,MOSSY_COBBLESTONE,50,COBBLESTONE,100)
Block(-2,7,-3,MOSSY_COBBLESTONE,50,COBBLESTONE,100)
Block(-2,7,-2,MOSSY_COBBLESTONE,50,COBBLESTONE,100)
Block(-2,7,-1,COBBLESTONE_STAIRS:5)
Block(-2,7,0,COBBLESTONE_STAIRS:5)
Block(-2,7,1,COBBLESTONE_STAIRS:5)
Block(-2,7,2,COBBLESTONE_STAIRS:5)
Block(-2,7,3,MOSSY_COBBLESTONE,50,COBBLESTONE,100)
Block(-2,7,4,MOSSY_COBBLESTONE,50,COBBLESTONE,100)
Block(-2,7,5,MOSSY_COBBLESTONE,50,COBBLESTONE,100)
RandomBlock(-1,0,-1,STONEBRICK:1,50,STONEBRICK:2,100)
RandomBlock(-1,0,0,STONEBRICK:1,50,STONEBRICK:2,100)
RandomBlock(-1,0,1,STONEBRICK:1,50,STONEBRICK:2,100)
RandomBlock(-1,0,2,STONEBRICK:1,50,STONEBRICK:2,100)
Block(-1,1,-1,AIR)
Block(-1,1,0,AIR)
Block(-1,1,1,AIR)
Block(-1,1,2,AIR)
Block(-1,2,-2,AIR)
Block(-1,2,-1,AIR)
Block(-1,2,0,AIR)
Block(-1,2,1,AIR)
Block(-1,2,2,AIR)
Block(-1,2,3,AIR)
Block(-1,3,-2,AIR)
Block(-1,3,-1,AIR)
Block(-1,3,0,AIR)
Block(-1,3,1,AIR)
Block(-1,3,2,AIR)
Block(-1,3,3,AIR)
Block(-1,4,-2,AIR)
Block(-1,4,-1,AIR)
Block(-1,4,0,AIR)
Block(-1,4,1,AIR)
Block(-1,4,2,AIR)
Block(-1,4,3,AIR)
Block(-1,5,-4,AIR)
Block(-1,5,-3,AIR)
Block(-1,5,-2,AIR)
Block(-1,5,-1,AIR)
Block(-1,5,0,AIR)
Block(-1,5,1,AIR)
Block(-1,5,2,AIR)
Block(-1,5,3,AIR)
Block(-1,5,4,AIR)
Block(-1,5,5,AIR)
Block(-1,6,-4,COBBLESTONE_STAIRS:6)
Block(-1,6,-3,AIR)
Block(-1,6,-2,AIR)
Block(-1,6,-1,AIR)
Block(-1,6,0,AIR)
Block(-1,6,1,AIR)
Block(-1,6,2,AIR)
Block(-1,6,3,AIR)
Block(-1,6,4,AIR)
Block(-1,6,5,COBBLESTONE_STAIRS:7)
Block(-1,7,-4,SMOOTH_BRICK)
Block(-1,7,-3,MOSSY_COBBLESTONE,50,COBBLESTONE,100)
Block(-1,7,-2,STONE)
Block(-1,7,-1,STONE)
Block(-1,7,0,STONE)
Block(-1,7,1,STONE)
Block(-1,7,2,STONE)
Block(-1,7,3,STONE)
Block(-1,7,4,MOSSY_COBBLESTONE,50,COBBLESTONE,100)
Block(-1,7,5,MOSSY_COBBLESTONE,50,COBBLESTONE,100)
RandomBlock(0,0,-1,STONEBRICK:1,50,STONEBRICK:2,100)
RandomBlock(0,0,0,STONEBRICK:1,50,STONEBRICK:2,100)
RandomBlock(0,0,1,STONEBRICK:1,50,STONEBRICK:2,100)
RandomBlock(0,0,2,STONEBRICK:1,50,STONEBRICK:2,100)
Block(0,1,-1,AIR)
Block(0,1,0,AIR)
Block(0,1,1,AIR)
Block(0,1,2,AIR)
Block(0,2,-2,AIR)
Block(0,2,-1,AIR)
Block(0,2,0,AIR)
Block(0,2,1,AIR)
Block(0,2,2,AIR)
Block(0,2,3,AIR)
Block(0,3,-2,AIR)
Block(0,3,-1,AIR)
Block(0,3,0,AIR)
Block(0,3,1,AIR)
Block(0,3,2,AIR)
Block(0,3,3,AIR)
Block(0,4,-2,AIR)
Block(0,4,-1,AIR)
Block(0,4,0,AIR)
Block(0,4,1,AIR)
Block(0,4,2,AIR)
Block(0,4,3,AIR)
Block(0,5,-4,AIR)
Block(0,5,-3,AIR)
Block(0,5,-2,AIR)
Block(0,5,-1,AIR)
Block(0,5,0,AIR)
Block(0,5,1,AIR)
Block(0,5,2,AIR)
Block(0,5,3,AIR)
Block(0,5,4,AIR)
Block(0,5,5,AIR)
Block(0,6,-4,COBBLESTONE_STAIRS:6)
Block(0,6,-3,AIR)
Block(0,6,-2,AIR)
Block(0,6,-1,AIR)
Block(0,6,0,AIR)
Block(0,6,1,AIR)
Block(0,6,2,AIR)
Block(0,6,3,AIR)
Block(0,6,4,AIR)
Block(0,6,5,COBBLESTONE_STAIRS:7)
Block(0,7,-4,SMOOTH_BRICK)
Block(0,7,-3,MOSSY_COBBLESTONE,50,COBBLESTONE,100)
Block(0,7,-2,STONE)
Block(0,7,-1,STONE)
Block(0,7,0,STONE)
Block(0,7,1,STONE)
Block(0,7,2,STONE)
Block(0,7,3,STONE)
Block(0,7,4,MOSSY_COBBLESTONE,50,COBBLESTONE,100)
Block(0,7,5,MOSSY_COBBLESTONE,50,COBBLESTONE,100)
RandomBlock(1,0,-3,STONEBRICK:1,50,STONEBRICK:2,100)
RandomBlock(1,0,-2,STONEBRICK:1,50,STONEBRICK:2,100)
RandomBlock(1,0,-1,STONEBRICK:1,50,STONEBRICK:2,100)
RandomBlock(1,0,0,STONEBRICK:1,50,STONEBRICK:2,100)
RandomBlock(1,0,1,STONEBRICK:1,50,STONEBRICK:2,100)
RandomBlock(1,0,2,STONEBRICK:1,50,STONEBRICK:2,100)
RandomBlock(1,0,3,STONEBRICK:1,50,STONEBRICK:2,100)
RandomBlock(1,0,4,STONEBRICK:1,50,STONEBRICK:2,100)
Block(1,1,-3,AIR)
Block(1,1,-2,AIR)
Block(1,1,-1,AIR)
Block(1,1,0,AIR)
Block(1,1,1,AIR)
Block(1,1,2,AIR)
Block(1,1,3,AIR)
Block(1,1,4,AIR)
Block(1,2,-2,AIR)
Block(1,2,-1,AIR)
Block(1,2,0,AIR)
Block(1,2,1,AIR)
Block(1,2,2,AIR)
Block(1,2,3,AIR)
Block(1,3,-2,AIR)
Block(1,3,-1,AIR)
Block(1,3,0,AIR)
Block(1,3,1,AIR)
Block(1,3,2,AIR)
Block(1,3,3,AIR)
Block(1,4,-2,AIR)
Block(1,4,-1,AIR)
Block(1,4,0,AIR)
Block(1,4,1,AIR)
Block(1,4,2,AIR)
Block(1,4,3,AIR)
Block(1,5,-4,AIR)
Block(1,5,-3,AIR)
Block(1,5,-2,AIR)
Block(1,5,-1,AIR)
Block(1,5,0,AIR)
Block(1,5,1,AIR)
Block(1,5,2,AIR)
Block(1,5,3,AIR)
Block(1,5,4,AIR)
Block(1,5,5,AIR)
Block(1,6,-4,MOSSY_COBBLESTONE,50,COBBLESTONE,100)
Block(1,6,-3,COBBLESTONE_STAIRS:7)
Block(1,6,-2,AIR)
Block(1,6,-1,AIR)
Block(1,6,0,AIR)
Block(1,6,1,AIR)
Block(1,6,2,AIR)
Block(1,6,3,AIR)
Block(1,6,4,COBBLESTONE_STAIRS:6)
Block(1,6,5,MOSSY_COBBLESTONE,50,COBBLESTONE,100)
Block(1,7,-4,MOSSY_COBBLESTONE,50,COBBLESTONE,100)
Block(1,7,-3,MOSSY_COBBLESTONE,50,COBBLESTONE,100)
Block(1,7,-2,MOSSY_COBBLESTONE,50,COBBLESTONE,100)
Block(1,7,-1,COBBLESTONE_STAIRS:4)
Block(1,7,0,COBBLESTONE_STAIRS:4)
Block(1,7,1,COBBLESTONE_STAIRS:4)
Block(1,7,2,COBBLESTONE_STAIRS:4)
Block(1,7,3,MOSSY_COBBLESTONE,50,COBBLESTONE,100)
Block(1,7,4,MOSSY_COBBLESTONE,50,COBBLESTONE,100)
Block(1,7,5,MOSSY_COBBLESTONE,50,COBBLESTONE,100)
RandomBlock(2,0,-1,STONEBRICK:1,50,STONEBRICK:2,100)
RandomBlock(2,0,0,STONEBRICK:1,50,STONEBRICK:2,100)
RandomBlock(2,0,1,STONEBRICK:1,50,STONEBRICK:2,100)
RandomBlock(2,0,2,STONEBRICK:1,50,STONEBRICK:2,100)
Block(2,1,-1,AIR)
Block(2,1,0,AIR)
Block(2,1,1,AIR)
Block(2,1,2,AIR)
Block(2,2,-2,AIR)
Block(2,2,-1,AIR)
Block(2,2,0,AIR)
Block(2,2,1,AIR)
Block(2,2,2,AIR)
Block(2,2,3,AIR)
Block(2,3,-2,AIR)
Block(2,3,-1,AIR)
Block(2,3,0,AIR)
Block(2,3,1,AIR)
Block(2,3,2,AIR)
Block(2,3,3,AIR)
Block(2,4,-2,AIR)
Block(2,4,-1,AIR)
Block(2,4,0,AIR)
Block(2,4,1,AIR)
Block(2,4,2,AIR)
Block(2,4,3,AIR)
Block(2,5,-4,AIR)
Block(2,5,-3,AIR)
Block(2,5,-2,AIR)
Block(2,5,-1,AIR)
Block(2,5,0,AIR)
Block(2,5,1,AIR)
Block(2,5,2,AIR)
Block(2,5,3,AIR)
Block(2,5,4,AIR)
Block(2,5,5,AIR)
Block(2,6,-4,COBBLESTONE_STAIRS:7)
Block(2,6,-3,COBBLESTONE_STAIRS:6)
Block(2,6,-2,COBBLESTONE_STAIRS:4)
Block(2,6,-1,COBBLESTONE_STAIRS:4)
Block(2,6,0,COBBLESTONE_STAIRS:4)
Block(2,6,1,COBBLESTONE_STAIRS:4)
Block(2,6,2,COBBLESTONE_STAIRS:4)
Block(2,6,3,COBBLESTONE_STAIRS:4)
Block(2,6,4,COBBLESTONE_STAIRS:7)
Block(2,6,5,COBBLESTONE_STAIRS:6)
Block(2,7,-4,MOSSY_COBBLESTONE,50,COBBLESTONE,100)
Block(2,7,-3,MOSSY_COBBLESTONE,50,COBBLESTONE,100)
Block(2,7,-2,MOSSY_COBBLESTONE,50,COBBLESTONE,100)
Block(2,7,-1,MOSSY_COBBLESTONE,50,COBBLESTONE,100)
Block(2,7,0,MOSSY_COBBLESTONE,50,COBBLESTONE,100)
Block(2,7,1,MOSSY_COBBLESTONE,50,COBBLESTONE,100)
Block(2,7,2,MOSSY_COBBLESTONE,50,COBBLESTONE,100)
Block(2,7,3,MOSSY_COBBLESTONE,50,COBBLESTONE,100)
Block(2,7,4,MOSSY_COBBLESTONE,50,COBBLESTONE,100)
Block(2,7,5,MOSSY_COBBLESTONE,50,COBBLESTONE,100)
RandomBlock(3,0,-1,STONEBRICK:1,50,STONEBRICK:2,100)
RandomBlock(3,0,0,STONEBRICK:1,50,STONEBRICK:2,100)
RandomBlock(3,0,1,STONEBRICK:1,50,STONEBRICK:2,100)
RandomBlock(3,0,2,STONEBRICK:1,50,STONEBRICK:2,100)
Block(3,1,-1,AIR)
Block(3,1,0,AIR)
Block(3,1,1,AIR)
Block(3,1,2,AIR)
Block(3,2,-2,AIR)
Block(3,2,-1,AIR)
Block(3,2,0,AIR)
Block(3,2,1,AIR)
Block(3,2,2,AIR)
Block(3,2,3,AIR)
Block(3,3,-2,AIR)
Block(3,3,-1,AIR)
Block(3,3,0,AIR)
Block(3,3,1,AIR)
Block(3,3,2,AIR)
Block(3,3,3,AIR)
Block(3,4,-2,AIR)
Block(3,4,-1,AIR)
Block(3,4,0,AIR)
Block(3,4,1,AIR)
Block(3,4,2,AIR)
Block(3,4,3,AIR)
Block(3,5,-4,AIR)
Block(3,5,-3,AIR)
Block(3,5,-2,COBBLESTONE_STAIRS:4)
Block(3,5,-1,COBBLESTONE_STAIRS:4)
Block(3,5,0,COBBLESTONE_STAIRS:4)
Block(3,5,1,COBBLESTONE_STAIRS:4)
Block(3,5,2,COBBLESTONE_STAIRS:4)
Block(3,5,3,COBBLESTONE_STAIRS:4)
Block(3,5,4,AIR)
Block(3,5,5,AIR)
Block(3,6,-4,COBBLESTONE_STAIRS:7)
Block(3,6,-3,COBBLESTONE_STAIRS:6)
Block(3,6,-2,MOSSY_COBBLESTONE,50,COBBLESTONE,100)
Block(3,6,-1,MOSSY_COBBLESTONE,50,COBBLESTONE,100)
Block(3,6,0,MOSSY_COBBLESTONE,50,COBBLESTONE,100)
Block(3,6,1,MOSSY_COBBLESTONE,50,COBBLESTONE,100)
Block(3,6,2,MOSSY_COBBLESTONE,50,COBBLESTONE,100)
Block(3,6,3,MOSSY_COBBLESTONE,50,COBBLESTONE,100)
Block(3,6,4,COBBLESTONE_STAIRS:7)
Block(3,6,5,COBBLESTONE_STAIRS:6)
Block(3,7,-4,MOSSY_COBBLESTONE,50,COBBLESTONE,100)
Block(3,7,-3,MOSSY_COBBLESTONE,50,COBBLESTONE,100)
Block(3,7,-2,MOSSY_COBBLESTONE,50,COBBLESTONE,100)
Block(3,7,-1,MOSSY_COBBLESTONE,50,COBBLESTONE,100)
Block(3,7,0,MOSSY_COBBLESTONE,50,COBBLESTONE,100)
Block(3,7,1,MOSSY_COBBLESTONE,50,COBBLESTONE,100)
Block(3,7,2,MOSSY_COBBLESTONE,50,COBBLESTONE,100)
Block(3,7,3,MOSSY_COBBLESTONE,50,COBBLESTONE,100)
Block(3,7,4,MOSSY_COBBLESTONE,50,COBBLESTONE,100)
Block(3,7,5,MOSSY_COBBLESTONE,50,COBBLESTONE,100)
Block(4,0,-1,MOSSY_COBBLESTONE,50,COBBLESTONE,100)
Block(4,0,0,MOSSY_COBBLESTONE,50,COBBLESTONE,100)
Block(4,0,1,MOSSY_COBBLESTONE,50,COBBLESTONE,100)
Block(4,0,2,MOSSY_COBBLESTONE,50,COBBLESTONE,100)
Block(4,1,-1,SMOOTH_STAIRS)
Block(4,1,0,SMOOTH_STAIRS)
Block(4,1,1,SMOOTH_STAIRS)
Block(4,1,2,SMOOTH_STAIRS)
Block(4,2,-2,AIR)
Block(4,2,0,AIR,25,VINE:8,100)
Block(4,2,1,AIR,25,VINE:8,100)
Block(4,2,3,AIR)
Block(4,3,-2,AIR)
Block(4,3,0,AIR,25,VINE:8,100)
Block(4,3,1,AIR,25,VINE:8,100)
Block(4,3,3,AIR)
Block(4,4,-2,AIR)
Block(4,4,-1,SMOOTH_STAIRS:4)
Block(4,4,0,SMOOTH_STAIRS:4)
Block(4,4,1,SMOOTH_STAIRS:4)
Block(4,4,2,SMOOTH_STAIRS:4)
Block(4,4,3,AIR)
Block(4,5,-2,COBBLESTONE_STAIRS:6)
Block(4,5,-1,MOSSY_COBBLESTONE,50,COBBLESTONE,100)
Block(4,5,0,MOSSY_COBBLESTONE,50,COBBLESTONE,100)
Block(4,5,1,MOSSY_COBBLESTONE,50,COBBLESTONE,100)
Block(4,5,2,MOSSY_COBBLESTONE,50,COBBLESTONE,100)
Block(4,5,3,COBBLESTONE_STAIRS:7)
Block(4,6,-2,MOSSY_COBBLESTONE,50,COBBLESTONE,100)
Block(4,6,-1,MOSSY_COBBLESTONE,50,COBBLESTONE,100)
Block(4,6,0,MOSSY_COBBLESTONE,50,COBBLESTONE,100)
Block(4,6,1,MOSSY_COBBLESTONE,50,COBBLESTONE,100)
Block(4,6,2,MOSSY_COBBLESTONE,50,COBBLESTONE,100)
Block(4,6,3,MOSSY_COBBLESTONE,50,COBBLESTONE,100)
Block(4,7,-2,MOSSY_COBBLESTONE,50,COBBLESTONE,100)
Block(4,7,-1,MOSSY_COBBLESTONE,50,COBBLESTONE,100)
Block(4,7,0,MOSSY_COBBLESTONE,50,COBBLESTONE,100)
Block(4,7,1,MOSSY_COBBLESTONE,50,COBBLESTONE,100)
Block(4,7,2,MOSSY_COBBLESTONE,50,COBBLESTONE,100)
Block(4,7,3,MOSSY_COBBLESTONE,50,COBBLESTONE,100)
Block(5,0,-1,MOSSY_COBBLESTONE,50,COBBLESTONE,100)
Block(5,0,0,MOSSY_COBBLESTONE,50,COBBLESTONE,100)
Block(5,0,1,MOSSY_COBBLESTONE,50,COBBLESTONE,100)
Block(5,0,2,MOSSY_COBBLESTONE,50,COBBLESTONE,100)
Block(5,1,-1,SMOOTH_STAIRS:2)
Block(5,1,0,MOSSY_COBBLESTONE,50,COBBLESTONE,100)
Block(5,1,1,MOSSY_COBBLESTONE,50,COBBLESTONE,100)
Block(5,1,2,SMOOTH_STAIRS:3)
Block(5,2,-2,AIR)
Block(5,2,-1,AIR,25,VINE:1,100)
Block(5,2,0,SMOOTH_BRICK:3)
Block(5,2,1,SMOOTH_BRICK:3)
Block(5,2,2,AIR,25,VINE:4,100)
Block(5,2,3,AIR)
Block(5,3,-2,AIR)
Block(5,3,-1,AIR,25,VINE:1,100)
Block(5,3,0,SMOOTH_BRICK:3)
Block(5,3,1,SMOOTH_BRICK:3)
Block(5,3,2,AIR,25,VINE:4,100)
Block(5,3,3,AIR)
Block(5,4,-2,AIR)
Block(5,4,-1,SMOOTH_STAIRS:6)
Block(5,4,0,MOSSY_COBBLESTONE,50,COBBLESTONE,100)
Block(5,4,1,MOSSY_COBBLESTONE,50,COBBLESTONE,100)
Block(5,4,2,SMOOTH_STAIRS:7)
Block(5,4,3,AIR)
Block(5,5,-2,STONE)
Block(5,5,-1,MOSSY_COBBLESTONE,50,COBBLESTONE,100)
Block(5,5,0,MOSSY_COBBLESTONE,50,COBBLESTONE,100)
Block(5,5,1,MOSSY_COBBLESTONE,50,COBBLESTONE,100)
Block(5,5,2,MOSSY_COBBLESTONE,50,COBBLESTONE,100)
Block(5,5,3,STONE)
Block(5,6,-2,MOSSY_COBBLESTONE,50,COBBLESTONE,100)
Block(5,6,-1,MOSSY_COBBLESTONE,50,COBBLESTONE,100)
Block(5,6,0,MOSSY_COBBLESTONE,50,COBBLESTONE,100)
Block(5,6,1,MOSSY_COBBLESTONE,50,COBBLESTONE,100)
Block(5,6,2,MOSSY_COBBLESTONE,50,COBBLESTONE,100)
Block(5,6,3,MOSSY_COBBLESTONE,50,COBBLESTONE,100)
Block(5,7,-2,MOSSY_COBBLESTONE,50,COBBLESTONE,100)
Block(5,7,-1,MOSSY_COBBLESTONE,50,COBBLESTONE,100)
Block(5,7,0,MOSSY_COBBLESTONE,50,COBBLESTONE,100)
Block(5,7,1,MOSSY_COBBLESTONE,50,COBBLESTONE,100)
Block(5,7,2,MOSSY_COBBLESTONE,50,COBBLESTONE,100)
Block(5,7,3,MOSSY_COBBLESTONE,50,COBBLESTONE,100)
Block(6,0,-2,MOSSY_COBBLESTONE,50,COBBLESTONE,100)
Block(6,0,-1,MOSSY_COBBLESTONE,50,COBBLESTONE,100)
Block(6,0,0,MOSSY_COBBLESTONE,50,COBBLESTONE,100)
Block(6,0,1,MOSSY_COBBLESTONE,50,COBBLESTONE,100)
Block(6,0,2,MOSSY_COBBLESTONE,50,COBBLESTONE,100)
Block(6,0,3,MOSSY_COBBLESTONE,50,COBBLESTONE,100)
Block(6,1,-2,SMOOTH_STAIRS)
Block(6,1,-1,MOSSY_COBBLESTONE,50,COBBLESTONE,100)
Block(6,1,0,MOSSY_COBBLESTONE,50,COBBLESTONE,100)
Block(6,1,1,MOSSY_COBBLESTONE,50,COBBLESTONE,100)
Block(6,1,2,MOSSY_COBBLESTONE,50,COBBLESTONE,100)
Block(6,1,3,SMOOTH_STAIRS)
Block(6,2,-2,AIR,25,VINE:8,100)
Block(6,2,-1,CAULDRON)
Block(6,2,0,MOSSY_COBBLESTONE,50,COBBLESTONE,100)
Block(6,2,1,MOSSY_COBBLESTONE,50,COBBLESTONE,100)
Block(6,2,2,CAULDRON)
Block(6,2,3,AIR,25,VINE:8,100)
Block(6,3,-2,AIR,25,VINE:8,100)
Block(6,3,-1,AIR,25,VINE:8,100)
Block(6,3,0,MOSSY_COBBLESTONE,50,COBBLESTONE,100)
Block(6,3,1,MOSSY_COBBLESTONE,50,COBBLESTONE,100)
Block(6,3,2,AIR,25,VINE:4,100)
Block(6,3,3,AIR,25,VINE:8,100)
Block(6,4,-2,SMOOTH_STAIRS:4)
Block(6,4,-1,MOSSY_COBBLESTONE,50,COBBLESTONE,100)
Block(6,4,0,MOSSY_COBBLESTONE,50,COBBLESTONE,100)
Block(6,4,1,MOSSY_COBBLESTONE,50,COBBLESTONE,100)
Block(6,4,2,MOSSY_COBBLESTONE,50,COBBLESTONE,100)
Block(6,4,3,SMOOTH_STAIRS:4)
Block(6,5,-2,MOSSY_COBBLESTONE,50,COBBLESTONE,100)
Block(6,5,-1,MOSSY_COBBLESTONE,50,COBBLESTONE,100)
Block(6,5,0,MOSSY_COBBLESTONE,50,COBBLESTONE,100)
Block(6,5,1,MOSSY_COBBLESTONE,50,COBBLESTONE,100)
Block(6,5,2,MOSSY_COBBLESTONE,50,COBBLESTONE,100)
Block(6,5,3,MOSSY_COBBLESTONE,50,COBBLESTONE,100)
Block(6,6,-2,MOSSY_COBBLESTONE,50,COBBLESTONE,100)
Block(6,6,-1,MOSSY_COBBLESTONE,50,COBBLESTONE,100)
Block(6,6,0,MOSSY_COBBLESTONE,50,COBBLESTONE,100)
Block(6,6,1,MOSSY_COBBLESTONE,50,COBBLESTONE,100)
Block(6,6,2,MOSSY_COBBLESTONE,50,COBBLESTONE,100)
Block(6,6,3,MOSSY_COBBLESTONE,50,COBBLESTONE,100)
Block(6,7,-2,MOSSY_COBBLESTONE,50,COBBLESTONE,100)
Block(6,7,-1,MOSSY_COBBLESTONE,50,COBBLESTONE,100)
Block(6,7,0,MOSSY_COBBLESTONE,50,COBBLESTONE,100)
Block(6,7,1,MOSSY_COBBLESTONE,50,COBBLESTONE,100)
Block(6,7,2,MOSSY_COBBLESTONE,50,COBBLESTONE,100)
Block(6,7,3,MOSSY_COBBLESTONE,50,COBBLESTONE,100)
Block(7,0,-2,MOSSY_COBBLESTONE,50,COBBLESTONE,100)
Block(7,0,-1,MOSSY_COBBLESTONE,50,COBBLESTONE,100)
Block(7,0,0,MOSSY_COBBLESTONE,50,COBBLESTONE,100)
Block(7,0,1,MOSSY_COBBLESTONE,50,COBBLESTONE,100)
Block(7,0,2,MOSSY_COBBLESTONE,50,COBBLESTONE,100)
Block(7,0,3,MOSSY_COBBLESTONE,50,COBBLESTONE,100)
Block(7,1,-2,MOSSY_COBBLESTONE,50,COBBLESTONE,100)
Block(7,1,-1,MOSSY_COBBLESTONE,50,COBBLESTONE,100)
Block(7,1,0,MOSSY_COBBLESTONE,50,COBBLESTONE,100)
Block(7,1,1,MOSSY_COBBLESTONE,50,COBBLESTONE,100)
Block(7,1,2,MOSSY_COBBLESTONE,50,COBBLESTONE,100)
Block(7,1,3,MOSSY_COBBLESTONE,50,COBBLESTONE,100)
Block(7,2,-2,SMOOTH_BRICK:3)
Block(7,2,-1,MOSSY_COBBLESTONE,50,COBBLESTONE,100)
Block(7,2,0,MOSSY_COBBLESTONE,50,COBBLESTONE,100)
Block(7,2,1,MOSSY_COBBLESTONE,50,COBBLESTONE,100)
Block(7,2,2,MOSSY_COBBLESTONE,50,COBBLESTONE,100)
Block(7,2,3,SMOOTH_BRICK:3)
Block(7,3,-2,SMOOTH_BRICK:3)
Block(7,3,-1,MOSSY_COBBLESTONE,50,COBBLESTONE,100)
Block(7,3,0,MOSSY_COBBLESTONE,50,COBBLESTONE,100)
Block(7,3,1,MOSSY_COBBLESTONE,50,COBBLESTONE,100)
Block(7,3,2,MOSSY_COBBLESTONE,50,COBBLESTONE,100)
Block(7,3,3,SMOOTH_BRICK:3)
Block(7,4,-2,MOSSY_COBBLESTONE,50,COBBLESTONE,100)
Block(7,4,-1,MOSSY_COBBLESTONE,50,COBBLESTONE,100)
Block(7,4,0,MOSSY_COBBLESTONE,50,COBBLESTONE,100)
Block(7,4,1,MOSSY_COBBLESTONE,50,COBBLESTONE,100)
Block(7,4,2,MOSSY_COBBLESTONE,50,COBBLESTONE,100)
Block(7,4,3,MOSSY_COBBLESTONE,50,COBBLESTONE,100)
Block(7,5,-2,MOSSY_COBBLESTONE,50,COBBLESTONE,100)
Block(7,5,-1,MOSSY_COBBLESTONE,50,COBBLESTONE,100)
Block(7,5,0,MOSSY_COBBLESTONE,50,COBBLESTONE,100)
Block(7,5,1,MOSSY_COBBLESTONE,50,COBBLESTONE,100)
Block(7,5,2,MOSSY_COBBLESTONE,50,COBBLESTONE,100)
Block(7,5,3,MOSSY_COBBLESTONE,50,COBBLESTONE,100)
Block(7,6,-2,MOSSY_COBBLESTONE,50,COBBLESTONE,100)
Block(7,6,-1,MOSSY_COBBLESTONE,50,COBBLESTONE,100)
Block(7,6,0,MOSSY_COBBLESTONE,50,COBBLESTONE,100)
Block(7,6,1,MOSSY_COBBLESTONE,50,COBBLESTONE,100)
Block(7,6,2,MOSSY_COBBLESTONE,50,COBBLESTONE,100)
Block(7,6,3,MOSSY_COBBLESTONE,50,COBBLESTONE,100)
Block(7,7,-2,MOSSY_COBBLESTONE,50,COBBLESTONE,100)
Block(7,7,-1,MOSSY_COBBLESTONE,50,COBBLESTONE,100)
Block(7,7,0,MOSSY_COBBLESTONE,50,COBBLESTONE,100)
Block(7,7,1,MOSSY_COBBLESTONE,50,COBBLESTONE,100)
Block(7,7,2,MOSSY_COBBLESTONE,50,COBBLESTONE,100)
Block(7,7,3,MOSSY_COBBLESTONE,50,COBBLESTONE,100)
