IsOTGPlus:true

Author: PG85

Description: No description given

Version: MCW104

SettingsMode: WriteDisable

Tree: false

Frequency: 1

RotateRandomly: false

SpawnHeight: highestBlock

MinHeight: 0

MaxHeight: 256

ExcludedBiomes: All

SourceBlocks: AIR

MaxPercentageOutsideSourceBlock: 100

OutsideSourceBlock: placeAnyway

InheritBO3: 

OverrideChildSettings: true

CanOverride: false

MustBeBelowOther: false

CanSpawnOnWater: true

SpawnOnWaterOnly: false

SpawnUnderWater: false

SpawnAtWaterLevel: false

HeightOffset: 0

RemoveAir: true

ReplaceAbove: 

ReplaceBelow: 

ReplaceWithBiomeBlocks: true

ReplaceWithGroundBlock: DIRT

ReplaceWithSurfaceBlock: GRASS

SmoothRadius: 0

SmoothHeightOffset: 0

SmoothStartTop: false

SmoothStartWood: false

SmoothingSurfaceBlock: 

SmoothingGroundBlock: 

BO3Group: 

IsSpawnPoint: false

SpawnPointX: 8

SpawnPointY: -1

SpawnPointZ: 7

Block(-8,0,-7,SMOOTH_BRICK)
Block(-8,0,-6,SMOOTH_BRICK)
Block(-8,0,-5,SMOOTH_BRICK)
Block(-8,0,-4,SMOOTH_BRICK)
Block(-8,0,-3,SMOOTH_BRICK)
Block(-8,0,-2,SMOOTH_BRICK)
Block(-8,0,-1,SMOOTH_BRICK)
Block(-8,0,0,SMOOTH_BRICK)
Block(-8,0,1,SMOOTH_BRICK)
Block(-8,0,2,SMOOTH_BRICK)
Block(-8,0,3,SMOOTH_BRICK)
Block(-8,0,4,SMOOTH_BRICK)
Block(-8,0,5,SMOOTH_BRICK)
Block(-8,0,6,SMOOTH_BRICK)
Block(-8,0,7,SMOOTH_BRICK)
Block(-8,0,8,SMOOTH_BRICK)
Block(-8,1,-7,SMOOTH_BRICK)
Block(-8,1,-6,SMOOTH_BRICK)
Block(-8,1,-5,SMOOTH_BRICK)
Block(-8,1,-4,SMOOTH_BRICK)
Block(-8,1,-3,SMOOTH_BRICK)
Block(-8,1,-2,SMOOTH_BRICK)
Block(-8,1,-1,SMOOTH_BRICK)
Block(-8,1,0,SMOOTH_BRICK)
Block(-8,1,1,SMOOTH_BRICK)
Block(-8,1,2,SMOOTH_BRICK)
Block(-8,1,3,SMOOTH_BRICK)
Block(-8,1,4,SMOOTH_BRICK)
Block(-8,1,5,SMOOTH_BRICK)
Block(-8,1,6,SMOOTH_BRICK)
Block(-8,1,7,SMOOTH_BRICK)
Block(-8,1,8,SMOOTH_BRICK)
Block(-8,2,-7,SMOOTH_BRICK)
Block(-8,2,-6,SMOOTH_BRICK)
Block(-8,2,-5,SMOOTH_BRICK)
Block(-8,2,-4,SMOOTH_BRICK)
Block(-8,2,-3,SMOOTH_BRICK)
Block(-8,2,-2,SMOOTH_BRICK)
Block(-8,2,-1,SMOOTH_BRICK)
Block(-8,2,0,SMOOTH_BRICK)
Block(-8,2,1,SMOOTH_BRICK)
Block(-8,2,2,SMOOTH_BRICK)
Block(-8,2,3,SMOOTH_BRICK)
Block(-8,2,4,SMOOTH_BRICK)
Block(-8,2,5,SMOOTH_BRICK)
Block(-8,2,6,SMOOTH_BRICK)
Block(-8,2,7,SMOOTH_BRICK)
Block(-8,2,8,SMOOTH_BRICK)
Block(-8,3,-7,MOSSY_COBBLESTONE,50,COBBLESTONE,100)
Block(-8,3,-6,MOSSY_COBBLESTONE,50,COBBLESTONE,100)
Block(-8,3,-5,MOSSY_COBBLESTONE,50,COBBLESTONE,100)
Block(-8,3,-4,MOSSY_COBBLESTONE,50,COBBLESTONE,100)
Block(-8,3,-3,MOSSY_COBBLESTONE,50,COBBLESTONE,100)
Block(-8,3,-2,MOSSY_COBBLESTONE,50,COBBLESTONE,100)
Block(-8,3,-1,MOSSY_COBBLESTONE,50,COBBLESTONE,100)
Block(-8,3,0,MOSSY_COBBLESTONE,50,COBBLESTONE,100)
Block(-8,3,1,MOSSY_COBBLESTONE,50,COBBLESTONE,100)
Block(-8,3,2,MOSSY_COBBLESTONE,50,COBBLESTONE,100)
Block(-8,3,3,MOSSY_COBBLESTONE,50,COBBLESTONE,100)
Block(-8,3,4,MOSSY_COBBLESTONE,50,COBBLESTONE,100)
Block(-8,3,5,MOSSY_COBBLESTONE,50,COBBLESTONE,100)
Block(-8,3,6,MOSSY_COBBLESTONE,50,COBBLESTONE,100)
Block(-8,3,7,MOSSY_COBBLESTONE,50,COBBLESTONE,100)
Block(-8,3,8,MOSSY_COBBLESTONE,50,COBBLESTONE,100)
Block(-8,4,-7,MOSSY_COBBLESTONE,50,COBBLESTONE,100)
Block(-8,4,-6,MOSSY_COBBLESTONE,50,COBBLESTONE,100)
Block(-8,4,-5,MOSSY_COBBLESTONE,50,COBBLESTONE,100)
Block(-8,4,-4,MOSSY_COBBLESTONE,50,COBBLESTONE,100)
Block(-8,4,-3,MOSSY_COBBLESTONE,50,COBBLESTONE,100)
Block(-8,4,-2,MOSSY_COBBLESTONE,50,COBBLESTONE,100)
Block(-8,4,-1,MOSSY_COBBLESTONE,50,COBBLESTONE,100)
Block(-8,4,0,MOSSY_COBBLESTONE,50,COBBLESTONE,100)
Block(-8,4,1,MOSSY_COBBLESTONE,50,COBBLESTONE,100)
Block(-8,4,2,MOSSY_COBBLESTONE,50,COBBLESTONE,100)
Block(-8,4,3,MOSSY_COBBLESTONE,50,COBBLESTONE,100)
Block(-8,4,4,MOSSY_COBBLESTONE,50,COBBLESTONE,100)
Block(-8,4,5,MOSSY_COBBLESTONE,50,COBBLESTONE,100)
Block(-8,4,6,MOSSY_COBBLESTONE,50,COBBLESTONE,100)
Block(-8,4,7,MOSSY_COBBLESTONE,50,COBBLESTONE,100)
Block(-8,4,8,MOSSY_COBBLESTONE,50,COBBLESTONE,100)
Block(-8,5,-7,MOSSY_COBBLESTONE,50,COBBLESTONE,100)
Block(-8,5,-6,MOSSY_COBBLESTONE,50,COBBLESTONE,100)
Block(-8,5,-5,MOSSY_COBBLESTONE,50,COBBLESTONE,100)
Block(-8,5,-4,MOSSY_COBBLESTONE,50,COBBLESTONE,100)
Block(-8,5,-3,MOSSY_COBBLESTONE,50,COBBLESTONE,100)
Block(-8,5,-2,MOSSY_COBBLESTONE,50,COBBLESTONE,100)
Block(-8,5,-1,MOSSY_COBBLESTONE,50,COBBLESTONE,100)
Block(-8,5,0,MOSSY_COBBLESTONE,50,COBBLESTONE,100)
Block(-8,5,1,MOSSY_COBBLESTONE,50,COBBLESTONE,100)
Block(-8,5,2,MOSSY_COBBLESTONE,50,COBBLESTONE,100)
Block(-8,5,3,MOSSY_COBBLESTONE,50,COBBLESTONE,100)
Block(-8,5,4,MOSSY_COBBLESTONE,50,COBBLESTONE,100)
Block(-8,5,5,MOSSY_COBBLESTONE,50,COBBLESTONE,100)
Block(-8,5,6,MOSSY_COBBLESTONE,50,COBBLESTONE,100)
Block(-8,5,7,MOSSY_COBBLESTONE,50,COBBLESTONE,100)
Block(-8,5,8,MOSSY_COBBLESTONE,50,COBBLESTONE,100)
Block(-8,6,-7,STONE)
Block(-8,6,-6,STONE)
Block(-8,6,-5,STONE)
Block(-8,6,-4,STONE)
Block(-8,6,-3,STONE)
Block(-8,6,-2,STONE)
Block(-8,6,-1,STONE)
Block(-8,6,0,STONE)
Block(-8,6,1,STONE)
Block(-8,6,2,STONE)
Block(-8,6,3,STONE)
Block(-8,6,4,STONE)
Block(-8,6,5,STONE)
Block(-8,6,6,STONE)
Block(-8,6,7,STONE)
Block(-8,6,8,STONE)
Block(-8,7,-7,SMOOTH_BRICK)
Block(-8,7,-6,SMOOTH_BRICK)
Block(-8,7,-5,SMOOTH_BRICK)
Block(-8,7,-4,SMOOTH_BRICK)
Block(-8,7,-3,SMOOTH_BRICK)
Block(-8,7,-2,SMOOTH_BRICK)
Block(-8,7,-1,SMOOTH_BRICK)
Block(-8,7,0,SMOOTH_BRICK)
Block(-8,7,1,SMOOTH_BRICK)
Block(-8,7,2,SMOOTH_BRICK)
Block(-8,7,3,SMOOTH_BRICK)
Block(-8,7,4,SMOOTH_BRICK)
Block(-8,7,5,SMOOTH_BRICK)
Block(-8,7,6,SMOOTH_BRICK)
Block(-8,7,7,SMOOTH_BRICK)
Block(-8,7,8,SMOOTH_BRICK)
Block(-8,8,-6,AIR,25,VINE:8,100)
Block(-8,8,-5,COBBLE_WALL:1,50,COBBLE_WALL,100)
Block(-8,8,-4,AIR,25,VINE:8,100)
Block(-8,8,-3,AIR,25,VINE:8,100)
Block(-8,8,-2,COBBLE_WALL:1,50,COBBLE_WALL,100)
Block(-8,8,-1,AIR,25,VINE:8,100)
Block(-8,8,0,AIR,25,VINE:8,100)
Block(-8,8,1,COBBLE_WALL:1,50,COBBLE_WALL,100)
Block(-8,8,2,AIR,25,VINE:8,100)
Block(-8,8,3,AIR,25,VINE:8,100)
Block(-8,8,4,COBBLE_WALL:1,50,COBBLE_WALL,100)
Block(-8,8,5,AIR,25,VINE:8,100)
Block(-8,8,6,AIR,25,VINE:8,100)
Block(-8,8,7,COBBLE_WALL:1,50,COBBLE_WALL,100)
Block(-8,8,8,AIR,25,VINE:8,100)
Block(-8,9,-6,AIR,25,VINE:8,100)
Block(-8,9,-4,AIR,25,VINE:8,100)
Block(-8,9,-3,AIR,25,VINE:8,100)
Block(-8,9,-1,AIR,25,VINE:8,100)
Block(-8,9,0,AIR,25,VINE:8,100)
Block(-8,9,2,AIR,25,VINE:8,100)
Block(-8,9,3,AIR,25,VINE:8,100)
Block(-8,9,5,AIR,25,VINE:8,100)
Block(-8,9,6,AIR,25,VINE:8,100)
Block(-8,9,8,AIR,25,VINE:8,100)
Block(-8,10,-6,AIR,25,VINE:8,100)
Block(-8,10,-4,AIR,25,VINE:8,100)
Block(-8,10,-3,AIR,25,VINE:8,100)
Block(-8,10,-1,AIR,25,VINE:8,100)
Block(-8,10,0,AIR,25,VINE:8,100)
Block(-8,10,2,AIR,25,VINE:8,100)
Block(-8,10,3,AIR,25,VINE:8,100)
Block(-8,10,5,AIR,25,VINE:8,100)
Block(-8,10,6,AIR,25,VINE:8,100)
Block(-8,10,8,AIR,25,VINE:8,100)
Block(-8,11,-6,AIR,25,VINE:8,100)
Block(-8,11,-5,COBBLESTONE_STAIRS:4)
Block(-8,11,-4,AIR,25,VINE:8,100)
Block(-8,11,-3,AIR,25,VINE:8,100)
Block(-8,11,-2,COBBLESTONE_STAIRS:4)
Block(-8,11,-1,AIR,25,VINE:8,100)
Block(-8,11,0,AIR,25,VINE:8,100)
Block(-8,11,1,COBBLESTONE_STAIRS:4)
Block(-8,11,2,AIR,25,VINE:8,100)
Block(-8,11,3,AIR,25,VINE:8,100)
Block(-8,11,4,COBBLESTONE_STAIRS:4)
Block(-8,11,5,AIR,25,VINE:8,100)
Block(-8,11,6,AIR,25,VINE:8,100)
Block(-8,11,7,COBBLESTONE_STAIRS:4)
Block(-8,11,8,AIR,25,VINE:8,100)
Block(-8,12,-6,AIR,25,VINE:8,100)
Block(-8,12,-5,76:5)
Block(-8,12,-4,AIR,25,VINE:8,100)
Block(-8,12,-3,AIR,25,VINE:8,100)
Block(-8,12,-2,76:5)
Block(-8,12,-1,AIR,25,VINE:8,100)
Block(-8,12,0,AIR,25,VINE:8,100)
Block(-8,12,1,76:5)
Block(-8,12,2,AIR,25,VINE:8,100)
Block(-8,12,3,AIR,25,VINE:8,100)
Block(-8,12,4,76:5)
Block(-8,12,5,AIR,25,VINE:8,100)
Block(-8,12,6,AIR,25,VINE:8,100)
Block(-8,12,7,76:5)
Block(-8,12,8,AIR,25,VINE:8,100)
Block(-7,0,-7,SMOOTH_BRICK)
Block(-7,0,-6,SMOOTH_BRICK)
Block(-7,0,-5,SMOOTH_BRICK)
Block(-7,0,-4,SMOOTH_BRICK)
Block(-7,0,-3,SMOOTH_BRICK)
Block(-7,0,-2,SMOOTH_BRICK)
Block(-7,0,-1,SMOOTH_BRICK)
Block(-7,0,0,SMOOTH_BRICK)
Block(-7,0,1,SMOOTH_BRICK)
Block(-7,0,2,SMOOTH_BRICK)
Block(-7,0,3,SMOOTH_BRICK)
Block(-7,0,4,SMOOTH_BRICK)
Block(-7,0,5,SMOOTH_BRICK)
Block(-7,0,6,SMOOTH_BRICK)
Block(-7,0,7,SMOOTH_BRICK)
Block(-7,0,8,SMOOTH_BRICK)
Block(-7,1,-7,SMOOTH_BRICK)
Block(-7,1,-6,SMOOTH_BRICK)
Block(-7,1,-5,SMOOTH_BRICK)
Block(-7,1,-4,SMOOTH_BRICK)
Block(-7,1,-3,SMOOTH_BRICK)
Block(-7,1,-2,SMOOTH_BRICK)
Block(-7,1,-1,SMOOTH_BRICK)
Block(-7,1,0,SMOOTH_BRICK)
Block(-7,1,1,SMOOTH_BRICK)
Block(-7,1,2,SMOOTH_BRICK)
Block(-7,1,3,SMOOTH_BRICK)
Block(-7,1,4,SMOOTH_BRICK)
Block(-7,1,5,SMOOTH_BRICK)
Block(-7,1,6,SMOOTH_BRICK)
Block(-7,1,7,SMOOTH_BRICK)
Block(-7,1,8,SMOOTH_BRICK)
Block(-7,2,-7,SMOOTH_BRICK)
Block(-7,2,-6,SMOOTH_BRICK)
Block(-7,2,-5,SMOOTH_BRICK)
Block(-7,2,-4,SMOOTH_BRICK)
Block(-7,2,-3,SMOOTH_BRICK)
Block(-7,2,-2,SMOOTH_BRICK)
Block(-7,2,-1,SMOOTH_BRICK)
Block(-7,2,0,SMOOTH_BRICK)
Block(-7,2,1,SMOOTH_BRICK)
Block(-7,2,2,SMOOTH_BRICK)
Block(-7,2,3,SMOOTH_BRICK)
Block(-7,2,4,SMOOTH_BRICK)
Block(-7,2,5,SMOOTH_BRICK)
Block(-7,2,6,SMOOTH_BRICK)
Block(-7,2,7,SMOOTH_BRICK)
Block(-7,2,8,SMOOTH_BRICK)
Block(-7,3,-7,MOSSY_COBBLESTONE,50,COBBLESTONE,100)
Block(-7,3,-6,MOSSY_COBBLESTONE,50,COBBLESTONE,100)
Block(-7,3,-5,MOSSY_COBBLESTONE,50,COBBLESTONE,100)
Block(-7,3,-4,MOSSY_COBBLESTONE,50,COBBLESTONE,100)
Block(-7,3,-3,MOSSY_COBBLESTONE,50,COBBLESTONE,100)
Block(-7,3,-2,MOSSY_COBBLESTONE,50,COBBLESTONE,100)
Block(-7,3,-1,MOSSY_COBBLESTONE,50,COBBLESTONE,100)
Block(-7,3,0,MOSSY_COBBLESTONE,50,COBBLESTONE,100)
Block(-7,3,1,MOSSY_COBBLESTONE,50,COBBLESTONE,100)
Block(-7,3,2,MOSSY_COBBLESTONE,50,COBBLESTONE,100)
Block(-7,3,3,MOSSY_COBBLESTONE,50,COBBLESTONE,100)
Block(-7,3,4,MOSSY_COBBLESTONE,50,COBBLESTONE,100)
Block(-7,3,5,MOSSY_COBBLESTONE,50,COBBLESTONE,100)
Block(-7,3,6,MOSSY_COBBLESTONE,50,COBBLESTONE,100)
Block(-7,3,7,MOSSY_COBBLESTONE,50,COBBLESTONE,100)
Block(-7,3,8,MOSSY_COBBLESTONE,50,COBBLESTONE,100)
Block(-7,4,-7,MOSSY_COBBLESTONE,50,COBBLESTONE,100)
Block(-7,4,-6,MOSSY_COBBLESTONE,50,COBBLESTONE,100)
Block(-7,4,-5,MOSSY_COBBLESTONE,50,COBBLESTONE,100)
Block(-7,4,-4,MOSSY_COBBLESTONE,50,COBBLESTONE,100)
Block(-7,4,-3,MOSSY_COBBLESTONE,50,COBBLESTONE,100)
Block(-7,4,-2,MOSSY_COBBLESTONE,50,COBBLESTONE,100)
Block(-7,4,-1,MOSSY_COBBLESTONE,50,COBBLESTONE,100)
Block(-7,4,0,MOSSY_COBBLESTONE,50,COBBLESTONE,100)
Block(-7,4,1,MOSSY_COBBLESTONE,50,COBBLESTONE,100)
Block(-7,4,2,MOSSY_COBBLESTONE,50,COBBLESTONE,100)
Block(-7,4,3,MOSSY_COBBLESTONE,50,COBBLESTONE,100)
Block(-7,4,4,MOSSY_COBBLESTONE,50,COBBLESTONE,100)
Block(-7,4,5,MOSSY_COBBLESTONE,50,COBBLESTONE,100)
Block(-7,4,6,MOSSY_COBBLESTONE,50,COBBLESTONE,100)
Block(-7,4,7,MOSSY_COBBLESTONE,50,COBBLESTONE,100)
Block(-7,4,8,MOSSY_COBBLESTONE,50,COBBLESTONE,100)
Block(-7,5,-7,MOSSY_COBBLESTONE,50,COBBLESTONE,100)
Block(-7,5,-6,MOSSY_COBBLESTONE,50,COBBLESTONE,100)
Block(-7,5,-5,MOSSY_COBBLESTONE,50,COBBLESTONE,100)
Block(-7,5,-4,MOSSY_COBBLESTONE,50,COBBLESTONE,100)
Block(-7,5,-3,MOSSY_COBBLESTONE,50,COBBLESTONE,100)
Block(-7,5,-2,MOSSY_COBBLESTONE,50,COBBLESTONE,100)
Block(-7,5,-1,MOSSY_COBBLESTONE,50,COBBLESTONE,100)
Block(-7,5,0,MOSSY_COBBLESTONE,50,COBBLESTONE,100)
Block(-7,5,1,MOSSY_COBBLESTONE,50,COBBLESTONE,100)
Block(-7,5,2,MOSSY_COBBLESTONE,50,COBBLESTONE,100)
Block(-7,5,3,MOSSY_COBBLESTONE,50,COBBLESTONE,100)
Block(-7,5,4,MOSSY_COBBLESTONE,50,COBBLESTONE,100)
Block(-7,5,5,MOSSY_COBBLESTONE,50,COBBLESTONE,100)
Block(-7,5,6,MOSSY_COBBLESTONE,50,COBBLESTONE,100)
Block(-7,5,7,MOSSY_COBBLESTONE,50,COBBLESTONE,100)
Block(-7,5,8,MOSSY_COBBLESTONE,50,COBBLESTONE,100)
Block(-7,6,-7,STONE)
Block(-7,6,-6,STONE)
Block(-7,6,-5,STONE)
Block(-7,6,-4,STONE)
Block(-7,6,-3,STONE)
Block(-7,6,-2,STONE)
Block(-7,6,-1,STONE)
Block(-7,6,0,STONE)
Block(-7,6,1,STONE)
Block(-7,6,2,STONE)
Block(-7,6,3,STONE)
Block(-7,6,4,STONE)
Block(-7,6,5,STONE)
Block(-7,6,6,STONE)
Block(-7,6,7,STONE)
Block(-7,6,8,STONE)
Block(-7,7,-7,SMOOTH_BRICK)
Block(-7,7,-6,MOSSY_COBBLESTONE,50,COBBLESTONE,100)
Block(-7,7,-5,MOSSY_COBBLESTONE,50,COBBLESTONE,100)
Block(-7,7,-4,MOSSY_COBBLESTONE,50,COBBLESTONE,100)
Block(-7,7,-3,MOSSY_COBBLESTONE,50,COBBLESTONE,100)
Block(-7,7,-2,MOSSY_COBBLESTONE,50,COBBLESTONE,100)
Block(-7,7,-1,MOSSY_COBBLESTONE,50,COBBLESTONE,100)
Block(-7,7,0,MOSSY_COBBLESTONE,50,COBBLESTONE,100)
Block(-7,7,1,MOSSY_COBBLESTONE,50,COBBLESTONE,100)
Block(-7,7,2,MOSSY_COBBLESTONE,50,COBBLESTONE,100)
Block(-7,7,3,MOSSY_COBBLESTONE,50,COBBLESTONE,100)
Block(-7,7,4,MOSSY_COBBLESTONE,50,COBBLESTONE,100)
Block(-7,7,5,MOSSY_COBBLESTONE,50,COBBLESTONE,100)
Block(-7,7,6,MOSSY_COBBLESTONE,50,COBBLESTONE,100)
Block(-7,7,7,MOSSY_COBBLESTONE,50,COBBLESTONE,100)
Block(-7,7,8,MOSSY_COBBLESTONE,50,COBBLESTONE,100)
Block(-7,8,-7,AIR,25,VINE:1,100)
Block(-7,8,-6,COBBLE_WALL:1,50,COBBLE_WALL,100)
Block(-7,8,-5,MOSSY_COBBLESTONE,50,COBBLESTONE,100)
Block(-7,8,-4,COBBLE_WALL:1,50,COBBLE_WALL,100)
Block(-7,8,-3,COBBLE_WALL:1,50,COBBLE_WALL,100)
Block(-7,8,-2,MOSSY_COBBLESTONE,50,COBBLESTONE,100)
Block(-7,8,-1,COBBLE_WALL:1,50,COBBLE_WALL,100)
Block(-7,8,0,COBBLE_WALL:1,50,COBBLE_WALL,100)
Block(-7,8,1,MOSSY_COBBLESTONE,50,COBBLESTONE,100)
Block(-7,8,2,COBBLE_WALL:1,50,COBBLE_WALL,100)
Block(-7,8,3,COBBLE_WALL:1,50,COBBLE_WALL,100)
Block(-7,8,4,MOSSY_COBBLESTONE,50,COBBLESTONE,100)
Block(-7,8,5,COBBLE_WALL:1,50,COBBLE_WALL,100)
Block(-7,8,6,COBBLE_WALL:1,50,COBBLE_WALL,100)
Block(-7,8,7,MOSSY_COBBLESTONE,50,COBBLESTONE,100)
Block(-7,8,8,COBBLE_WALL:1,50,COBBLE_WALL,100)
Block(-7,9,-7,AIR,25,VINE:1,100)
Block(-7,9,-5,COBBLE_WALL:1,50,COBBLE_WALL,100)
Block(-7,9,-4,AIR,25,VINE:8,100)
Block(-7,9,-3,AIR,25,VINE:8,100)
Block(-7,9,-2,COBBLE_WALL:1,50,COBBLE_WALL,100)
Block(-7,9,-1,AIR,25,VINE:8,100)
Block(-7,9,0,AIR,25,VINE:8,100)
Block(-7,9,1,COBBLE_WALL:1,50,COBBLE_WALL,100)
Block(-7,9,2,AIR,25,VINE:8,100)
Block(-7,9,3,AIR,25,VINE:8,100)
Block(-7,9,4,COBBLE_WALL:1,50,COBBLE_WALL,100)
Block(-7,9,5,AIR,25,VINE:8,100)
Block(-7,9,6,AIR,25,VINE:8,100)
Block(-7,9,7,COBBLE_WALL:1,50,COBBLE_WALL,100)
Block(-7,9,8,AIR,25,VINE:8,100)
Block(-7,10,-7,AIR,25,VINE:1,100)
Block(-7,10,-5,COBBLE_WALL:1,50,COBBLE_WALL,100)
Block(-7,10,-4,AIR,25,VINE:8,100)
Block(-7,10,-3,AIR,25,VINE:8,100)
Block(-7,10,-2,COBBLE_WALL:1,50,COBBLE_WALL,100)
Block(-7,10,-1,AIR,25,VINE:8,100)
Block(-7,10,0,AIR,25,VINE:8,100)
Block(-7,10,1,COBBLE_WALL:1,50,COBBLE_WALL,100)
Block(-7,10,2,AIR,25,VINE:8,100)
Block(-7,10,3,AIR,25,VINE:8,100)
Block(-7,10,4,COBBLE_WALL:1,50,COBBLE_WALL,100)
Block(-7,10,5,AIR,25,VINE:8,100)
Block(-7,10,6,AIR,25,VINE:8,100)
Block(-7,10,7,COBBLE_WALL:1,50,COBBLE_WALL,100)
Block(-7,10,8,AIR,25,VINE:8,100)
Block(-7,11,-7,AIR,25,VINE:1,100)
Block(-7,11,-6,COBBLE_WALL:1,50,COBBLE_WALL,100)
Block(-7,11,-5,MOSSY_COBBLESTONE,50,COBBLESTONE,100)
Block(-7,11,-4,COBBLE_WALL:1,50,COBBLE_WALL,100)
Block(-7,11,-3,COBBLE_WALL:1,50,COBBLE_WALL,100)
Block(-7,11,-2,MOSSY_COBBLESTONE,50,COBBLESTONE,100)
Block(-7,11,-1,COBBLE_WALL:1,50,COBBLE_WALL,100)
Block(-7,11,0,COBBLE_WALL:1,50,COBBLE_WALL,100)
Block(-7,11,1,MOSSY_COBBLESTONE,50,COBBLESTONE,100)
Block(-7,11,2,COBBLE_WALL:1,50,COBBLE_WALL,100)
Block(-7,11,3,COBBLE_WALL:1,50,COBBLE_WALL,100)
Block(-7,11,4,MOSSY_COBBLESTONE,50,COBBLESTONE,100)
Block(-7,11,5,COBBLE_WALL:1,50,COBBLE_WALL,100)
Block(-7,11,6,COBBLE_WALL:1,50,COBBLE_WALL,100)
Block(-7,11,7,MOSSY_COBBLESTONE,50,COBBLESTONE,100)
Block(-7,11,8,COBBLE_WALL:1,50,COBBLE_WALL,100)
Block(-7,12,-7,AIR,25,VINE:1,100)
Block(-7,12,-6,MOSSY_COBBLESTONE,50,COBBLESTONE,100)
Block(-7,12,-5,COBBLE_WALL:1,50,COBBLE_WALL,100)
Block(-7,12,-4,MOSSY_COBBLESTONE,50,COBBLESTONE,100)
Block(-7,12,-3,MOSSY_COBBLESTONE,50,COBBLESTONE,100)
Block(-7,12,-2,COBBLE_WALL:1,50,COBBLE_WALL,100)
Block(-7,12,-1,MOSSY_COBBLESTONE,50,COBBLESTONE,100)
Block(-7,12,0,MOSSY_COBBLESTONE,50,COBBLESTONE,100)
Block(-7,12,1,COBBLE_WALL:1,50,COBBLE_WALL,100)
Block(-7,12,2,MOSSY_COBBLESTONE,50,COBBLESTONE,100)
Block(-7,12,3,MOSSY_COBBLESTONE,50,COBBLESTONE,100)
Block(-7,12,4,COBBLE_WALL:1,50,COBBLE_WALL,100)
Block(-7,12,5,MOSSY_COBBLESTONE,50,COBBLESTONE,100)
Block(-7,12,6,MOSSY_COBBLESTONE,50,COBBLESTONE,100)
Block(-7,12,7,COBBLE_WALL:1,50,COBBLE_WALL,100)
Block(-7,12,8,MOSSY_COBBLESTONE,50,COBBLESTONE,100)
Block(-6,0,-7,SMOOTH_BRICK)
Block(-6,0,-6,SMOOTH_BRICK)
Block(-6,0,-5,SMOOTH_BRICK)
Block(-6,0,-4,SMOOTH_BRICK)
Block(-6,0,-3,SMOOTH_BRICK)
Block(-6,0,-2,SMOOTH_BRICK)
Block(-6,0,-1,SMOOTH_BRICK)
Block(-6,0,0,SMOOTH_BRICK)
Block(-6,0,1,SMOOTH_BRICK)
Block(-6,0,2,SMOOTH_BRICK)
Block(-6,0,3,SMOOTH_BRICK)
Block(-6,0,4,SMOOTH_BRICK)
Block(-6,0,5,SMOOTH_BRICK)
Block(-6,0,6,SMOOTH_BRICK)
Block(-6,0,7,SMOOTH_BRICK)
Block(-6,0,8,SMOOTH_BRICK)
Block(-6,1,-7,SMOOTH_BRICK)
Block(-6,1,-6,SMOOTH_BRICK)
Block(-6,1,-5,SMOOTH_BRICK)
Block(-6,1,-4,SMOOTH_BRICK)
Block(-6,1,-3,SMOOTH_BRICK)
Block(-6,1,-2,SMOOTH_BRICK)
Block(-6,1,-1,SMOOTH_BRICK)
Block(-6,1,0,SMOOTH_BRICK)
Block(-6,1,1,SMOOTH_BRICK)
Block(-6,1,2,SMOOTH_BRICK)
Block(-6,1,3,SMOOTH_BRICK)
Block(-6,1,4,SMOOTH_BRICK)
Block(-6,1,5,SMOOTH_BRICK)
Block(-6,1,6,SMOOTH_BRICK)
Block(-6,1,7,SMOOTH_BRICK)
Block(-6,1,8,SMOOTH_BRICK)
Block(-6,2,-7,SMOOTH_BRICK)
Block(-6,2,-6,SMOOTH_BRICK)
Block(-6,2,-5,SMOOTH_BRICK)
Block(-6,2,-4,SMOOTH_BRICK)
Block(-6,2,-3,SMOOTH_BRICK)
Block(-6,2,-2,SMOOTH_BRICK)
Block(-6,2,-1,SMOOTH_BRICK)
Block(-6,2,0,SMOOTH_BRICK)
Block(-6,2,1,SMOOTH_BRICK)
Block(-6,2,2,SMOOTH_BRICK)
Block(-6,2,3,SMOOTH_BRICK)
Block(-6,2,4,SMOOTH_BRICK)
Block(-6,2,5,SMOOTH_BRICK)
Block(-6,2,6,SMOOTH_BRICK)
Block(-6,2,7,SMOOTH_BRICK)
Block(-6,2,8,SMOOTH_BRICK)
Block(-6,3,-7,MOSSY_COBBLESTONE,50,COBBLESTONE,100)
Block(-6,3,-6,MOSSY_COBBLESTONE,50,COBBLESTONE,100)
Block(-6,3,-5,MOSSY_COBBLESTONE,50,COBBLESTONE,100)
Block(-6,3,-4,MOSSY_COBBLESTONE,50,COBBLESTONE,100)
Block(-6,3,-3,MOSSY_COBBLESTONE,50,COBBLESTONE,100)
Block(-6,3,-2,MOSSY_COBBLESTONE,50,COBBLESTONE,100)
Block(-6,3,-1,MOSSY_COBBLESTONE,50,COBBLESTONE,100)
Block(-6,3,0,MOSSY_COBBLESTONE,50,COBBLESTONE,100)
Block(-6,3,1,MOSSY_COBBLESTONE,50,COBBLESTONE,100)
Block(-6,3,2,MOSSY_COBBLESTONE,50,COBBLESTONE,100)
Block(-6,3,3,MOSSY_COBBLESTONE,50,COBBLESTONE,100)
Block(-6,3,4,MOSSY_COBBLESTONE,50,COBBLESTONE,100)
Block(-6,3,5,MOSSY_COBBLESTONE,50,COBBLESTONE,100)
Block(-6,3,6,MOSSY_COBBLESTONE,50,COBBLESTONE,100)
Block(-6,3,7,MOSSY_COBBLESTONE,50,COBBLESTONE,100)
Block(-6,3,8,MOSSY_COBBLESTONE,50,COBBLESTONE,100)
Block(-6,4,-7,MOSSY_COBBLESTONE,50,COBBLESTONE,100)
Block(-6,4,-6,MOSSY_COBBLESTONE,50,COBBLESTONE,100)
Block(-6,4,-5,MOSSY_COBBLESTONE,50,COBBLESTONE,100)
Block(-6,4,-4,MOSSY_COBBLESTONE,50,COBBLESTONE,100)
Block(-6,4,-3,MOSSY_COBBLESTONE,50,COBBLESTONE,100)
Block(-6,4,-2,MOSSY_COBBLESTONE,50,COBBLESTONE,100)
Block(-6,4,-1,MOSSY_COBBLESTONE,50,COBBLESTONE,100)
Block(-6,4,0,MOSSY_COBBLESTONE,50,COBBLESTONE,100)
Block(-6,4,1,MOSSY_COBBLESTONE,50,COBBLESTONE,100)
Block(-6,4,2,MOSSY_COBBLESTONE,50,COBBLESTONE,100)
Block(-6,4,3,MOSSY_COBBLESTONE,50,COBBLESTONE,100)
Block(-6,4,4,MOSSY_COBBLESTONE,50,COBBLESTONE,100)
Block(-6,4,5,MOSSY_COBBLESTONE,50,COBBLESTONE,100)
Block(-6,4,6,MOSSY_COBBLESTONE,50,COBBLESTONE,100)
Block(-6,4,7,MOSSY_COBBLESTONE,50,COBBLESTONE,100)
Block(-6,4,8,MOSSY_COBBLESTONE,50,COBBLESTONE,100)
Block(-6,5,-7,MOSSY_COBBLESTONE,50,COBBLESTONE,100)
Block(-6,5,-6,MOSSY_COBBLESTONE,50,COBBLESTONE,100)
Block(-6,5,-5,MOSSY_COBBLESTONE,50,COBBLESTONE,100)
Block(-6,5,-4,MOSSY_COBBLESTONE,50,COBBLESTONE,100)
Block(-6,5,-3,MOSSY_COBBLESTONE,50,COBBLESTONE,100)
Block(-6,5,-2,MOSSY_COBBLESTONE,50,COBBLESTONE,100)
Block(-6,5,-1,MOSSY_COBBLESTONE,50,COBBLESTONE,100)
Block(-6,5,0,MOSSY_COBBLESTONE,50,COBBLESTONE,100)
Block(-6,5,1,MOSSY_COBBLESTONE,50,COBBLESTONE,100)
Block(-6,5,2,MOSSY_COBBLESTONE,50,COBBLESTONE,100)
Block(-6,5,3,MOSSY_COBBLESTONE,50,COBBLESTONE,100)
Block(-6,5,4,MOSSY_COBBLESTONE,50,COBBLESTONE,100)
Block(-6,5,5,MOSSY_COBBLESTONE,50,COBBLESTONE,100)
Block(-6,5,6,MOSSY_COBBLESTONE,50,COBBLESTONE,100)
Block(-6,5,7,MOSSY_COBBLESTONE,50,COBBLESTONE,100)
Block(-6,5,8,MOSSY_COBBLESTONE,50,COBBLESTONE,100)
Block(-6,6,-7,STONE)
Block(-6,6,-6,STONE)
Block(-6,6,-5,STONE)
Block(-6,6,-4,STONE)
Block(-6,6,-3,STONE)
Block(-6,6,-2,STONE)
Block(-6,6,-1,STONE)
Block(-6,6,0,STONE)
Block(-6,6,1,STONE)
Block(-6,6,2,STONE)
Block(-6,6,3,STONE)
Block(-6,6,4,STONE)
Block(-6,6,5,STONE)
Block(-6,6,6,STONE)
Block(-6,6,7,STONE)
Block(-6,6,8,STONE)
Block(-6,7,-7,SMOOTH_BRICK)
Block(-6,7,-6,MOSSY_COBBLESTONE,50,COBBLESTONE,100)
Block(-6,7,-5,MOSSY_COBBLESTONE,50,COBBLESTONE,100)
Block(-6,7,-4,MOSSY_COBBLESTONE,50,COBBLESTONE,100)
Block(-6,7,-3,MOSSY_COBBLESTONE,50,COBBLESTONE,100)
Block(-6,7,-2,MOSSY_COBBLESTONE,50,COBBLESTONE,100)
Block(-6,7,-1,MOSSY_COBBLESTONE,50,COBBLESTONE,100)
Block(-6,7,0,MOSSY_COBBLESTONE,50,COBBLESTONE,100)
Block(-6,7,1,MOSSY_COBBLESTONE,50,COBBLESTONE,100)
Block(-6,7,2,MOSSY_COBBLESTONE,50,COBBLESTONE,100)
Block(-6,7,3,MOSSY_COBBLESTONE,50,COBBLESTONE,100)
Block(-6,7,4,MOSSY_COBBLESTONE,50,COBBLESTONE,100)
Block(-6,7,5,MOSSY_COBBLESTONE,50,COBBLESTONE,100)
Block(-6,7,6,MOSSY_COBBLESTONE,50,COBBLESTONE,100)
Block(-6,7,7,MOSSY_COBBLESTONE,50,COBBLESTONE,100)
Block(-6,7,8,MOSSY_COBBLESTONE,50,COBBLESTONE,100)
Block(-6,8,-7,COBBLE_WALL:1,50,COBBLE_WALL,100)
Block(-6,8,-6,MOSSY_COBBLESTONE,50,COBBLESTONE,100)
Block(-6,8,-5,MOSSY_COBBLESTONE,50,COBBLESTONE,100)
Block(-6,8,-4,MOSSY_COBBLESTONE,50,COBBLESTONE,100)
Block(-6,8,-3,MOSSY_COBBLESTONE,50,COBBLESTONE,100)
Block(-6,8,-2,MOSSY_COBBLESTONE,50,COBBLESTONE,100)
Block(-6,8,-1,MOSSY_COBBLESTONE,50,COBBLESTONE,100)
Block(-6,8,0,MOSSY_COBBLESTONE,50,COBBLESTONE,100)
Block(-6,8,1,MOSSY_COBBLESTONE,50,COBBLESTONE,100)
Block(-6,8,2,MOSSY_COBBLESTONE,50,COBBLESTONE,100)
Block(-6,8,3,MOSSY_COBBLESTONE,50,COBBLESTONE,100)
Block(-6,8,4,MOSSY_COBBLESTONE,50,COBBLESTONE,100)
Block(-6,8,5,MOSSY_COBBLESTONE,50,COBBLESTONE,100)
Block(-6,8,6,MOSSY_COBBLESTONE,50,COBBLESTONE,100)
Block(-6,8,7,MOSSY_COBBLESTONE,50,COBBLESTONE,100)
Block(-6,8,8,MOSSY_COBBLESTONE,50,COBBLESTONE,100)
Block(-6,9,-6,COBBLE_WALL:1,50,COBBLE_WALL,100)
Block(-6,9,-5,SMOOTH_BRICK:3)
Block(-6,9,-4,SMOOTH_BRICK:3)
Block(-6,9,-3,SMOOTH_BRICK:3)
Block(-6,9,-2,SMOOTH_BRICK:3)
Block(-6,9,-1,SMOOTH_BRICK:3)
Block(-6,9,0,SMOOTH_BRICK:3)
Block(-6,9,1,SMOOTH_BRICK:3)
Block(-6,9,2,SMOOTH_BRICK:3)
Block(-6,9,3,SMOOTH_BRICK:3)
Block(-6,9,4,SMOOTH_BRICK:3)
Block(-6,9,5,SMOOTH_BRICK:3)
Block(-6,9,6,SMOOTH_BRICK:3)
Block(-6,9,7,SMOOTH_BRICK:3)
Block(-6,9,8,SMOOTH_BRICK:3)
Block(-6,10,-6,COBBLE_WALL:1,50,COBBLE_WALL,100)
Block(-6,10,-5,SMOOTH_BRICK:3)
Block(-6,10,-4,SMOOTH_BRICK:3)
Block(-6,10,-3,SMOOTH_BRICK:3)
Block(-6,10,-2,SMOOTH_BRICK:3)
Block(-6,10,-1,SMOOTH_BRICK:3)
Block(-6,10,0,SMOOTH_BRICK:3)
Block(-6,10,1,SMOOTH_BRICK:3)
Block(-6,10,2,SMOOTH_BRICK:3)
Block(-6,10,3,SMOOTH_BRICK:3)
Block(-6,10,4,SMOOTH_BRICK:3)
Block(-6,10,5,SMOOTH_BRICK:3)
Block(-6,10,6,SMOOTH_BRICK:3)
Block(-6,10,7,SMOOTH_BRICK:3)
Block(-6,10,8,SMOOTH_BRICK:3)
Block(-6,11,-7,COBBLESTONE_STAIRS:6)
Block(-6,11,-6,MOSSY_COBBLESTONE,50,COBBLESTONE,100)
Block(-6,11,-5,SMOOTH_BRICK)
Block(-6,11,-4,SMOOTH_BRICK)
Block(-6,11,-3,SMOOTH_BRICK)
Block(-6,11,-2,SMOOTH_BRICK)
Block(-6,11,-1,SMOOTH_BRICK)
Block(-6,11,0,SMOOTH_BRICK)
Block(-6,11,1,SMOOTH_BRICK)
Block(-6,11,2,SMOOTH_BRICK)
Block(-6,11,3,SMOOTH_BRICK)
Block(-6,11,4,SMOOTH_BRICK)
Block(-6,11,5,SMOOTH_BRICK)
Block(-6,11,6,SMOOTH_BRICK)
Block(-6,11,7,SMOOTH_BRICK)
Block(-6,11,8,SMOOTH_BRICK)
Block(-6,12,-7,76:5)
Block(-6,12,-6,COBBLE_WALL:1,50,COBBLE_WALL,100)
Block(-5,0,-7,SMOOTH_BRICK)
Block(-5,0,-6,SMOOTH_BRICK)
Block(-5,0,-5,SMOOTH_BRICK)
Block(-5,0,-4,SMOOTH_BRICK)
Block(-5,0,-3,SMOOTH_BRICK)
Block(-5,0,-2,SMOOTH_BRICK)
Block(-5,0,-1,SMOOTH_BRICK)
Block(-5,0,0,SMOOTH_BRICK)
Block(-5,0,1,SMOOTH_BRICK)
Block(-5,0,2,SMOOTH_BRICK)
Block(-5,0,3,SMOOTH_BRICK)
Block(-5,0,4,SMOOTH_BRICK)
Block(-5,0,5,SMOOTH_BRICK)
Block(-5,0,6,SMOOTH_BRICK)
Block(-5,0,7,SMOOTH_BRICK)
Block(-5,0,8,SMOOTH_BRICK)
Block(-5,1,-7,SMOOTH_BRICK)
Block(-5,1,-6,SMOOTH_BRICK)
Block(-5,1,-5,SMOOTH_BRICK)
Block(-5,1,-4,SMOOTH_BRICK)
Block(-5,1,-3,SMOOTH_BRICK)
Block(-5,1,-2,SMOOTH_BRICK)
Block(-5,1,-1,SMOOTH_BRICK)
Block(-5,1,0,SMOOTH_BRICK)
Block(-5,1,1,SMOOTH_BRICK)
Block(-5,1,2,SMOOTH_BRICK)
Block(-5,1,3,SMOOTH_BRICK)
Block(-5,1,4,SMOOTH_BRICK)
Block(-5,1,5,SMOOTH_BRICK)
Block(-5,1,6,SMOOTH_BRICK)
Block(-5,1,7,SMOOTH_BRICK)
Block(-5,1,8,SMOOTH_BRICK)
Block(-5,2,-7,SMOOTH_BRICK)
Block(-5,2,-6,SMOOTH_BRICK)
Block(-5,2,-5,SMOOTH_BRICK)
Block(-5,2,-4,SMOOTH_BRICK)
Block(-5,2,-3,SMOOTH_BRICK)
Block(-5,2,-2,SMOOTH_BRICK)
Block(-5,2,-1,SMOOTH_BRICK)
Block(-5,2,0,SMOOTH_BRICK)
Block(-5,2,1,SMOOTH_BRICK)
Block(-5,2,2,SMOOTH_BRICK)
Block(-5,2,3,SMOOTH_BRICK)
Block(-5,2,4,SMOOTH_BRICK)
Block(-5,2,5,SMOOTH_BRICK)
Block(-5,2,6,SMOOTH_BRICK)
Block(-5,2,7,SMOOTH_BRICK)
Block(-5,2,8,SMOOTH_BRICK)
Block(-5,3,-7,MOSSY_COBBLESTONE,50,COBBLESTONE,100)
Block(-5,3,-6,MOSSY_COBBLESTONE,50,COBBLESTONE,100)
Block(-5,3,-5,MOSSY_COBBLESTONE,50,COBBLESTONE,100)
Block(-5,3,-4,MOSSY_COBBLESTONE,50,COBBLESTONE,100)
Block(-5,3,-3,MOSSY_COBBLESTONE,50,COBBLESTONE,100)
Block(-5,3,-2,MOSSY_COBBLESTONE,50,COBBLESTONE,100)
Block(-5,3,-1,MOSSY_COBBLESTONE,50,COBBLESTONE,100)
Block(-5,3,0,MOSSY_COBBLESTONE,50,COBBLESTONE,100)
Block(-5,3,1,MOSSY_COBBLESTONE,50,COBBLESTONE,100)
Block(-5,3,2,MOSSY_COBBLESTONE,50,COBBLESTONE,100)
Block(-5,3,3,MOSSY_COBBLESTONE,50,COBBLESTONE,100)
Block(-5,3,4,MOSSY_COBBLESTONE,50,COBBLESTONE,100)
Block(-5,3,5,MOSSY_COBBLESTONE,50,COBBLESTONE,100)
Block(-5,3,6,MOSSY_COBBLESTONE,50,COBBLESTONE,100)
Block(-5,3,7,MOSSY_COBBLESTONE,50,COBBLESTONE,100)
Block(-5,3,8,MOSSY_COBBLESTONE,50,COBBLESTONE,100)
Block(-5,4,-7,MOSSY_COBBLESTONE,50,COBBLESTONE,100)
Block(-5,4,-6,MOSSY_COBBLESTONE,50,COBBLESTONE,100)
Block(-5,4,-5,MOSSY_COBBLESTONE,50,COBBLESTONE,100)
Block(-5,4,-4,MOSSY_COBBLESTONE,50,COBBLESTONE,100)
Block(-5,4,-3,MOSSY_COBBLESTONE,50,COBBLESTONE,100)
Block(-5,4,-2,MOSSY_COBBLESTONE,50,COBBLESTONE,100)
Block(-5,4,-1,MOSSY_COBBLESTONE,50,COBBLESTONE,100)
Block(-5,4,0,MOSSY_COBBLESTONE,50,COBBLESTONE,100)
Block(-5,4,1,MOSSY_COBBLESTONE,50,COBBLESTONE,100)
Block(-5,4,2,MOSSY_COBBLESTONE,50,COBBLESTONE,100)
Block(-5,4,3,MOSSY_COBBLESTONE,50,COBBLESTONE,100)
Block(-5,4,4,MOSSY_COBBLESTONE,50,COBBLESTONE,100)
Block(-5,4,5,MOSSY_COBBLESTONE,50,COBBLESTONE,100)
Block(-5,4,6,MOSSY_COBBLESTONE,50,COBBLESTONE,100)
Block(-5,4,7,MOSSY_COBBLESTONE,50,COBBLESTONE,100)
Block(-5,4,8,MOSSY_COBBLESTONE,50,COBBLESTONE,100)
Block(-5,5,-7,MOSSY_COBBLESTONE,50,COBBLESTONE,100)
Block(-5,5,-6,MOSSY_COBBLESTONE,50,COBBLESTONE,100)
Block(-5,5,-5,MOSSY_COBBLESTONE,50,COBBLESTONE,100)
Block(-5,5,-4,MOSSY_COBBLESTONE,50,COBBLESTONE,100)
Block(-5,5,-3,MOSSY_COBBLESTONE,50,COBBLESTONE,100)
Block(-5,5,-2,MOSSY_COBBLESTONE,50,COBBLESTONE,100)
Block(-5,5,-1,MOSSY_COBBLESTONE,50,COBBLESTONE,100)
Block(-5,5,0,MOSSY_COBBLESTONE,50,COBBLESTONE,100)
Block(-5,5,1,MOSSY_COBBLESTONE,50,COBBLESTONE,100)
Block(-5,5,2,MOSSY_COBBLESTONE,50,COBBLESTONE,100)
Block(-5,5,3,MOSSY_COBBLESTONE,50,COBBLESTONE,100)
Block(-5,5,4,MOSSY_COBBLESTONE,50,COBBLESTONE,100)
Block(-5,5,5,MOSSY_COBBLESTONE,50,COBBLESTONE,100)
Block(-5,5,6,MOSSY_COBBLESTONE,50,COBBLESTONE,100)
Block(-5,5,7,MOSSY_COBBLESTONE,50,COBBLESTONE,100)
Block(-5,5,8,MOSSY_COBBLESTONE,50,COBBLESTONE,100)
Block(-5,6,-7,STONE)
Block(-5,6,-6,STONE)
Block(-5,6,-5,STONE)
Block(-5,6,-4,STONE)
Block(-5,6,-3,STONE)
Block(-5,6,-2,STONE)
Block(-5,6,-1,STONE)
Block(-5,6,0,STONE)
Block(-5,6,1,STONE)
Block(-5,6,2,STONE)
Block(-5,6,3,STONE)
Block(-5,6,4,STONE)
Block(-5,6,5,STONE)
Block(-5,6,6,STONE)
Block(-5,6,7,STONE)
Block(-5,6,8,STONE)
Block(-5,7,-7,SMOOTH_BRICK)
Block(-5,7,-6,MOSSY_COBBLESTONE,50,COBBLESTONE,100)
Block(-5,7,-5,MOSSY_COBBLESTONE,50,COBBLESTONE,100)
Block(-5,7,-4,MOSSY_COBBLESTONE,50,COBBLESTONE,100)
Block(-5,7,-3,MOSSY_COBBLESTONE,50,COBBLESTONE,100)
Block(-5,7,-2,MOSSY_COBBLESTONE,50,COBBLESTONE,100)
Block(-5,7,-1,MOSSY_COBBLESTONE,50,COBBLESTONE,100)
Block(-5,7,0,MOSSY_COBBLESTONE,50,COBBLESTONE,100)
Block(-5,7,1,MOSSY_COBBLESTONE,50,COBBLESTONE,100)
Block(-5,7,2,MOSSY_COBBLESTONE,50,COBBLESTONE,100)
Block(-5,7,3,MOSSY_COBBLESTONE,50,COBBLESTONE,100)
Block(-5,7,4,MOSSY_COBBLESTONE,50,COBBLESTONE,100)
Block(-5,7,5,MOSSY_COBBLESTONE,50,COBBLESTONE,100)
Block(-5,7,6,MOSSY_COBBLESTONE,50,COBBLESTONE,100)
Block(-5,7,7,MOSSY_COBBLESTONE,50,COBBLESTONE,100)
Block(-5,7,8,MOSSY_COBBLESTONE,50,COBBLESTONE,100)
Block(-5,8,-7,AIR,25,VINE:1,100)
Block(-5,8,-6,COBBLE_WALL:1,50,COBBLE_WALL,100)
Block(-5,8,-5,MOSSY_COBBLESTONE,50,COBBLESTONE,100)
Block(-5,8,-4,MOSSY_COBBLESTONE,50,COBBLESTONE,100)
Block(-5,8,-3,MOSSY_COBBLESTONE,50,COBBLESTONE,100)
Block(-5,8,-2,MOSSY_COBBLESTONE,50,COBBLESTONE,100)
Block(-5,8,-1,MOSSY_COBBLESTONE,50,COBBLESTONE,100)
Block(-5,8,0,MOSSY_COBBLESTONE,50,COBBLESTONE,100)
Block(-5,8,1,MOSSY_COBBLESTONE,50,COBBLESTONE,100)
Block(-5,8,2,MOSSY_COBBLESTONE,50,COBBLESTONE,100)
Block(-5,8,3,MOSSY_COBBLESTONE,50,COBBLESTONE,100)
Block(-5,8,4,MOSSY_COBBLESTONE,50,COBBLESTONE,100)
Block(-5,8,5,MOSSY_COBBLESTONE,50,COBBLESTONE,100)
Block(-5,8,6,MOSSY_COBBLESTONE,50,COBBLESTONE,100)
Block(-5,8,7,MOSSY_COBBLESTONE,50,COBBLESTONE,100)
Block(-5,8,8,MOSSY_COBBLESTONE,50,COBBLESTONE,100)
Block(-5,9,-7,AIR,25,VINE:1,100)
Block(-5,9,-6,AIR,25,VINE:1,100)
Block(-5,9,-5,SMOOTH_BRICK:3)
Block(-5,9,-4,MOSSY_COBBLESTONE,50,COBBLESTONE,100)
Block(-5,9,-3,MOSSY_COBBLESTONE,50,COBBLESTONE,100)
Block(-5,9,-2,MOSSY_COBBLESTONE,50,COBBLESTONE,100)
Block(-5,9,-1,MOSSY_COBBLESTONE,50,COBBLESTONE,100)
Block(-5,9,0,MOSSY_COBBLESTONE,50,COBBLESTONE,100)
Block(-5,9,1,MOSSY_COBBLESTONE,50,COBBLESTONE,100)
Block(-5,9,2,MOSSY_COBBLESTONE,50,COBBLESTONE,100)
Block(-5,9,3,MOSSY_COBBLESTONE,50,COBBLESTONE,100)
Block(-5,9,4,MOSSY_COBBLESTONE,50,COBBLESTONE,100)
Block(-5,9,5,MOSSY_COBBLESTONE,50,COBBLESTONE,100)
Block(-5,9,6,MOSSY_COBBLESTONE,50,COBBLESTONE,100)
Block(-5,9,7,MOSSY_COBBLESTONE,50,COBBLESTONE,100)
Block(-5,9,8,MOSSY_COBBLESTONE,50,COBBLESTONE,100)
Block(-5,10,-7,AIR,25,VINE:1,100)
Block(-5,10,-6,AIR,25,VINE:1,100)
Block(-5,10,-5,SMOOTH_BRICK:3)
Block(-5,10,-4,MOSSY_COBBLESTONE,50,COBBLESTONE,100)
Block(-5,10,-3,MOSSY_COBBLESTONE,50,COBBLESTONE,100)
Block(-5,10,-2,MOSSY_COBBLESTONE,50,COBBLESTONE,100)
Block(-5,10,-1,MOSSY_COBBLESTONE,50,COBBLESTONE,100)
Block(-5,10,0,MOSSY_COBBLESTONE,50,COBBLESTONE,100)
Block(-5,10,1,MOSSY_COBBLESTONE,50,COBBLESTONE,100)
Block(-5,10,2,MOSSY_COBBLESTONE,50,COBBLESTONE,100)
Block(-5,10,3,MOSSY_COBBLESTONE,50,COBBLESTONE,100)
Block(-5,10,4,MOSSY_COBBLESTONE,50,COBBLESTONE,100)
Block(-5,10,5,MOSSY_COBBLESTONE,50,COBBLESTONE,100)
Block(-5,10,6,MOSSY_COBBLESTONE,50,COBBLESTONE,100)
Block(-5,10,7,MOSSY_COBBLESTONE,50,COBBLESTONE,100)
Block(-5,10,8,MOSSY_COBBLESTONE,50,COBBLESTONE,100)
Block(-5,11,-7,AIR,25,VINE:1,100)
Block(-5,11,-6,COBBLE_WALL:1,50,COBBLE_WALL,100)
Block(-5,11,-5,SMOOTH_BRICK)
Block(-5,11,-4,SMOOTH_BRICK)
Block(-5,11,-3,SMOOTH_BRICK)
Block(-5,11,-2,SMOOTH_BRICK)
Block(-5,11,-1,SMOOTH_BRICK)
Block(-5,11,0,SMOOTH_BRICK)
Block(-5,11,1,SMOOTH_BRICK)
Block(-5,11,2,SMOOTH_BRICK)
Block(-5,11,3,SMOOTH_BRICK)
Block(-5,11,4,SMOOTH_BRICK)
Block(-5,11,5,SMOOTH_BRICK)
Block(-5,11,6,SMOOTH_BRICK)
Block(-5,11,7,SMOOTH_BRICK)
Block(-5,11,8,SMOOTH_BRICK)
Block(-5,12,-7,AIR,25,VINE:1,100)
Block(-5,12,-6,MOSSY_COBBLESTONE,50,COBBLESTONE,100)
Block(-4,0,-7,SMOOTH_BRICK)
Block(-4,0,-6,SMOOTH_BRICK)
Block(-4,0,-5,SMOOTH_BRICK)
Block(-4,0,-4,SMOOTH_BRICK)
Block(-4,0,-3,SMOOTH_BRICK)
Block(-4,0,-2,SMOOTH_BRICK)
Block(-4,0,-1,SMOOTH_BRICK)
Block(-4,0,0,SMOOTH_BRICK)
Block(-4,0,1,SMOOTH_BRICK)
Block(-4,0,2,SMOOTH_BRICK)
Block(-4,0,3,SMOOTH_BRICK)
Block(-4,0,4,SMOOTH_BRICK)
Block(-4,0,5,SMOOTH_BRICK)
Block(-4,0,6,SMOOTH_BRICK)
Block(-4,0,7,SMOOTH_BRICK)
Block(-4,0,8,SMOOTH_BRICK)
Block(-4,1,-7,SMOOTH_BRICK)
Block(-4,1,-6,SMOOTH_BRICK)
Block(-4,1,-5,SMOOTH_BRICK)
Block(-4,1,-4,SMOOTH_BRICK)
Block(-4,1,-3,SMOOTH_BRICK)
Block(-4,1,-2,SMOOTH_BRICK)
Block(-4,1,-1,SMOOTH_BRICK)
Block(-4,1,0,SMOOTH_BRICK)
Block(-4,1,1,SMOOTH_BRICK)
Block(-4,1,2,SMOOTH_BRICK)
Block(-4,1,3,SMOOTH_BRICK)
Block(-4,1,4,SMOOTH_BRICK)
Block(-4,1,5,SMOOTH_BRICK)
Block(-4,1,6,SMOOTH_BRICK)
Block(-4,1,7,SMOOTH_BRICK)
Block(-4,1,8,SMOOTH_BRICK)
Block(-4,2,-7,SMOOTH_BRICK)
Block(-4,2,-6,SMOOTH_BRICK)
Block(-4,2,-5,SMOOTH_BRICK)
Block(-4,2,-4,SMOOTH_BRICK)
Block(-4,2,-3,SMOOTH_BRICK)
Block(-4,2,-2,SMOOTH_BRICK)
Block(-4,2,-1,SMOOTH_BRICK)
Block(-4,2,0,SMOOTH_BRICK)
Block(-4,2,1,SMOOTH_BRICK)
Block(-4,2,2,SMOOTH_BRICK)
Block(-4,2,3,SMOOTH_BRICK)
Block(-4,2,4,SMOOTH_BRICK)
Block(-4,2,5,SMOOTH_BRICK)
Block(-4,2,6,SMOOTH_BRICK)
Block(-4,2,7,SMOOTH_BRICK)
Block(-4,2,8,SMOOTH_BRICK)
Block(-4,3,-7,MOSSY_COBBLESTONE,50,COBBLESTONE,100)
Block(-4,3,-6,MOSSY_COBBLESTONE,50,COBBLESTONE,100)
Block(-4,3,-5,MOSSY_COBBLESTONE,50,COBBLESTONE,100)
Block(-4,3,-4,MOSSY_COBBLESTONE,50,COBBLESTONE,100)
Block(-4,3,-3,MOSSY_COBBLESTONE,50,COBBLESTONE,100)
Block(-4,3,-2,MOSSY_COBBLESTONE,50,COBBLESTONE,100)
Block(-4,3,-1,MOSSY_COBBLESTONE,50,COBBLESTONE,100)
Block(-4,3,0,MOSSY_COBBLESTONE,50,COBBLESTONE,100)
Block(-4,3,1,MOSSY_COBBLESTONE,50,COBBLESTONE,100)
Block(-4,3,2,MOSSY_COBBLESTONE,50,COBBLESTONE,100)
Block(-4,3,3,MOSSY_COBBLESTONE,50,COBBLESTONE,100)
Block(-4,3,4,MOSSY_COBBLESTONE,50,COBBLESTONE,100)
Block(-4,3,5,MOSSY_COBBLESTONE,50,COBBLESTONE,100)
Block(-4,3,6,MOSSY_COBBLESTONE,50,COBBLESTONE,100)
Block(-4,3,7,MOSSY_COBBLESTONE,50,COBBLESTONE,100)
Block(-4,3,8,MOSSY_COBBLESTONE,50,COBBLESTONE,100)
Block(-4,4,-7,MOSSY_COBBLESTONE,50,COBBLESTONE,100)
Block(-4,4,-6,MOSSY_COBBLESTONE,50,COBBLESTONE,100)
Block(-4,4,-5,MOSSY_COBBLESTONE,50,COBBLESTONE,100)
Block(-4,4,-4,MOSSY_COBBLESTONE,50,COBBLESTONE,100)
Block(-4,4,-3,MOSSY_COBBLESTONE,50,COBBLESTONE,100)
Block(-4,4,-2,MOSSY_COBBLESTONE,50,COBBLESTONE,100)
Block(-4,4,-1,MOSSY_COBBLESTONE,50,COBBLESTONE,100)
Block(-4,4,0,MOSSY_COBBLESTONE,50,COBBLESTONE,100)
Block(-4,4,1,MOSSY_COBBLESTONE,50,COBBLESTONE,100)
Block(-4,4,2,MOSSY_COBBLESTONE,50,COBBLESTONE,100)
Block(-4,4,3,MOSSY_COBBLESTONE,50,COBBLESTONE,100)
Block(-4,4,4,MOSSY_COBBLESTONE,50,COBBLESTONE,100)
Block(-4,4,5,MOSSY_COBBLESTONE,50,COBBLESTONE,100)
Block(-4,4,6,MOSSY_COBBLESTONE,50,COBBLESTONE,100)
Block(-4,4,7,MOSSY_COBBLESTONE,50,COBBLESTONE,100)
Block(-4,4,8,MOSSY_COBBLESTONE,50,COBBLESTONE,100)
Block(-4,5,-7,MOSSY_COBBLESTONE,50,COBBLESTONE,100)
Block(-4,5,-6,MOSSY_COBBLESTONE,50,COBBLESTONE,100)
Block(-4,5,-5,MOSSY_COBBLESTONE,50,COBBLESTONE,100)
Block(-4,5,-4,MOSSY_COBBLESTONE,50,COBBLESTONE,100)
Block(-4,5,-3,MOSSY_COBBLESTONE,50,COBBLESTONE,100)
Block(-4,5,-2,MOSSY_COBBLESTONE,50,COBBLESTONE,100)
Block(-4,5,-1,MOSSY_COBBLESTONE,50,COBBLESTONE,100)
Block(-4,5,0,MOSSY_COBBLESTONE,50,COBBLESTONE,100)
Block(-4,5,1,MOSSY_COBBLESTONE,50,COBBLESTONE,100)
Block(-4,5,2,MOSSY_COBBLESTONE,50,COBBLESTONE,100)
Block(-4,5,3,MOSSY_COBBLESTONE,50,COBBLESTONE,100)
Block(-4,5,4,MOSSY_COBBLESTONE,50,COBBLESTONE,100)
Block(-4,5,5,MOSSY_COBBLESTONE,50,COBBLESTONE,100)
Block(-4,5,6,MOSSY_COBBLESTONE,50,COBBLESTONE,100)
Block(-4,5,7,MOSSY_COBBLESTONE,50,COBBLESTONE,100)
Block(-4,5,8,MOSSY_COBBLESTONE,50,COBBLESTONE,100)
Block(-4,6,-7,STONE)
Block(-4,6,-6,STONE)
Block(-4,6,-5,STONE)
Block(-4,6,-4,STONE)
Block(-4,6,-3,STONE)
Block(-4,6,-2,STONE)
Block(-4,6,-1,STONE)
Block(-4,6,0,STONE)
Block(-4,6,1,STONE)
Block(-4,6,2,STONE)
Block(-4,6,3,STONE)
Block(-4,6,4,STONE)
Block(-4,6,5,STONE)
Block(-4,6,6,STONE)
Block(-4,6,7,STONE)
Block(-4,6,8,STONE)
Block(-4,7,-7,SMOOTH_BRICK)
Block(-4,7,-6,MOSSY_COBBLESTONE,50,COBBLESTONE,100)
Block(-4,7,-5,MOSSY_COBBLESTONE,50,COBBLESTONE,100)
Block(-4,7,-4,MOSSY_COBBLESTONE,50,COBBLESTONE,100)
Block(-4,7,-3,MOSSY_COBBLESTONE,50,COBBLESTONE,100)
Block(-4,7,-2,MOSSY_COBBLESTONE,50,COBBLESTONE,100)
Block(-4,7,-1,MOSSY_COBBLESTONE,50,COBBLESTONE,100)
Block(-4,7,0,MOSSY_COBBLESTONE,50,COBBLESTONE,100)
Block(-4,7,1,MOSSY_COBBLESTONE,50,COBBLESTONE,100)
Block(-4,7,2,MOSSY_COBBLESTONE,50,COBBLESTONE,100)
Block(-4,7,3,MOSSY_COBBLESTONE,50,COBBLESTONE,100)
Block(-4,7,4,MOSSY_COBBLESTONE,50,COBBLESTONE,100)
Block(-4,7,5,MOSSY_COBBLESTONE,50,COBBLESTONE,100)
Block(-4,7,6,MOSSY_COBBLESTONE,50,COBBLESTONE,100)
Block(-4,7,7,MOSSY_COBBLESTONE,50,COBBLESTONE,100)
Block(-4,7,8,MOSSY_COBBLESTONE,50,COBBLESTONE,100)
Block(-4,8,-7,AIR,25,VINE:1,100)
Block(-4,8,-6,COBBLE_WALL:1,50,COBBLE_WALL,100)
Block(-4,8,-5,MOSSY_COBBLESTONE,50,COBBLESTONE,100)
Block(-4,8,-4,MOSSY_COBBLESTONE,50,COBBLESTONE,100)
Block(-4,8,-3,MOSSY_COBBLESTONE,50,COBBLESTONE,100)
Block(-4,8,-2,MOSSY_COBBLESTONE,50,COBBLESTONE,100)
Block(-4,8,-1,MOSSY_COBBLESTONE,50,COBBLESTONE,100)
Block(-4,8,0,MOSSY_COBBLESTONE,50,COBBLESTONE,100)
Block(-4,8,1,MOSSY_COBBLESTONE,50,COBBLESTONE,100)
Block(-4,8,2,MOSSY_COBBLESTONE,50,COBBLESTONE,100)
Block(-4,8,3,MOSSY_COBBLESTONE,50,COBBLESTONE,100)
Block(-4,8,4,MOSSY_COBBLESTONE,50,COBBLESTONE,100)
Block(-4,8,5,MOSSY_COBBLESTONE,50,COBBLESTONE,100)
Block(-4,8,6,MOSSY_COBBLESTONE,50,COBBLESTONE,100)
Block(-4,8,7,MOSSY_COBBLESTONE,50,COBBLESTONE,100)
Block(-4,8,8,MOSSY_COBBLESTONE,50,COBBLESTONE,100)
Block(-4,9,-7,AIR,25,VINE:1,100)
Block(-4,9,-6,AIR,25,VINE:1,100)
Block(-4,9,-5,SMOOTH_BRICK:3)
Block(-4,9,-4,MOSSY_COBBLESTONE,50,COBBLESTONE,100)
Block(-4,9,-3,MOSSY_COBBLESTONE,50,COBBLESTONE,100)
Block(-4,9,-2,MOSSY_COBBLESTONE,50,COBBLESTONE,100)
Block(-4,9,-1,MOSSY_COBBLESTONE,50,COBBLESTONE,100)
Block(-4,9,0,MOSSY_COBBLESTONE,50,COBBLESTONE,100)
Block(-4,9,1,MOSSY_COBBLESTONE,50,COBBLESTONE,100)
Block(-4,9,2,MOSSY_COBBLESTONE,50,COBBLESTONE,100)
Block(-4,9,3,MOSSY_COBBLESTONE,50,COBBLESTONE,100)
Block(-4,9,4,MOSSY_COBBLESTONE,50,COBBLESTONE,100)
Block(-4,9,5,MOSSY_COBBLESTONE,50,COBBLESTONE,100)
Block(-4,9,6,MOSSY_COBBLESTONE,50,COBBLESTONE,100)
Block(-4,9,7,MOSSY_COBBLESTONE,50,COBBLESTONE,100)
Block(-4,9,8,MOSSY_COBBLESTONE,50,COBBLESTONE,100)
Block(-4,10,-7,AIR,25,VINE:1,100)
Block(-4,10,-6,AIR,25,VINE:1,100)
Block(-4,10,-5,SMOOTH_BRICK:3)
Block(-4,10,-4,MOSSY_COBBLESTONE,50,COBBLESTONE,100)
Block(-4,10,-3,MOSSY_COBBLESTONE,50,COBBLESTONE,100)
Block(-4,10,-2,MOSSY_COBBLESTONE,50,COBBLESTONE,100)
Block(-4,10,-1,MOSSY_COBBLESTONE,50,COBBLESTONE,100)
Block(-4,10,0,MOSSY_COBBLESTONE,50,COBBLESTONE,100)
Block(-4,10,1,MOSSY_COBBLESTONE,50,COBBLESTONE,100)
Block(-4,10,2,MOSSY_COBBLESTONE,50,COBBLESTONE,100)
Block(-4,10,3,MOSSY_COBBLESTONE,50,COBBLESTONE,100)
Block(-4,10,4,MOSSY_COBBLESTONE,50,COBBLESTONE,100)
Block(-4,10,5,MOSSY_COBBLESTONE,50,COBBLESTONE,100)
Block(-4,10,6,MOSSY_COBBLESTONE,50,COBBLESTONE,100)
Block(-4,10,7,MOSSY_COBBLESTONE,50,COBBLESTONE,100)
Block(-4,10,8,MOSSY_COBBLESTONE,50,COBBLESTONE,100)
Block(-4,11,-7,AIR,25,VINE:1,100)
Block(-4,11,-6,COBBLE_WALL:1,50,COBBLE_WALL,100)
Block(-4,11,-5,SMOOTH_BRICK)
Block(-4,11,-4,SMOOTH_BRICK)
Block(-4,11,-3,SMOOTH_BRICK)
Block(-4,11,-2,SMOOTH_BRICK)
Block(-4,11,-1,SMOOTH_BRICK)
Block(-4,11,0,SMOOTH_BRICK)
Block(-4,11,1,SMOOTH_BRICK)
Block(-4,11,2,SMOOTH_BRICK)
Block(-4,11,3,SMOOTH_BRICK)
Block(-4,11,4,SMOOTH_BRICK)
Block(-4,11,5,SMOOTH_BRICK)
Block(-4,11,6,SMOOTH_BRICK)
Block(-4,11,7,SMOOTH_BRICK)
Block(-4,11,8,SMOOTH_BRICK)
Block(-4,12,-7,AIR,25,VINE:1,100)
Block(-4,12,-6,MOSSY_COBBLESTONE,50,COBBLESTONE,100)
Block(-4,12,-2,AIR,25,VINE:8,100)
Block(-4,12,-1,COBBLE_WALL:1,50,COBBLE_WALL,100)
Block(-4,12,0,AIR,25,VINE:8,100)
Block(-4,12,1,AIR,25,VINE:8,100)
Block(-4,12,2,COBBLE_WALL:1,50,COBBLE_WALL,100)
Block(-4,12,3,AIR,25,VINE:8,100)
Block(-4,12,4,AIR,25,VINE:8,100)
Block(-4,12,5,COBBLE_WALL:1,50,COBBLE_WALL,100)
Block(-4,12,6,AIR,25,VINE:8,100)
Block(-4,12,7,AIR,25,VINE:8,100)
Block(-4,12,8,COBBLE_WALL:1,50,COBBLE_WALL,100)
Block(-4,13,-2,AIR,25,VINE:8,100)
Block(-4,13,0,AIR,25,VINE:8,100)
Block(-4,13,1,AIR,25,VINE:8,100)
Block(-4,13,3,AIR,25,VINE:8,100)
Block(-4,13,4,AIR,25,VINE:8,100)
Block(-4,13,6,AIR,25,VINE:8,100)
Block(-4,13,7,AIR,25,VINE:8,100)
Block(-4,14,-2,AIR,25,VINE:8,100)
Block(-4,14,0,AIR,25,VINE:8,100)
Block(-4,14,1,AIR,25,VINE:8,100)
Block(-4,14,3,AIR,25,VINE:8,100)
Block(-4,14,4,AIR,25,VINE:8,100)
Block(-4,14,6,AIR,25,VINE:8,100)
Block(-4,14,7,AIR,25,VINE:8,100)
Block(-4,15,-2,AIR,25,VINE:8,100)
Block(-4,15,-1,COBBLESTONE_STAIRS:4)
Block(-4,15,0,AIR,25,VINE:8,100)
Block(-4,15,1,AIR,25,VINE:8,100)
Block(-4,15,2,COBBLESTONE_STAIRS:4)
Block(-4,15,3,AIR,25,VINE:8,100)
Block(-4,15,4,AIR,25,VINE:8,100)
Block(-4,15,5,COBBLESTONE_STAIRS:4)
Block(-4,15,6,AIR,25,VINE:8,100)
Block(-4,15,7,AIR,25,VINE:8,100)
Block(-4,15,8,COBBLESTONE_STAIRS:4)
Block(-4,16,-2,AIR,25,VINE:8,100)
Block(-4,16,-1,76:5)
Block(-4,16,0,AIR,25,VINE:8,100)
Block(-4,16,1,AIR,25,VINE:8,100)
Block(-4,16,2,76:5)
Block(-4,16,3,AIR,25,VINE:8,100)
Block(-4,16,4,AIR,25,VINE:8,100)
Block(-4,16,5,76:5)
Block(-4,16,6,AIR,25,VINE:8,100)
Block(-4,16,7,AIR,25,VINE:8,100)
Block(-4,16,8,76:5)
Block(-3,0,-7,SMOOTH_BRICK)
Block(-3,0,-6,SMOOTH_BRICK)
Block(-3,0,-5,SMOOTH_BRICK)
Block(-3,0,-4,SMOOTH_BRICK)
Block(-3,0,-3,SMOOTH_BRICK)
Block(-3,0,-2,SMOOTH_BRICK)
Block(-3,0,-1,SMOOTH_BRICK)
Block(-3,0,0,SMOOTH_BRICK)
Block(-3,0,1,SMOOTH_BRICK)
Block(-3,0,2,SMOOTH_BRICK)
Block(-3,0,3,SMOOTH_BRICK)
Block(-3,0,4,SMOOTH_BRICK)
Block(-3,0,5,SMOOTH_BRICK)
Block(-3,0,6,SMOOTH_BRICK)
Block(-3,0,7,SMOOTH_BRICK)
Block(-3,0,8,SMOOTH_BRICK)
Block(-3,1,-7,SMOOTH_BRICK)
Block(-3,1,-6,SMOOTH_BRICK)
Block(-3,1,-5,SMOOTH_BRICK)
Block(-3,1,-4,SMOOTH_BRICK)
Block(-3,1,-3,SMOOTH_BRICK)
Block(-3,1,-2,SMOOTH_BRICK)
Block(-3,1,-1,SMOOTH_BRICK)
Block(-3,1,0,SMOOTH_BRICK)
Block(-3,1,1,SMOOTH_BRICK)
Block(-3,1,2,SMOOTH_BRICK)
Block(-3,1,3,SMOOTH_BRICK)
Block(-3,1,4,SMOOTH_BRICK)
Block(-3,1,5,SMOOTH_BRICK)
Block(-3,1,6,SMOOTH_BRICK)
Block(-3,1,7,SMOOTH_BRICK)
Block(-3,1,8,SMOOTH_BRICK)
Block(-3,2,-7,SMOOTH_BRICK)
Block(-3,2,-6,SMOOTH_BRICK)
Block(-3,2,-5,SMOOTH_BRICK)
Block(-3,2,-4,SMOOTH_BRICK)
Block(-3,2,-3,SMOOTH_BRICK)
Block(-3,2,-2,SMOOTH_BRICK)
Block(-3,2,-1,SMOOTH_BRICK)
Block(-3,2,0,SMOOTH_BRICK)
Block(-3,2,1,SMOOTH_BRICK)
Block(-3,2,2,SMOOTH_BRICK)
Block(-3,2,3,SMOOTH_BRICK)
Block(-3,2,4,SMOOTH_BRICK)
Block(-3,2,5,SMOOTH_BRICK)
Block(-3,2,6,SMOOTH_BRICK)
Block(-3,2,7,SMOOTH_BRICK)
Block(-3,2,8,SMOOTH_BRICK)
Block(-3,3,-7,MOSSY_COBBLESTONE,50,COBBLESTONE,100)
Block(-3,3,-6,MOSSY_COBBLESTONE,50,COBBLESTONE,100)
Block(-3,3,-5,MOSSY_COBBLESTONE,50,COBBLESTONE,100)
Block(-3,3,-4,MOSSY_COBBLESTONE,50,COBBLESTONE,100)
Block(-3,3,-3,MOSSY_COBBLESTONE,50,COBBLESTONE,100)
Block(-3,3,-2,MOSSY_COBBLESTONE,50,COBBLESTONE,100)
Block(-3,3,-1,MOSSY_COBBLESTONE,50,COBBLESTONE,100)
Block(-3,3,0,MOSSY_COBBLESTONE,50,COBBLESTONE,100)
Block(-3,3,1,MOSSY_COBBLESTONE,50,COBBLESTONE,100)
Block(-3,3,2,MOSSY_COBBLESTONE,50,COBBLESTONE,100)
Block(-3,3,3,MOSSY_COBBLESTONE,50,COBBLESTONE,100)
Block(-3,3,4,MOSSY_COBBLESTONE,50,COBBLESTONE,100)
Block(-3,3,5,MOSSY_COBBLESTONE,50,COBBLESTONE,100)
Block(-3,3,6,MOSSY_COBBLESTONE,50,COBBLESTONE,100)
Block(-3,3,7,MOSSY_COBBLESTONE,50,COBBLESTONE,100)
Block(-3,3,8,MOSSY_COBBLESTONE,50,COBBLESTONE,100)
Block(-3,4,-7,MOSSY_COBBLESTONE,50,COBBLESTONE,100)
Block(-3,4,-6,MOSSY_COBBLESTONE,50,COBBLESTONE,100)
Block(-3,4,-5,MOSSY_COBBLESTONE,50,COBBLESTONE,100)
Block(-3,4,-4,MOSSY_COBBLESTONE,50,COBBLESTONE,100)
Block(-3,4,-3,MOSSY_COBBLESTONE,50,COBBLESTONE,100)
Block(-3,4,-2,MOSSY_COBBLESTONE,50,COBBLESTONE,100)
Block(-3,4,-1,MOSSY_COBBLESTONE,50,COBBLESTONE,100)
Block(-3,4,0,MOSSY_COBBLESTONE,50,COBBLESTONE,100)
Block(-3,4,1,MOSSY_COBBLESTONE,50,COBBLESTONE,100)
Block(-3,4,2,MOSSY_COBBLESTONE,50,COBBLESTONE,100)
Block(-3,4,3,MOSSY_COBBLESTONE,50,COBBLESTONE,100)
Block(-3,4,4,MOSSY_COBBLESTONE,50,COBBLESTONE,100)
Block(-3,4,5,MOSSY_COBBLESTONE,50,COBBLESTONE,100)
Block(-3,4,6,MOSSY_COBBLESTONE,50,COBBLESTONE,100)
Block(-3,4,7,MOSSY_COBBLESTONE,50,COBBLESTONE,100)
Block(-3,4,8,MOSSY_COBBLESTONE,50,COBBLESTONE,100)
Block(-3,5,-7,MOSSY_COBBLESTONE,50,COBBLESTONE,100)
Block(-3,5,-6,MOSSY_COBBLESTONE,50,COBBLESTONE,100)
Block(-3,5,-5,MOSSY_COBBLESTONE,50,COBBLESTONE,100)
Block(-3,5,-4,MOSSY_COBBLESTONE,50,COBBLESTONE,100)
Block(-3,5,-3,MOSSY_COBBLESTONE,50,COBBLESTONE,100)
Block(-3,5,-2,MOSSY_COBBLESTONE,50,COBBLESTONE,100)
Block(-3,5,-1,MOSSY_COBBLESTONE,50,COBBLESTONE,100)
Block(-3,5,0,MOSSY_COBBLESTONE,50,COBBLESTONE,100)
Block(-3,5,1,MOSSY_COBBLESTONE,50,COBBLESTONE,100)
Block(-3,5,2,MOSSY_COBBLESTONE,50,COBBLESTONE,100)
Block(-3,5,3,MOSSY_COBBLESTONE,50,COBBLESTONE,100)
Block(-3,5,4,MOSSY_COBBLESTONE,50,COBBLESTONE,100)
Block(-3,5,5,MOSSY_COBBLESTONE,50,COBBLESTONE,100)
Block(-3,5,6,MOSSY_COBBLESTONE,50,COBBLESTONE,100)
Block(-3,5,7,MOSSY_COBBLESTONE,50,COBBLESTONE,100)
Block(-3,5,8,MOSSY_COBBLESTONE,50,COBBLESTONE,100)
Block(-3,6,-7,STONE)
Block(-3,6,-6,STONE)
Block(-3,6,-5,STONE)
Block(-3,6,-4,STONE)
Block(-3,6,-3,STONE)
Block(-3,6,-2,STONE)
Block(-3,6,-1,STONE)
Block(-3,6,0,STONE)
Block(-3,6,1,STONE)
Block(-3,6,2,STONE)
Block(-3,6,3,STONE)
Block(-3,6,4,STONE)
Block(-3,6,5,STONE)
Block(-3,6,6,STONE)
Block(-3,6,7,STONE)
Block(-3,6,8,STONE)
Block(-3,7,-7,SMOOTH_BRICK)
Block(-3,7,-6,MOSSY_COBBLESTONE,50,COBBLESTONE,100)
Block(-3,7,-5,MOSSY_COBBLESTONE,50,COBBLESTONE,100)
Block(-3,7,-4,MOSSY_COBBLESTONE,50,COBBLESTONE,100)
Block(-3,7,-3,MOSSY_COBBLESTONE,50,COBBLESTONE,100)
Block(-3,7,-2,MOSSY_COBBLESTONE,50,COBBLESTONE,100)
Block(-3,7,-1,MOSSY_COBBLESTONE,50,COBBLESTONE,100)
Block(-3,7,0,MOSSY_COBBLESTONE,50,COBBLESTONE,100)
Block(-3,7,1,MOSSY_COBBLESTONE,50,COBBLESTONE,100)
Block(-3,7,2,MOSSY_COBBLESTONE,50,COBBLESTONE,100)
Block(-3,7,3,MOSSY_COBBLESTONE,50,COBBLESTONE,100)
Block(-3,7,4,MOSSY_COBBLESTONE,50,COBBLESTONE,100)
Block(-3,7,5,MOSSY_COBBLESTONE,50,COBBLESTONE,100)
Block(-3,7,6,MOSSY_COBBLESTONE,50,COBBLESTONE,100)
Block(-3,7,7,MOSSY_COBBLESTONE,50,COBBLESTONE,100)
Block(-3,7,8,MOSSY_COBBLESTONE,50,COBBLESTONE,100)
Block(-3,8,-7,COBBLE_WALL:1,50,COBBLE_WALL,100)
Block(-3,8,-6,MOSSY_COBBLESTONE,50,COBBLESTONE,100)
Block(-3,8,-5,MOSSY_COBBLESTONE,50,COBBLESTONE,100)
Block(-3,8,-4,MOSSY_COBBLESTONE,50,COBBLESTONE,100)
Block(-3,8,-3,MOSSY_COBBLESTONE,50,COBBLESTONE,100)
Block(-3,8,-2,MOSSY_COBBLESTONE,50,COBBLESTONE,100)
Block(-3,8,-1,MOSSY_COBBLESTONE,50,COBBLESTONE,100)
Block(-3,8,0,MOSSY_COBBLESTONE,50,COBBLESTONE,100)
Block(-3,8,1,MOSSY_COBBLESTONE,50,COBBLESTONE,100)
Block(-3,8,2,MOSSY_COBBLESTONE,50,COBBLESTONE,100)
Block(-3,8,3,MOSSY_COBBLESTONE,50,COBBLESTONE,100)
Block(-3,8,4,MOSSY_COBBLESTONE,50,COBBLESTONE,100)
Block(-3,8,5,MOSSY_COBBLESTONE,50,COBBLESTONE,100)
Block(-3,8,6,MOSSY_COBBLESTONE,50,COBBLESTONE,100)
Block(-3,8,7,MOSSY_COBBLESTONE,50,COBBLESTONE,100)
Block(-3,8,8,MOSSY_COBBLESTONE,50,COBBLESTONE,100)
Block(-3,9,-6,COBBLE_WALL:1,50,COBBLE_WALL,100)
Block(-3,9,-5,SMOOTH_BRICK:3)
Block(-3,9,-4,MOSSY_COBBLESTONE,50,COBBLESTONE,100)
Block(-3,9,-3,MOSSY_COBBLESTONE,50,COBBLESTONE,100)
Block(-3,9,-2,MOSSY_COBBLESTONE,50,COBBLESTONE,100)
Block(-3,9,-1,MOSSY_COBBLESTONE,50,COBBLESTONE,100)
Block(-3,9,0,MOSSY_COBBLESTONE,50,COBBLESTONE,100)
Block(-3,9,1,MOSSY_COBBLESTONE,50,COBBLESTONE,100)
Block(-3,9,2,MOSSY_COBBLESTONE,50,COBBLESTONE,100)
Block(-3,9,3,MOSSY_COBBLESTONE,50,COBBLESTONE,100)
Block(-3,9,4,MOSSY_COBBLESTONE,50,COBBLESTONE,100)
Block(-3,9,5,MOSSY_COBBLESTONE,50,COBBLESTONE,100)
Block(-3,9,6,MOSSY_COBBLESTONE,50,COBBLESTONE,100)
Block(-3,9,7,MOSSY_COBBLESTONE,50,COBBLESTONE,100)
Block(-3,9,8,MOSSY_COBBLESTONE,50,COBBLESTONE,100)
Block(-3,10,-6,COBBLE_WALL:1,50,COBBLE_WALL,100)
Block(-3,10,-5,SMOOTH_BRICK:3)
Block(-3,10,-4,MOSSY_COBBLESTONE,50,COBBLESTONE,100)
Block(-3,10,-3,MOSSY_COBBLESTONE,50,COBBLESTONE,100)
Block(-3,10,-2,MOSSY_COBBLESTONE,50,COBBLESTONE,100)
Block(-3,10,-1,MOSSY_COBBLESTONE,50,COBBLESTONE,100)
Block(-3,10,0,MOSSY_COBBLESTONE,50,COBBLESTONE,100)
Block(-3,10,1,MOSSY_COBBLESTONE,50,COBBLESTONE,100)
Block(-3,10,2,MOSSY_COBBLESTONE,50,COBBLESTONE,100)
Block(-3,10,3,MOSSY_COBBLESTONE,50,COBBLESTONE,100)
Block(-3,10,4,MOSSY_COBBLESTONE,50,COBBLESTONE,100)
Block(-3,10,5,MOSSY_COBBLESTONE,50,COBBLESTONE,100)
Block(-3,10,6,MOSSY_COBBLESTONE,50,COBBLESTONE,100)
Block(-3,10,7,MOSSY_COBBLESTONE,50,COBBLESTONE,100)
Block(-3,10,8,MOSSY_COBBLESTONE,50,COBBLESTONE,100)
Block(-3,11,-7,COBBLESTONE_STAIRS:6)
Block(-3,11,-6,MOSSY_COBBLESTONE,50,COBBLESTONE,100)
Block(-3,11,-5,SMOOTH_BRICK)
Block(-3,11,-4,SMOOTH_BRICK)
Block(-3,11,-3,SMOOTH_BRICK)
Block(-3,11,-2,MOSSY_COBBLESTONE,50,COBBLESTONE,100)
Block(-3,11,-1,MOSSY_COBBLESTONE,50,COBBLESTONE,100)
Block(-3,11,0,MOSSY_COBBLESTONE,50,COBBLESTONE,100)
Block(-3,11,1,MOSSY_COBBLESTONE,50,COBBLESTONE,100)
Block(-3,11,2,MOSSY_COBBLESTONE,50,COBBLESTONE,100)
Block(-3,11,3,MOSSY_COBBLESTONE,50,COBBLESTONE,100)
Block(-3,11,4,MOSSY_COBBLESTONE,50,COBBLESTONE,100)
Block(-3,11,5,MOSSY_COBBLESTONE,50,COBBLESTONE,100)
Block(-3,11,6,MOSSY_COBBLESTONE,50,COBBLESTONE,100)
Block(-3,11,7,MOSSY_COBBLESTONE,50,COBBLESTONE,100)
Block(-3,11,8,MOSSY_COBBLESTONE,50,COBBLESTONE,100)
Block(-3,12,-7,76:5)
Block(-3,12,-6,COBBLE_WALL:1,50,COBBLE_WALL,100)
Block(-3,12,-3,AIR,25,VINE:1,100)
Block(-3,12,-2,COBBLE_WALL:1,50,COBBLE_WALL,100)
Block(-3,12,-1,MOSSY_COBBLESTONE,50,COBBLESTONE,100)
Block(-3,12,0,COBBLE_WALL:1,50,COBBLE_WALL,100)
Block(-3,12,1,COBBLE_WALL:1,50,COBBLE_WALL,100)
Block(-3,12,2,MOSSY_COBBLESTONE,50,COBBLESTONE,100)
Block(-3,12,3,COBBLE_WALL:1,50,COBBLE_WALL,100)
Block(-3,12,4,COBBLE_WALL:1,50,COBBLE_WALL,100)
Block(-3,12,5,MOSSY_COBBLESTONE,50,COBBLESTONE,100)
Block(-3,12,6,COBBLE_WALL:1,50,COBBLE_WALL,100)
Block(-3,12,7,COBBLE_WALL:1,50,COBBLE_WALL,100)
Block(-3,12,8,MOSSY_COBBLESTONE,50,COBBLESTONE,100)
Block(-3,13,-3,AIR,25,VINE:1,100)
Block(-3,13,-1,COBBLE_WALL:1,50,COBBLE_WALL,100)
Block(-3,13,0,AIR,25,VINE:8,100)
Block(-3,13,1,AIR,25,VINE:8,100)
Block(-3,13,2,COBBLE_WALL:1,50,COBBLE_WALL,100)
Block(-3,13,3,AIR,25,VINE:8,100)
Block(-3,13,4,AIR,25,VINE:8,100)
Block(-3,13,5,COBBLE_WALL:1,50,COBBLE_WALL,100)
Block(-3,13,6,AIR,25,VINE:8,100)
Block(-3,13,7,AIR,25,VINE:8,100)
Block(-3,13,8,COBBLE_WALL:1,50,COBBLE_WALL,100)
Block(-3,14,-3,AIR,25,VINE:1,100)
Block(-3,14,-1,COBBLE_WALL:1,50,COBBLE_WALL,100)
Block(-3,14,0,AIR,25,VINE:8,100)
Block(-3,14,1,AIR,25,VINE:8,100)
Block(-3,14,2,COBBLE_WALL:1,50,COBBLE_WALL,100)
Block(-3,14,3,AIR,25,VINE:8,100)
Block(-3,14,4,AIR,25,VINE:8,100)
Block(-3,14,5,COBBLE_WALL:1,50,COBBLE_WALL,100)
Block(-3,14,6,AIR,25,VINE:8,100)
Block(-3,14,7,AIR,25,VINE:8,100)
Block(-3,14,8,COBBLE_WALL:1,50,COBBLE_WALL,100)
Block(-3,15,-3,AIR,25,VINE:1,100)
Block(-3,15,-2,COBBLE_WALL:1,50,COBBLE_WALL,100)
Block(-3,15,-1,MOSSY_COBBLESTONE,50,COBBLESTONE,100)
Block(-3,15,0,COBBLE_WALL:1,50,COBBLE_WALL,100)
Block(-3,15,1,COBBLE_WALL:1,50,COBBLE_WALL,100)
Block(-3,15,2,MOSSY_COBBLESTONE,50,COBBLESTONE,100)
Block(-3,15,3,COBBLE_WALL:1,50,COBBLE_WALL,100)
Block(-3,15,4,COBBLE_WALL:1,50,COBBLE_WALL,100)
Block(-3,15,5,MOSSY_COBBLESTONE,50,COBBLESTONE,100)
Block(-3,15,6,COBBLE_WALL:1,50,COBBLE_WALL,100)
Block(-3,15,7,COBBLE_WALL:1,50,COBBLE_WALL,100)
Block(-3,15,8,MOSSY_COBBLESTONE,50,COBBLESTONE,100)
Block(-3,16,-3,AIR,25,VINE:1,100)
Block(-3,16,-2,MOSSY_COBBLESTONE,50,COBBLESTONE,100)
Block(-3,16,-1,COBBLE_WALL:1,50,COBBLE_WALL,100)
Block(-3,16,0,MOSSY_COBBLESTONE,50,COBBLESTONE,100)
Block(-3,16,1,MOSSY_COBBLESTONE,50,COBBLESTONE,100)
Block(-3,16,2,COBBLE_WALL:1,50,COBBLE_WALL,100)
Block(-3,16,3,MOSSY_COBBLESTONE,50,COBBLESTONE,100)
Block(-3,16,4,MOSSY_COBBLESTONE,50,COBBLESTONE,100)
Block(-3,16,5,COBBLE_WALL:1,50,COBBLE_WALL,100)
Block(-3,16,6,MOSSY_COBBLESTONE,50,COBBLESTONE,100)
Block(-3,16,7,MOSSY_COBBLESTONE,50,COBBLESTONE,100)
Block(-3,16,8,COBBLE_WALL:1,50,COBBLE_WALL,100)
Block(-2,0,-7,SMOOTH_BRICK)
Block(-2,0,-6,SMOOTH_BRICK)
Block(-2,0,-5,SMOOTH_BRICK)
Block(-2,0,-4,SMOOTH_BRICK)
Block(-2,0,-3,SMOOTH_BRICK)
Block(-2,0,-2,SMOOTH_BRICK)
Block(-2,0,-1,SMOOTH_BRICK)
Block(-2,0,0,SMOOTH_BRICK)
Block(-2,0,1,SMOOTH_BRICK)
Block(-2,0,2,SMOOTH_BRICK)
Block(-2,0,3,SMOOTH_BRICK)
Block(-2,0,4,SMOOTH_BRICK)
Block(-2,0,5,SMOOTH_BRICK)
Block(-2,0,6,SMOOTH_BRICK)
Block(-2,0,7,SMOOTH_BRICK)
Block(-2,0,8,SMOOTH_BRICK)
Block(-2,1,-7,SMOOTH_BRICK)
Block(-2,1,-6,SMOOTH_BRICK)
Block(-2,1,-5,SMOOTH_BRICK)
Block(-2,1,-4,SMOOTH_BRICK)
Block(-2,1,-3,SMOOTH_BRICK)
Block(-2,1,-2,SMOOTH_BRICK)
Block(-2,1,-1,SMOOTH_BRICK)
Block(-2,1,0,SMOOTH_BRICK)
Block(-2,1,1,SMOOTH_BRICK)
Block(-2,1,2,SMOOTH_BRICK)
Block(-2,1,3,SMOOTH_BRICK)
Block(-2,1,4,SMOOTH_BRICK)
Block(-2,1,5,SMOOTH_BRICK)
Block(-2,1,6,SMOOTH_BRICK)
Block(-2,1,7,SMOOTH_BRICK)
Block(-2,1,8,SMOOTH_BRICK)
Block(-2,2,-7,SMOOTH_BRICK)
Block(-2,2,-6,SMOOTH_BRICK)
Block(-2,2,-5,SMOOTH_BRICK)
Block(-2,2,-4,SMOOTH_BRICK)
Block(-2,2,-3,SMOOTH_BRICK)
Block(-2,2,-2,SMOOTH_BRICK)
Block(-2,2,-1,SMOOTH_BRICK)
Block(-2,2,0,SMOOTH_BRICK)
Block(-2,2,1,SMOOTH_BRICK)
Block(-2,2,2,SMOOTH_BRICK)
Block(-2,2,3,SMOOTH_BRICK)
Block(-2,2,4,SMOOTH_BRICK)
Block(-2,2,5,SMOOTH_BRICK)
Block(-2,2,6,SMOOTH_BRICK)
Block(-2,2,7,SMOOTH_BRICK)
Block(-2,2,8,SMOOTH_BRICK)
Block(-2,3,-7,MOSSY_COBBLESTONE,50,COBBLESTONE,100)
Block(-2,3,-6,MOSSY_COBBLESTONE,50,COBBLESTONE,100)
Block(-2,3,-5,MOSSY_COBBLESTONE,50,COBBLESTONE,100)
Block(-2,3,-4,MOSSY_COBBLESTONE,50,COBBLESTONE,100)
Block(-2,3,-3,MOSSY_COBBLESTONE,50,COBBLESTONE,100)
Block(-2,3,-2,MOSSY_COBBLESTONE,50,COBBLESTONE,100)
Block(-2,3,-1,MOSSY_COBBLESTONE,50,COBBLESTONE,100)
Block(-2,3,0,MOSSY_COBBLESTONE,50,COBBLESTONE,100)
Block(-2,3,1,MOSSY_COBBLESTONE,50,COBBLESTONE,100)
Block(-2,3,2,MOSSY_COBBLESTONE,50,COBBLESTONE,100)
Block(-2,3,3,MOSSY_COBBLESTONE,50,COBBLESTONE,100)
Block(-2,3,4,MOSSY_COBBLESTONE,50,COBBLESTONE,100)
Block(-2,3,5,MOSSY_COBBLESTONE,50,COBBLESTONE,100)
Block(-2,3,6,MOSSY_COBBLESTONE,50,COBBLESTONE,100)
Block(-2,3,7,MOSSY_COBBLESTONE,50,COBBLESTONE,100)
Block(-2,3,8,MOSSY_COBBLESTONE,50,COBBLESTONE,100)
Block(-2,4,-7,MOSSY_COBBLESTONE,50,COBBLESTONE,100)
Block(-2,4,-6,MOSSY_COBBLESTONE,50,COBBLESTONE,100)
Block(-2,4,-5,MOSSY_COBBLESTONE,50,COBBLESTONE,100)
Block(-2,4,-4,MOSSY_COBBLESTONE,50,COBBLESTONE,100)
Block(-2,4,-3,MOSSY_COBBLESTONE,50,COBBLESTONE,100)
Block(-2,4,-2,MOSSY_COBBLESTONE,50,COBBLESTONE,100)
Block(-2,4,-1,MOSSY_COBBLESTONE,50,COBBLESTONE,100)
Block(-2,4,0,MOSSY_COBBLESTONE,50,COBBLESTONE,100)
Block(-2,4,1,MOSSY_COBBLESTONE,50,COBBLESTONE,100)
Block(-2,4,2,MOSSY_COBBLESTONE,50,COBBLESTONE,100)
Block(-2,4,3,MOSSY_COBBLESTONE,50,COBBLESTONE,100)
Block(-2,4,4,MOSSY_COBBLESTONE,50,COBBLESTONE,100)
Block(-2,4,5,MOSSY_COBBLESTONE,50,COBBLESTONE,100)
Block(-2,4,6,MOSSY_COBBLESTONE,50,COBBLESTONE,100)
Block(-2,4,7,MOSSY_COBBLESTONE,50,COBBLESTONE,100)
Block(-2,4,8,MOSSY_COBBLESTONE,50,COBBLESTONE,100)
Block(-2,5,-7,MOSSY_COBBLESTONE,50,COBBLESTONE,100)
Block(-2,5,-6,MOSSY_COBBLESTONE,50,COBBLESTONE,100)
Block(-2,5,-5,MOSSY_COBBLESTONE,50,COBBLESTONE,100)
Block(-2,5,-4,MOSSY_COBBLESTONE,50,COBBLESTONE,100)
Block(-2,5,-3,MOSSY_COBBLESTONE,50,COBBLESTONE,100)
Block(-2,5,-2,MOSSY_COBBLESTONE,50,COBBLESTONE,100)
Block(-2,5,-1,MOSSY_COBBLESTONE,50,COBBLESTONE,100)
Block(-2,5,0,MOSSY_COBBLESTONE,50,COBBLESTONE,100)
Block(-2,5,1,MOSSY_COBBLESTONE,50,COBBLESTONE,100)
Block(-2,5,2,MOSSY_COBBLESTONE,50,COBBLESTONE,100)
Block(-2,5,3,MOSSY_COBBLESTONE,50,COBBLESTONE,100)
Block(-2,5,4,MOSSY_COBBLESTONE,50,COBBLESTONE,100)
Block(-2,5,5,MOSSY_COBBLESTONE,50,COBBLESTONE,100)
Block(-2,5,6,MOSSY_COBBLESTONE,50,COBBLESTONE,100)
Block(-2,5,7,MOSSY_COBBLESTONE,50,COBBLESTONE,100)
Block(-2,5,8,MOSSY_COBBLESTONE,50,COBBLESTONE,100)
Block(-2,6,-7,STONE)
Block(-2,6,-6,STONE)
Block(-2,6,-5,STONE)
Block(-2,6,-4,STONE)
Block(-2,6,-3,STONE)
Block(-2,6,-2,STONE)
Block(-2,6,-1,STONE)
Block(-2,6,0,STONE)
Block(-2,6,1,STONE)
Block(-2,6,2,STONE)
Block(-2,6,3,STONE)
Block(-2,6,4,STONE)
Block(-2,6,5,STONE)
Block(-2,6,6,STONE)
Block(-2,6,7,STONE)
Block(-2,6,8,STONE)
Block(-2,7,-7,SMOOTH_BRICK)
Block(-2,7,-6,MOSSY_COBBLESTONE,50,COBBLESTONE,100)
Block(-2,7,-5,MOSSY_COBBLESTONE,50,COBBLESTONE,100)
Block(-2,7,-4,MOSSY_COBBLESTONE,50,COBBLESTONE,100)
Block(-2,7,-3,MOSSY_COBBLESTONE,50,COBBLESTONE,100)
Block(-2,7,-2,MOSSY_COBBLESTONE,50,COBBLESTONE,100)
Block(-2,7,-1,MOSSY_COBBLESTONE,50,COBBLESTONE,100)
Block(-2,7,0,MOSSY_COBBLESTONE,50,COBBLESTONE,100)
Block(-2,7,1,MOSSY_COBBLESTONE,50,COBBLESTONE,100)
Block(-2,7,2,MOSSY_COBBLESTONE,50,COBBLESTONE,100)
Block(-2,7,3,MOSSY_COBBLESTONE,50,COBBLESTONE,100)
Block(-2,7,4,MOSSY_COBBLESTONE,50,COBBLESTONE,100)
Block(-2,7,5,MOSSY_COBBLESTONE,50,COBBLESTONE,100)
Block(-2,7,6,MOSSY_COBBLESTONE,50,COBBLESTONE,100)
Block(-2,7,7,MOSSY_COBBLESTONE,50,COBBLESTONE,100)
Block(-2,7,8,MOSSY_COBBLESTONE,50,COBBLESTONE,100)
Block(-2,8,-7,AIR,25,VINE:1,100)
Block(-2,8,-6,COBBLE_WALL:1,50,COBBLE_WALL,100)
Block(-2,8,-5,MOSSY_COBBLESTONE,50,COBBLESTONE,100)
Block(-2,8,-4,MOSSY_COBBLESTONE,50,COBBLESTONE,100)
Block(-2,8,-3,MOSSY_COBBLESTONE,50,COBBLESTONE,100)
Block(-2,8,-2,MOSSY_COBBLESTONE,50,COBBLESTONE,100)
Block(-2,8,-1,MOSSY_COBBLESTONE,50,COBBLESTONE,100)
Block(-2,8,0,MOSSY_COBBLESTONE,50,COBBLESTONE,100)
Block(-2,8,1,MOSSY_COBBLESTONE,50,COBBLESTONE,100)
Block(-2,8,2,MOSSY_COBBLESTONE,50,COBBLESTONE,100)
Block(-2,8,3,MOSSY_COBBLESTONE,50,COBBLESTONE,100)
Block(-2,8,4,MOSSY_COBBLESTONE,50,COBBLESTONE,100)
Block(-2,8,5,MOSSY_COBBLESTONE,50,COBBLESTONE,100)
Block(-2,8,6,MOSSY_COBBLESTONE,50,COBBLESTONE,100)
Block(-2,8,7,MOSSY_COBBLESTONE,50,COBBLESTONE,100)
Block(-2,8,8,MOSSY_COBBLESTONE,50,COBBLESTONE,100)
Block(-2,9,-7,AIR,25,VINE:1,100)
Block(-2,9,-6,AIR,25,VINE:1,100)
Block(-2,9,-5,SMOOTH_BRICK:3)
Block(-2,9,-4,MOSSY_COBBLESTONE,50,COBBLESTONE,100)
Block(-2,9,-3,MOSSY_COBBLESTONE,50,COBBLESTONE,100)
Block(-2,9,-2,MOSSY_COBBLESTONE,50,COBBLESTONE,100)
Block(-2,9,-1,MOSSY_COBBLESTONE,50,COBBLESTONE,100)
Block(-2,9,0,MOSSY_COBBLESTONE,50,COBBLESTONE,100)
Block(-2,9,1,MOSSY_COBBLESTONE,50,COBBLESTONE,100)
Block(-2,9,2,MOSSY_COBBLESTONE,50,COBBLESTONE,100)
Block(-2,9,3,MOSSY_COBBLESTONE,50,COBBLESTONE,100)
Block(-2,9,4,MOSSY_COBBLESTONE,50,COBBLESTONE,100)
Block(-2,9,5,MOSSY_COBBLESTONE,50,COBBLESTONE,100)
Block(-2,9,6,MOSSY_COBBLESTONE,50,COBBLESTONE,100)
Block(-2,9,7,MOSSY_COBBLESTONE,50,COBBLESTONE,100)
Block(-2,9,8,MOSSY_COBBLESTONE,50,COBBLESTONE,100)
Block(-2,10,-7,AIR,25,VINE:1,100)
Block(-2,10,-6,AIR,25,VINE:1,100)
Block(-2,10,-5,SMOOTH_BRICK:3)
Block(-2,10,-4,MOSSY_COBBLESTONE,50,COBBLESTONE,100)
Block(-2,10,-3,MOSSY_COBBLESTONE,50,COBBLESTONE,100)
Block(-2,10,-2,MOSSY_COBBLESTONE,50,COBBLESTONE,100)
Block(-2,10,-1,MOSSY_COBBLESTONE,50,COBBLESTONE,100)
Block(-2,10,0,MOSSY_COBBLESTONE,50,COBBLESTONE,100)
Block(-2,10,1,MOSSY_COBBLESTONE,50,COBBLESTONE,100)
Block(-2,10,2,MOSSY_COBBLESTONE,50,COBBLESTONE,100)
Block(-2,10,3,MOSSY_COBBLESTONE,50,COBBLESTONE,100)
Block(-2,10,4,MOSSY_COBBLESTONE,50,COBBLESTONE,100)
Block(-2,10,5,MOSSY_COBBLESTONE,50,COBBLESTONE,100)
Block(-2,10,6,MOSSY_COBBLESTONE,50,COBBLESTONE,100)
Block(-2,10,7,MOSSY_COBBLESTONE,50,COBBLESTONE,100)
Block(-2,10,8,MOSSY_COBBLESTONE,50,COBBLESTONE,100)
Block(-2,11,-7,AIR,25,VINE:1,100)
Block(-2,11,-6,COBBLE_WALL:1,50,COBBLE_WALL,100)
Block(-2,11,-5,SMOOTH_BRICK)
Block(-2,11,-4,SMOOTH_BRICK)
Block(-2,11,-3,SMOOTH_BRICK)
Block(-2,11,-2,MOSSY_COBBLESTONE,50,COBBLESTONE,100)
Block(-2,11,-1,MOSSY_COBBLESTONE,50,COBBLESTONE,100)
Block(-2,11,0,MOSSY_COBBLESTONE,50,COBBLESTONE,100)
Block(-2,11,1,MOSSY_COBBLESTONE,50,COBBLESTONE,100)
Block(-2,11,2,MOSSY_COBBLESTONE,50,COBBLESTONE,100)
Block(-2,11,3,MOSSY_COBBLESTONE,50,COBBLESTONE,100)
Block(-2,11,4,MOSSY_COBBLESTONE,50,COBBLESTONE,100)
Block(-2,11,5,MOSSY_COBBLESTONE,50,COBBLESTONE,100)
Block(-2,11,6,MOSSY_COBBLESTONE,50,COBBLESTONE,100)
Block(-2,11,7,MOSSY_COBBLESTONE,50,COBBLESTONE,100)
Block(-2,11,8,MOSSY_COBBLESTONE,50,COBBLESTONE,100)
Block(-2,12,-7,AIR,25,VINE:1,100)
Block(-2,12,-6,MOSSY_COBBLESTONE,50,COBBLESTONE,100)
Block(-2,12,-3,COBBLE_WALL:1,50,COBBLE_WALL,100)
Block(-2,12,-2,MOSSY_COBBLESTONE,50,COBBLESTONE,100)
Block(-2,12,-1,MOSSY_COBBLESTONE,50,COBBLESTONE,100)
Block(-2,12,0,MOSSY_COBBLESTONE,50,COBBLESTONE,100)
Block(-2,12,1,MOSSY_COBBLESTONE,50,COBBLESTONE,100)
Block(-2,12,2,MOSSY_COBBLESTONE,50,COBBLESTONE,100)
Block(-2,12,3,MOSSY_COBBLESTONE,50,COBBLESTONE,100)
Block(-2,12,4,MOSSY_COBBLESTONE,50,COBBLESTONE,100)
Block(-2,12,5,MOSSY_COBBLESTONE,50,COBBLESTONE,100)
Block(-2,12,6,MOSSY_COBBLESTONE,50,COBBLESTONE,100)
Block(-2,12,7,MOSSY_COBBLESTONE,50,COBBLESTONE,100)
Block(-2,12,8,MOSSY_COBBLESTONE,50,COBBLESTONE,100)
Block(-2,13,-2,COBBLE_WALL:1,50,COBBLE_WALL,100)
Block(-2,13,-1,SMOOTH_BRICK:3)
Block(-2,13,0,SMOOTH_BRICK:3)
Block(-2,13,1,SMOOTH_BRICK:3)
Block(-2,13,2,SMOOTH_BRICK:3)
Block(-2,13,3,SMOOTH_BRICK:3)
Block(-2,13,4,SMOOTH_BRICK:3)
Block(-2,13,5,SMOOTH_BRICK:3)
Block(-2,13,6,SMOOTH_BRICK:3)
Block(-2,13,7,SMOOTH_BRICK:3)
Block(-2,13,8,SMOOTH_BRICK:3)
Block(-2,14,-2,COBBLE_WALL:1,50,COBBLE_WALL,100)
Block(-2,14,-1,SMOOTH_BRICK:3)
Block(-2,14,0,SMOOTH_BRICK:3)
Block(-2,14,1,SMOOTH_BRICK:3)
Block(-2,14,2,SMOOTH_BRICK:3)
Block(-2,14,3,SMOOTH_BRICK:3)
Block(-2,14,4,SMOOTH_BRICK:3)
Block(-2,14,5,SMOOTH_BRICK:3)
Block(-2,14,6,SMOOTH_BRICK:3)
Block(-2,14,7,SMOOTH_BRICK:3)
Block(-2,14,8,SMOOTH_BRICK:3)
Block(-2,15,-3,COBBLESTONE_STAIRS:6)
Block(-2,15,-2,MOSSY_COBBLESTONE,50,COBBLESTONE,100)
Block(-2,15,-1,SMOOTH_BRICK)
Block(-2,15,0,SMOOTH_BRICK)
Block(-2,15,1,SMOOTH_BRICK)
Block(-2,15,2,SMOOTH_BRICK)
Block(-2,15,3,SMOOTH_BRICK)
Block(-2,15,4,SMOOTH_BRICK)
Block(-2,15,5,SMOOTH_BRICK)
Block(-2,15,6,SMOOTH_BRICK)
Block(-2,15,7,SMOOTH_BRICK)
Block(-2,15,8,SMOOTH_BRICK)
Block(-2,16,-3,76:5)
Block(-2,16,-2,COBBLE_WALL:1,50,COBBLE_WALL,100)
Block(-1,0,-7,SMOOTH_BRICK)
Block(-1,0,-6,SMOOTH_BRICK)
Block(-1,0,-5,SMOOTH_BRICK)
Block(-1,0,-4,SMOOTH_BRICK)
Block(-1,0,-3,SMOOTH_BRICK)
Block(-1,0,-2,SMOOTH_BRICK)
Block(-1,0,-1,SMOOTH_BRICK)
Block(-1,0,0,SMOOTH_BRICK)
Block(-1,0,1,SMOOTH_BRICK)
Block(-1,0,2,SMOOTH_BRICK)
Block(-1,0,3,SMOOTH_BRICK)
Block(-1,0,4,SMOOTH_BRICK)
Block(-1,0,5,SMOOTH_BRICK)
Block(-1,0,6,SMOOTH_BRICK)
Block(-1,0,7,SMOOTH_BRICK)
Block(-1,0,8,SMOOTH_BRICK)
Block(-1,1,-7,SMOOTH_BRICK)
Block(-1,1,-6,SMOOTH_BRICK)
Block(-1,1,-5,SMOOTH_BRICK)
Block(-1,1,-4,SMOOTH_BRICK)
Block(-1,1,-3,SMOOTH_BRICK)
Block(-1,1,-2,SMOOTH_BRICK)
Block(-1,1,-1,SMOOTH_BRICK)
Block(-1,1,0,SMOOTH_BRICK)
Block(-1,1,1,SMOOTH_BRICK)
Block(-1,1,2,SMOOTH_BRICK)
Block(-1,1,3,SMOOTH_BRICK)
Block(-1,1,4,SMOOTH_BRICK)
Block(-1,1,5,SMOOTH_BRICK)
Block(-1,1,6,SMOOTH_BRICK)
Block(-1,1,7,SMOOTH_BRICK)
Block(-1,1,8,SMOOTH_BRICK)
Block(-1,2,-7,SMOOTH_BRICK)
Block(-1,2,-6,SMOOTH_BRICK)
Block(-1,2,-5,SMOOTH_BRICK)
Block(-1,2,-4,SMOOTH_BRICK)
Block(-1,2,-3,SMOOTH_BRICK)
Block(-1,2,-2,SMOOTH_BRICK)
Block(-1,2,-1,SMOOTH_BRICK)
Block(-1,2,0,SMOOTH_BRICK)
Block(-1,2,1,SMOOTH_BRICK)
Block(-1,2,2,SMOOTH_BRICK)
Block(-1,2,3,SMOOTH_BRICK)
Block(-1,2,4,SMOOTH_BRICK)
Block(-1,2,5,SMOOTH_BRICK)
Block(-1,2,6,SMOOTH_BRICK)
Block(-1,2,7,SMOOTH_BRICK)
Block(-1,2,8,SMOOTH_BRICK)
Block(-1,3,-7,MOSSY_COBBLESTONE,50,COBBLESTONE,100)
Block(-1,3,-6,MOSSY_COBBLESTONE,50,COBBLESTONE,100)
Block(-1,3,-5,MOSSY_COBBLESTONE,50,COBBLESTONE,100)
Block(-1,3,-4,MOSSY_COBBLESTONE,50,COBBLESTONE,100)
Block(-1,3,-3,MOSSY_COBBLESTONE,50,COBBLESTONE,100)
Block(-1,3,-2,MOSSY_COBBLESTONE,50,COBBLESTONE,100)
Block(-1,3,-1,MOSSY_COBBLESTONE,50,COBBLESTONE,100)
Block(-1,3,0,MOSSY_COBBLESTONE,50,COBBLESTONE,100)
Block(-1,3,1,MOSSY_COBBLESTONE,50,COBBLESTONE,100)
Block(-1,3,2,MOSSY_COBBLESTONE,50,COBBLESTONE,100)
Block(-1,3,3,MOSSY_COBBLESTONE,50,COBBLESTONE,100)
Block(-1,3,4,MOSSY_COBBLESTONE,50,COBBLESTONE,100)
Block(-1,3,5,MOSSY_COBBLESTONE,50,COBBLESTONE,100)
Block(-1,3,6,MOSSY_COBBLESTONE,50,COBBLESTONE,100)
Block(-1,3,7,MOSSY_COBBLESTONE,50,COBBLESTONE,100)
Block(-1,3,8,MOSSY_COBBLESTONE,50,COBBLESTONE,100)
Block(-1,4,-7,MOSSY_COBBLESTONE,50,COBBLESTONE,100)
Block(-1,4,-6,MOSSY_COBBLESTONE,50,COBBLESTONE,100)
Block(-1,4,-5,MOSSY_COBBLESTONE,50,COBBLESTONE,100)
Block(-1,4,-4,MOSSY_COBBLESTONE,50,COBBLESTONE,100)
Block(-1,4,-3,MOSSY_COBBLESTONE,50,COBBLESTONE,100)
Block(-1,4,-2,MOSSY_COBBLESTONE,50,COBBLESTONE,100)
Block(-1,4,-1,MOSSY_COBBLESTONE,50,COBBLESTONE,100)
Block(-1,4,0,MOSSY_COBBLESTONE,50,COBBLESTONE,100)
Block(-1,4,1,MOSSY_COBBLESTONE,50,COBBLESTONE,100)
Block(-1,4,2,MOSSY_COBBLESTONE,50,COBBLESTONE,100)
Block(-1,4,3,MOSSY_COBBLESTONE,50,COBBLESTONE,100)
Block(-1,4,4,MOSSY_COBBLESTONE,50,COBBLESTONE,100)
Block(-1,4,5,MOSSY_COBBLESTONE,50,COBBLESTONE,100)
Block(-1,4,6,MOSSY_COBBLESTONE,50,COBBLESTONE,100)
Block(-1,4,7,MOSSY_COBBLESTONE,50,COBBLESTONE,100)
Block(-1,4,8,MOSSY_COBBLESTONE,50,COBBLESTONE,100)
Block(-1,5,-7,MOSSY_COBBLESTONE,50,COBBLESTONE,100)
Block(-1,5,-6,MOSSY_COBBLESTONE,50,COBBLESTONE,100)
Block(-1,5,-5,MOSSY_COBBLESTONE,50,COBBLESTONE,100)
Block(-1,5,-4,MOSSY_COBBLESTONE,50,COBBLESTONE,100)
Block(-1,5,-3,MOSSY_COBBLESTONE,50,COBBLESTONE,100)
Block(-1,5,-2,MOSSY_COBBLESTONE,50,COBBLESTONE,100)
Block(-1,5,-1,MOSSY_COBBLESTONE,50,COBBLESTONE,100)
Block(-1,5,0,MOSSY_COBBLESTONE,50,COBBLESTONE,100)
Block(-1,5,1,MOSSY_COBBLESTONE,50,COBBLESTONE,100)
Block(-1,5,2,MOSSY_COBBLESTONE,50,COBBLESTONE,100)
Block(-1,5,3,MOSSY_COBBLESTONE,50,COBBLESTONE,100)
Block(-1,5,4,MOSSY_COBBLESTONE,50,COBBLESTONE,100)
Block(-1,5,5,MOSSY_COBBLESTONE,50,COBBLESTONE,100)
Block(-1,5,6,MOSSY_COBBLESTONE,50,COBBLESTONE,100)
Block(-1,5,7,MOSSY_COBBLESTONE,50,COBBLESTONE,100)
Block(-1,5,8,MOSSY_COBBLESTONE,50,COBBLESTONE,100)
Block(-1,6,-7,STONE)
Block(-1,6,-6,STONE)
Block(-1,6,-5,STONE)
Block(-1,6,-4,STONE)
Block(-1,6,-3,STONE)
Block(-1,6,-2,STONE)
Block(-1,6,-1,STONE)
Block(-1,6,0,STONE)
Block(-1,6,1,STONE)
Block(-1,6,2,STONE)
Block(-1,6,3,STONE)
Block(-1,6,4,STONE)
Block(-1,6,5,STONE)
Block(-1,6,6,STONE)
Block(-1,6,7,STONE)
Block(-1,6,8,STONE)
Block(-1,7,-7,SMOOTH_BRICK)
Block(-1,7,-6,MOSSY_COBBLESTONE,50,COBBLESTONE,100)
Block(-1,7,-5,MOSSY_COBBLESTONE,50,COBBLESTONE,100)
Block(-1,7,-4,MOSSY_COBBLESTONE,50,COBBLESTONE,100)
Block(-1,7,-3,MOSSY_COBBLESTONE,50,COBBLESTONE,100)
Block(-1,7,-2,MOSSY_COBBLESTONE,50,COBBLESTONE,100)
Block(-1,7,-1,MOSSY_COBBLESTONE,50,COBBLESTONE,100)
Block(-1,7,0,MOSSY_COBBLESTONE,50,COBBLESTONE,100)
Block(-1,7,1,MOSSY_COBBLESTONE,50,COBBLESTONE,100)
Block(-1,7,2,MOSSY_COBBLESTONE,50,COBBLESTONE,100)
Block(-1,7,3,MOSSY_COBBLESTONE,50,COBBLESTONE,100)
Block(-1,7,4,MOSSY_COBBLESTONE,50,COBBLESTONE,100)
Block(-1,7,5,MOSSY_COBBLESTONE,50,COBBLESTONE,100)
Block(-1,7,6,MOSSY_COBBLESTONE,50,COBBLESTONE,100)
Block(-1,7,7,MOSSY_COBBLESTONE,50,COBBLESTONE,100)
Block(-1,7,8,MOSSY_COBBLESTONE,50,COBBLESTONE,100)
Block(-1,8,-7,AIR,25,VINE:1,100)
Block(-1,8,-6,COBBLE_WALL:1,50,COBBLE_WALL,100)
Block(-1,8,-5,MOSSY_COBBLESTONE,50,COBBLESTONE,100)
Block(-1,8,-4,MOSSY_COBBLESTONE,50,COBBLESTONE,100)
Block(-1,8,-3,MOSSY_COBBLESTONE,50,COBBLESTONE,100)
Block(-1,8,-2,MOSSY_COBBLESTONE,50,COBBLESTONE,100)
Block(-1,8,-1,MOSSY_COBBLESTONE,50,COBBLESTONE,100)
Block(-1,8,0,MOSSY_COBBLESTONE,50,COBBLESTONE,100)
Block(-1,8,1,MOSSY_COBBLESTONE,50,COBBLESTONE,100)
Block(-1,8,2,MOSSY_COBBLESTONE,50,COBBLESTONE,100)
Block(-1,8,3,MOSSY_COBBLESTONE,50,COBBLESTONE,100)
Block(-1,8,4,MOSSY_COBBLESTONE,50,COBBLESTONE,100)
Block(-1,8,5,MOSSY_COBBLESTONE,50,COBBLESTONE,100)
Block(-1,8,6,MOSSY_COBBLESTONE,50,COBBLESTONE,100)
Block(-1,8,7,MOSSY_COBBLESTONE,50,COBBLESTONE,100)
Block(-1,8,8,MOSSY_COBBLESTONE,50,COBBLESTONE,100)
Block(-1,9,-7,AIR,25,VINE:1,100)
Block(-1,9,-6,AIR,25,VINE:1,100)
Block(-1,9,-5,SMOOTH_BRICK:3)
Block(-1,9,-4,MOSSY_COBBLESTONE,50,COBBLESTONE,100)
Block(-1,9,-3,MOSSY_COBBLESTONE,50,COBBLESTONE,100)
Block(-1,9,-2,MOSSY_COBBLESTONE,50,COBBLESTONE,100)
Block(-1,9,-1,MOSSY_COBBLESTONE,50,COBBLESTONE,100)
Block(-1,9,0,MOSSY_COBBLESTONE,50,COBBLESTONE,100)
Block(-1,9,1,MOSSY_COBBLESTONE,50,COBBLESTONE,100)
Block(-1,9,2,MOSSY_COBBLESTONE,50,COBBLESTONE,100)
Block(-1,9,3,MOSSY_COBBLESTONE,50,COBBLESTONE,100)
Block(-1,9,4,MOSSY_COBBLESTONE,50,COBBLESTONE,100)
Block(-1,9,5,MOSSY_COBBLESTONE,50,COBBLESTONE,100)
Block(-1,9,6,MOSSY_COBBLESTONE,50,COBBLESTONE,100)
Block(-1,9,7,MOSSY_COBBLESTONE,50,COBBLESTONE,100)
Block(-1,9,8,MOSSY_COBBLESTONE,50,COBBLESTONE,100)
Block(-1,10,-7,AIR,25,VINE:1,100)
Block(-1,10,-6,AIR,25,VINE:1,100)
Block(-1,10,-5,SMOOTH_BRICK:3)
Block(-1,10,-4,MOSSY_COBBLESTONE,50,COBBLESTONE,100)
Block(-1,10,-3,MOSSY_COBBLESTONE,50,COBBLESTONE,100)
Block(-1,10,-2,MOSSY_COBBLESTONE,50,COBBLESTONE,100)
Block(-1,10,-1,MOSSY_COBBLESTONE,50,COBBLESTONE,100)
Block(-1,10,0,MOSSY_COBBLESTONE,50,COBBLESTONE,100)
Block(-1,10,1,MOSSY_COBBLESTONE,50,COBBLESTONE,100)
Block(-1,10,2,MOSSY_COBBLESTONE,50,COBBLESTONE,100)
Block(-1,10,3,MOSSY_COBBLESTONE,50,COBBLESTONE,100)
Block(-1,10,4,MOSSY_COBBLESTONE,50,COBBLESTONE,100)
Block(-1,10,5,MOSSY_COBBLESTONE,50,COBBLESTONE,100)
Block(-1,10,6,MOSSY_COBBLESTONE,50,COBBLESTONE,100)
Block(-1,10,7,MOSSY_COBBLESTONE,50,COBBLESTONE,100)
Block(-1,10,8,MOSSY_COBBLESTONE,50,COBBLESTONE,100)
Block(-1,11,-7,AIR,25,VINE:1,100)
Block(-1,11,-6,COBBLE_WALL:1,50,COBBLE_WALL,100)
Block(-1,11,-5,SMOOTH_BRICK)
Block(-1,11,-4,SMOOTH_BRICK)
Block(-1,11,-3,SMOOTH_BRICK)
Block(-1,11,-2,MOSSY_COBBLESTONE,50,COBBLESTONE,100)
Block(-1,11,-1,MOSSY_COBBLESTONE,50,COBBLESTONE,100)
Block(-1,11,0,MOSSY_COBBLESTONE,50,COBBLESTONE,100)
Block(-1,11,1,MOSSY_COBBLESTONE,50,COBBLESTONE,100)
Block(-1,11,2,MOSSY_COBBLESTONE,50,COBBLESTONE,100)
Block(-1,11,3,MOSSY_COBBLESTONE,50,COBBLESTONE,100)
Block(-1,11,4,MOSSY_COBBLESTONE,50,COBBLESTONE,100)
Block(-1,11,5,MOSSY_COBBLESTONE,50,COBBLESTONE,100)
Block(-1,11,6,MOSSY_COBBLESTONE,50,COBBLESTONE,100)
Block(-1,11,7,MOSSY_COBBLESTONE,50,COBBLESTONE,100)
Block(-1,11,8,MOSSY_COBBLESTONE,50,COBBLESTONE,100)
Block(-1,12,-7,AIR,25,VINE:1,100)
Block(-1,12,-6,MOSSY_COBBLESTONE,50,COBBLESTONE,100)
Block(-1,12,-3,AIR,25,VINE:1,100)
Block(-1,12,-2,COBBLE_WALL:1,50,COBBLE_WALL,100)
Block(-1,12,-1,MOSSY_COBBLESTONE,50,COBBLESTONE,100)
Block(-1,12,0,MOSSY_COBBLESTONE,50,COBBLESTONE,100)
Block(-1,12,1,MOSSY_COBBLESTONE,50,COBBLESTONE,100)
Block(-1,12,2,MOSSY_COBBLESTONE,50,COBBLESTONE,100)
Block(-1,12,3,MOSSY_COBBLESTONE,50,COBBLESTONE,100)
Block(-1,12,4,MOSSY_COBBLESTONE,50,COBBLESTONE,100)
Block(-1,12,5,MOSSY_COBBLESTONE,50,COBBLESTONE,100)
Block(-1,12,6,MOSSY_COBBLESTONE,50,COBBLESTONE,100)
Block(-1,12,7,MOSSY_COBBLESTONE,50,COBBLESTONE,100)
Block(-1,12,8,MOSSY_COBBLESTONE,50,COBBLESTONE,100)
Block(-1,13,-3,AIR,25,VINE:1,100)
Block(-1,13,-2,AIR,25,VINE:1,100)
Block(-1,13,-1,SMOOTH_BRICK:3)
Block(-1,13,0,MOSSY_COBBLESTONE,50,COBBLESTONE,100)
Block(-1,13,1,MOSSY_COBBLESTONE,50,COBBLESTONE,100)
Block(-1,13,2,MOSSY_COBBLESTONE,50,COBBLESTONE,100)
Block(-1,13,3,MOSSY_COBBLESTONE,50,COBBLESTONE,100)
Block(-1,13,4,MOSSY_COBBLESTONE,50,COBBLESTONE,100)
Block(-1,13,5,MOSSY_COBBLESTONE,50,COBBLESTONE,100)
Block(-1,13,6,MOSSY_COBBLESTONE,50,COBBLESTONE,100)
Block(-1,13,7,MOSSY_COBBLESTONE,50,COBBLESTONE,100)
Block(-1,13,8,MOSSY_COBBLESTONE,50,COBBLESTONE,100)
Block(-1,14,-3,AIR,25,VINE:1,100)
Block(-1,14,-2,AIR,25,VINE:1,100)
Block(-1,14,-1,SMOOTH_BRICK:3)
Block(-1,14,0,MOSSY_COBBLESTONE,50,COBBLESTONE,100)
Block(-1,14,1,MOSSY_COBBLESTONE,50,COBBLESTONE,100)
Block(-1,14,2,MOSSY_COBBLESTONE,50,COBBLESTONE,100)
Block(-1,14,3,MOSSY_COBBLESTONE,50,COBBLESTONE,100)
Block(-1,14,4,MOSSY_COBBLESTONE,50,COBBLESTONE,100)
Block(-1,14,5,MOSSY_COBBLESTONE,50,COBBLESTONE,100)
Block(-1,14,6,MOSSY_COBBLESTONE,50,COBBLESTONE,100)
Block(-1,14,7,MOSSY_COBBLESTONE,50,COBBLESTONE,100)
Block(-1,14,8,MOSSY_COBBLESTONE,50,COBBLESTONE,100)
Block(-1,15,-3,AIR,25,VINE:1,100)
Block(-1,15,-2,COBBLE_WALL:1,50,COBBLE_WALL,100)
Block(-1,15,-1,SMOOTH_BRICK)
Block(-1,15,0,SMOOTH_BRICK)
Block(-1,15,1,SMOOTH_BRICK)
Block(-1,15,2,SMOOTH_BRICK)
Block(-1,15,3,SMOOTH_BRICK)
Block(-1,15,4,SMOOTH_BRICK)
Block(-1,15,5,SMOOTH_BRICK)
Block(-1,15,6,SMOOTH_BRICK)
Block(-1,15,7,SMOOTH_BRICK)
Block(-1,15,8,SMOOTH_BRICK)
Block(-1,16,-3,AIR,25,VINE:1,100)
Block(-1,16,-2,MOSSY_COBBLESTONE,50,COBBLESTONE,100)
Block(0,0,-7,SMOOTH_BRICK)
Block(0,0,-6,SMOOTH_BRICK)
Block(0,0,-5,SMOOTH_BRICK)
Block(0,0,-4,SMOOTH_BRICK)
Block(0,0,-3,SMOOTH_BRICK)
Block(0,0,-2,SMOOTH_BRICK)
Block(0,0,-1,SMOOTH_BRICK)
Block(0,0,0,SMOOTH_BRICK)
Block(0,0,1,SMOOTH_BRICK)
Block(0,0,2,SMOOTH_BRICK)
Block(0,0,3,SMOOTH_BRICK)
Block(0,0,4,SMOOTH_BRICK)
Block(0,0,5,SMOOTH_BRICK)
Block(0,0,6,SMOOTH_BRICK)
Block(0,0,7,SMOOTH_BRICK)
Block(0,0,8,SMOOTH_BRICK)
Block(0,1,-7,SMOOTH_BRICK)
Block(0,1,-6,SMOOTH_BRICK)
Block(0,1,-5,SMOOTH_BRICK)
Block(0,1,-4,SMOOTH_BRICK)
Block(0,1,-3,SMOOTH_BRICK)
Block(0,1,-2,SMOOTH_BRICK)
Block(0,1,-1,SMOOTH_BRICK)
Block(0,1,0,SMOOTH_BRICK)
Block(0,1,1,SMOOTH_BRICK)
Block(0,1,2,SMOOTH_BRICK)
Block(0,1,3,SMOOTH_BRICK)
Block(0,1,4,SMOOTH_BRICK)
Block(0,1,5,SMOOTH_BRICK)
Block(0,1,6,SMOOTH_BRICK)
Block(0,1,7,SMOOTH_BRICK)
Block(0,1,8,SMOOTH_BRICK)
Block(0,2,-7,SMOOTH_BRICK)
Block(0,2,-6,SMOOTH_BRICK)
Block(0,2,-5,SMOOTH_BRICK)
Block(0,2,-4,SMOOTH_BRICK)
Block(0,2,-3,SMOOTH_BRICK)
Block(0,2,-2,SMOOTH_BRICK)
Block(0,2,-1,SMOOTH_BRICK)
Block(0,2,0,SMOOTH_BRICK)
Block(0,2,1,SMOOTH_BRICK)
Block(0,2,2,SMOOTH_BRICK)
Block(0,2,3,SMOOTH_BRICK)
Block(0,2,4,SMOOTH_BRICK)
Block(0,2,5,SMOOTH_BRICK)
Block(0,2,6,SMOOTH_BRICK)
Block(0,2,7,SMOOTH_BRICK)
Block(0,2,8,SMOOTH_BRICK)
Block(0,3,-7,MOSSY_COBBLESTONE,50,COBBLESTONE,100)
Block(0,3,-6,MOSSY_COBBLESTONE,50,COBBLESTONE,100)
Block(0,3,-5,MOSSY_COBBLESTONE,50,COBBLESTONE,100)
Block(0,3,-4,MOSSY_COBBLESTONE,50,COBBLESTONE,100)
Block(0,3,-3,MOSSY_COBBLESTONE,50,COBBLESTONE,100)
Block(0,3,-2,MOSSY_COBBLESTONE,50,COBBLESTONE,100)
Block(0,3,-1,MOSSY_COBBLESTONE,50,COBBLESTONE,100)
Block(0,3,0,MOSSY_COBBLESTONE,50,COBBLESTONE,100)
Block(0,3,1,MOSSY_COBBLESTONE,50,COBBLESTONE,100)
Block(0,3,2,MOSSY_COBBLESTONE,50,COBBLESTONE,100)
Block(0,3,3,MOSSY_COBBLESTONE,50,COBBLESTONE,100)
Block(0,3,4,MOSSY_COBBLESTONE,50,COBBLESTONE,100)
Block(0,3,5,MOSSY_COBBLESTONE,50,COBBLESTONE,100)
Block(0,3,6,MOSSY_COBBLESTONE,50,COBBLESTONE,100)
Block(0,3,7,MOSSY_COBBLESTONE,50,COBBLESTONE,100)
Block(0,3,8,MOSSY_COBBLESTONE,50,COBBLESTONE,100)
Block(0,4,-7,MOSSY_COBBLESTONE,50,COBBLESTONE,100)
Block(0,4,-6,MOSSY_COBBLESTONE,50,COBBLESTONE,100)
Block(0,4,-5,MOSSY_COBBLESTONE,50,COBBLESTONE,100)
Block(0,4,-4,MOSSY_COBBLESTONE,50,COBBLESTONE,100)
Block(0,4,-3,MOSSY_COBBLESTONE,50,COBBLESTONE,100)
Block(0,4,-2,MOSSY_COBBLESTONE,50,COBBLESTONE,100)
Block(0,4,-1,MOSSY_COBBLESTONE,50,COBBLESTONE,100)
Block(0,4,0,MOSSY_COBBLESTONE,50,COBBLESTONE,100)
Block(0,4,1,MOSSY_COBBLESTONE,50,COBBLESTONE,100)
Block(0,4,2,MOSSY_COBBLESTONE,50,COBBLESTONE,100)
Block(0,4,3,MOSSY_COBBLESTONE,50,COBBLESTONE,100)
Block(0,4,4,MOSSY_COBBLESTONE,50,COBBLESTONE,100)
Block(0,4,5,MOSSY_COBBLESTONE,50,COBBLESTONE,100)
Block(0,4,6,MOSSY_COBBLESTONE,50,COBBLESTONE,100)
Block(0,4,7,MOSSY_COBBLESTONE,50,COBBLESTONE,100)
Block(0,4,8,MOSSY_COBBLESTONE,50,COBBLESTONE,100)
Block(0,5,-7,MOSSY_COBBLESTONE,50,COBBLESTONE,100)
Block(0,5,-6,MOSSY_COBBLESTONE,50,COBBLESTONE,100)
Block(0,5,-5,MOSSY_COBBLESTONE,50,COBBLESTONE,100)
Block(0,5,-4,MOSSY_COBBLESTONE,50,COBBLESTONE,100)
Block(0,5,-3,MOSSY_COBBLESTONE,50,COBBLESTONE,100)
Block(0,5,-2,MOSSY_COBBLESTONE,50,COBBLESTONE,100)
Block(0,5,-1,MOSSY_COBBLESTONE,50,COBBLESTONE,100)
Block(0,5,0,MOSSY_COBBLESTONE,50,COBBLESTONE,100)
Block(0,5,1,MOSSY_COBBLESTONE,50,COBBLESTONE,100)
Block(0,5,2,MOSSY_COBBLESTONE,50,COBBLESTONE,100)
Block(0,5,3,MOSSY_COBBLESTONE,50,COBBLESTONE,100)
Block(0,5,4,MOSSY_COBBLESTONE,50,COBBLESTONE,100)
Block(0,5,5,MOSSY_COBBLESTONE,50,COBBLESTONE,100)
Block(0,5,6,MOSSY_COBBLESTONE,50,COBBLESTONE,100)
Block(0,5,7,MOSSY_COBBLESTONE,50,COBBLESTONE,100)
Block(0,5,8,MOSSY_COBBLESTONE,50,COBBLESTONE,100)
Block(0,6,-7,STONE)
Block(0,6,-6,STONE)
Block(0,6,-5,STONE)
Block(0,6,-4,STONE)
Block(0,6,-3,STONE)
Block(0,6,-2,STONE)
Block(0,6,-1,STONE)
Block(0,6,0,STONE)
Block(0,6,1,STONE)
Block(0,6,2,STONE)
Block(0,6,3,STONE)
Block(0,6,4,STONE)
Block(0,6,5,STONE)
Block(0,6,6,STONE)
Block(0,6,7,STONE)
Block(0,6,8,STONE)
Block(0,7,-7,SMOOTH_BRICK)
Block(0,7,-6,MOSSY_COBBLESTONE,50,COBBLESTONE,100)
Block(0,7,-5,MOSSY_COBBLESTONE,50,COBBLESTONE,100)
Block(0,7,-4,MOSSY_COBBLESTONE,50,COBBLESTONE,100)
Block(0,7,-3,MOSSY_COBBLESTONE,50,COBBLESTONE,100)
Block(0,7,-2,MOSSY_COBBLESTONE,50,COBBLESTONE,100)
Block(0,7,-1,MOSSY_COBBLESTONE,50,COBBLESTONE,100)
Block(0,7,0,MOSSY_COBBLESTONE,50,COBBLESTONE,100)
Block(0,7,1,MOSSY_COBBLESTONE,50,COBBLESTONE,100)
Block(0,7,2,MOSSY_COBBLESTONE,50,COBBLESTONE,100)
Block(0,7,3,MOSSY_COBBLESTONE,50,COBBLESTONE,100)
Block(0,7,4,MOSSY_COBBLESTONE,50,COBBLESTONE,100)
Block(0,7,5,MOSSY_COBBLESTONE,50,COBBLESTONE,100)
Block(0,7,6,MOSSY_COBBLESTONE,50,COBBLESTONE,100)
Block(0,7,7,MOSSY_COBBLESTONE,50,COBBLESTONE,100)
Block(0,7,8,MOSSY_COBBLESTONE,50,COBBLESTONE,100)
Block(0,8,-7,COBBLE_WALL:1,50,COBBLE_WALL,100)
Block(0,8,-6,MOSSY_COBBLESTONE,50,COBBLESTONE,100)
Block(0,8,-5,MOSSY_COBBLESTONE,50,COBBLESTONE,100)
Block(0,8,-4,MOSSY_COBBLESTONE,50,COBBLESTONE,100)
Block(0,8,-3,MOSSY_COBBLESTONE,50,COBBLESTONE,100)
Block(0,8,-2,MOSSY_COBBLESTONE,50,COBBLESTONE,100)
Block(0,8,-1,MOSSY_COBBLESTONE,50,COBBLESTONE,100)
Block(0,8,0,MOSSY_COBBLESTONE,50,COBBLESTONE,100)
Block(0,8,1,MOSSY_COBBLESTONE,50,COBBLESTONE,100)
Block(0,8,2,MOSSY_COBBLESTONE,50,COBBLESTONE,100)
Block(0,8,3,MOSSY_COBBLESTONE,50,COBBLESTONE,100)
Block(0,8,4,MOSSY_COBBLESTONE,50,COBBLESTONE,100)
Block(0,8,5,MOSSY_COBBLESTONE,50,COBBLESTONE,100)
Block(0,8,6,MOSSY_COBBLESTONE,50,COBBLESTONE,100)
Block(0,8,7,MOSSY_COBBLESTONE,50,COBBLESTONE,100)
Block(0,8,8,MOSSY_COBBLESTONE,50,COBBLESTONE,100)
Block(0,9,-6,COBBLE_WALL:1,50,COBBLE_WALL,100)
Block(0,9,-5,SMOOTH_BRICK:3)
Block(0,9,-4,MOSSY_COBBLESTONE,50,COBBLESTONE,100)
Block(0,9,-3,MOSSY_COBBLESTONE,50,COBBLESTONE,100)
Block(0,9,-2,MOSSY_COBBLESTONE,50,COBBLESTONE,100)
Block(0,9,-1,MOSSY_COBBLESTONE,50,COBBLESTONE,100)
Block(0,9,0,MOSSY_COBBLESTONE,50,COBBLESTONE,100)
Block(0,9,1,MOSSY_COBBLESTONE,50,COBBLESTONE,100)
Block(0,9,2,MOSSY_COBBLESTONE,50,COBBLESTONE,100)
Block(0,9,3,MOSSY_COBBLESTONE,50,COBBLESTONE,100)
Block(0,9,4,MOSSY_COBBLESTONE,50,COBBLESTONE,100)
Block(0,9,5,MOSSY_COBBLESTONE,50,COBBLESTONE,100)
Block(0,9,6,MOSSY_COBBLESTONE,50,COBBLESTONE,100)
Block(0,9,7,MOSSY_COBBLESTONE,50,COBBLESTONE,100)
Block(0,9,8,MOSSY_COBBLESTONE,50,COBBLESTONE,100)
Block(0,10,-6,COBBLE_WALL:1,50,COBBLE_WALL,100)
Block(0,10,-5,SMOOTH_BRICK:3)
Block(0,10,-4,MOSSY_COBBLESTONE,50,COBBLESTONE,100)
Block(0,10,-3,MOSSY_COBBLESTONE,50,COBBLESTONE,100)
Block(0,10,-2,MOSSY_COBBLESTONE,50,COBBLESTONE,100)
Block(0,10,-1,MOSSY_COBBLESTONE,50,COBBLESTONE,100)
Block(0,10,0,MOSSY_COBBLESTONE,50,COBBLESTONE,100)
Block(0,10,1,MOSSY_COBBLESTONE,50,COBBLESTONE,100)
Block(0,10,2,MOSSY_COBBLESTONE,50,COBBLESTONE,100)
Block(0,10,3,MOSSY_COBBLESTONE,50,COBBLESTONE,100)
Block(0,10,4,MOSSY_COBBLESTONE,50,COBBLESTONE,100)
Block(0,10,5,MOSSY_COBBLESTONE,50,COBBLESTONE,100)
Block(0,10,6,MOSSY_COBBLESTONE,50,COBBLESTONE,100)
Block(0,10,7,MOSSY_COBBLESTONE,50,COBBLESTONE,100)
Block(0,10,8,MOSSY_COBBLESTONE,50,COBBLESTONE,100)
Block(0,11,-7,COBBLESTONE_STAIRS:6)
Block(0,11,-6,MOSSY_COBBLESTONE,50,COBBLESTONE,100)
Block(0,11,-5,SMOOTH_BRICK)
Block(0,11,-4,SMOOTH_BRICK)
Block(0,11,-3,SMOOTH_BRICK)
Block(0,11,-2,MOSSY_COBBLESTONE,50,COBBLESTONE,100)
Block(0,11,-1,MOSSY_COBBLESTONE,50,COBBLESTONE,100)
Block(0,11,0,MOSSY_COBBLESTONE,50,COBBLESTONE,100)
Block(0,11,1,MOSSY_COBBLESTONE,50,COBBLESTONE,100)
Block(0,11,2,MOSSY_COBBLESTONE,50,COBBLESTONE,100)
Block(0,11,3,MOSSY_COBBLESTONE,50,COBBLESTONE,100)
Block(0,11,4,MOSSY_COBBLESTONE,50,COBBLESTONE,100)
Block(0,11,5,MOSSY_COBBLESTONE,50,COBBLESTONE,100)
Block(0,11,6,MOSSY_COBBLESTONE,50,COBBLESTONE,100)
Block(0,11,7,MOSSY_COBBLESTONE,50,COBBLESTONE,100)
Block(0,11,8,MOSSY_COBBLESTONE,50,COBBLESTONE,100)
Block(0,12,-7,76:5)
Block(0,12,-6,COBBLE_WALL:1,50,COBBLE_WALL,100)
Block(0,12,-3,AIR,25,VINE:1,100)
Block(0,12,-2,COBBLE_WALL:1,50,COBBLE_WALL,100)
Block(0,12,-1,MOSSY_COBBLESTONE,50,COBBLESTONE,100)
Block(0,12,0,MOSSY_COBBLESTONE,50,COBBLESTONE,100)
Block(0,12,1,MOSSY_COBBLESTONE,50,COBBLESTONE,100)
Block(0,12,2,MOSSY_COBBLESTONE,50,COBBLESTONE,100)
Block(0,12,3,MOSSY_COBBLESTONE,50,COBBLESTONE,100)
Block(0,12,4,MOSSY_COBBLESTONE,50,COBBLESTONE,100)
Block(0,12,5,MOSSY_COBBLESTONE,50,COBBLESTONE,100)
Block(0,12,6,MOSSY_COBBLESTONE,50,COBBLESTONE,100)
Block(0,12,7,MOSSY_COBBLESTONE,50,COBBLESTONE,100)
Block(0,12,8,MOSSY_COBBLESTONE,50,COBBLESTONE,100)
Block(0,13,-3,AIR,25,VINE:1,100)
Block(0,13,-2,AIR,25,VINE:1,100)
Block(0,13,-1,SMOOTH_BRICK:3)
Block(0,13,0,MOSSY_COBBLESTONE,50,COBBLESTONE,100)
Block(0,13,1,MOSSY_COBBLESTONE,50,COBBLESTONE,100)
Block(0,13,2,MOSSY_COBBLESTONE,50,COBBLESTONE,100)
Block(0,13,3,MOSSY_COBBLESTONE,50,COBBLESTONE,100)
Block(0,13,4,MOSSY_COBBLESTONE,50,COBBLESTONE,100)
Block(0,13,5,MOSSY_COBBLESTONE,50,COBBLESTONE,100)
Block(0,13,6,MOSSY_COBBLESTONE,50,COBBLESTONE,100)
Block(0,13,7,MOSSY_COBBLESTONE,50,COBBLESTONE,100)
Block(0,13,8,MOSSY_COBBLESTONE,50,COBBLESTONE,100)
Block(0,14,-3,AIR,25,VINE:1,100)
Block(0,14,-2,AIR,25,VINE:1,100)
Block(0,14,-1,SMOOTH_BRICK:3)
Block(0,14,0,MOSSY_COBBLESTONE,50,COBBLESTONE,100)
Block(0,14,1,MOSSY_COBBLESTONE,50,COBBLESTONE,100)
Block(0,14,2,MOSSY_COBBLESTONE,50,COBBLESTONE,100)
Block(0,14,3,MOSSY_COBBLESTONE,50,COBBLESTONE,100)
Block(0,14,4,MOSSY_COBBLESTONE,50,COBBLESTONE,100)
Block(0,14,5,MOSSY_COBBLESTONE,50,COBBLESTONE,100)
Block(0,14,6,MOSSY_COBBLESTONE,50,COBBLESTONE,100)
Block(0,14,7,MOSSY_COBBLESTONE,50,COBBLESTONE,100)
Block(0,14,8,MOSSY_COBBLESTONE,50,COBBLESTONE,100)
Block(0,15,-3,AIR,25,VINE:1,100)
Block(0,15,-2,COBBLE_WALL:1,50,COBBLE_WALL,100)
Block(0,15,-1,SMOOTH_BRICK)
Block(0,15,0,SMOOTH_BRICK)
Block(0,15,1,SMOOTH_BRICK)
Block(0,15,2,SMOOTH_BRICK)
Block(0,15,3,SMOOTH_BRICK)
Block(0,15,4,SMOOTH_BRICK)
Block(0,15,5,SMOOTH_BRICK)
Block(0,15,6,SMOOTH_BRICK)
Block(0,15,7,SMOOTH_BRICK)
Block(0,15,8,SMOOTH_BRICK)
Block(0,16,-3,AIR,25,VINE:1,100)
Block(0,16,-2,MOSSY_COBBLESTONE,50,COBBLESTONE,100)
Block(0,16,2,AIR,25,VINE:8,100)
Block(0,16,3,COBBLE_WALL:1,50,COBBLE_WALL,100)
Block(0,16,4,AIR,25,VINE:8,100)
Block(0,16,5,AIR,25,VINE:8,100)
Block(0,16,6,COBBLE_WALL:1,50,COBBLE_WALL,100)
Block(0,16,7,AIR,25,VINE:8,100)
Block(0,16,8,AIR,25,VINE:8,100)
Block(0,17,2,AIR,25,VINE:8,100)
Block(0,17,4,AIR,25,VINE:8,100)
Block(0,17,5,AIR,25,VINE:8,100)
Block(0,17,7,AIR,25,VINE:8,100)
Block(0,17,8,AIR,25,VINE:8,100)
Block(0,18,2,AIR,25,VINE:8,100)
Block(0,18,4,AIR,25,VINE:8,100)
Block(0,18,5,AIR,25,VINE:8,100)
Block(0,18,7,AIR,25,VINE:8,100)
Block(0,18,8,AIR,25,VINE:8,100)
Block(0,19,2,AIR,25,VINE:8,100)
Block(0,19,3,COBBLESTONE_STAIRS:4)
Block(0,19,4,AIR,25,VINE:8,100)
Block(0,19,5,AIR,25,VINE:8,100)
Block(0,19,6,COBBLESTONE_STAIRS:4)
Block(0,19,7,AIR,25,VINE:8,100)
Block(0,19,8,AIR,25,VINE:8,100)
Block(0,20,2,AIR,25,VINE:8,100)
Block(0,20,3,76:5)
Block(0,20,4,AIR,25,VINE:8,100)
Block(0,20,5,AIR,25,VINE:8,100)
Block(0,20,6,76:5)
Block(0,20,7,AIR,25,VINE:8,100)
Block(0,20,8,AIR,25,VINE:8,100)
Block(1,0,-7,SMOOTH_BRICK)
Block(1,0,-6,SMOOTH_BRICK)
Block(1,0,-5,SMOOTH_BRICK)
Block(1,0,-4,SMOOTH_BRICK)
Block(1,0,-3,SMOOTH_BRICK)
Block(1,0,-2,SMOOTH_BRICK)
Block(1,0,-1,SMOOTH_BRICK)
Block(1,0,0,SMOOTH_BRICK)
Block(1,0,1,SMOOTH_BRICK)
Block(1,0,2,SMOOTH_BRICK)
Block(1,0,3,SMOOTH_BRICK)
Block(1,0,4,SMOOTH_BRICK)
Block(1,0,5,SMOOTH_BRICK)
Block(1,0,6,SMOOTH_BRICK)
Block(1,0,7,SMOOTH_BRICK)
Block(1,0,8,SMOOTH_BRICK)
Block(1,1,-7,SMOOTH_BRICK)
Block(1,1,-6,SMOOTH_BRICK)
Block(1,1,-5,SMOOTH_BRICK)
Block(1,1,-4,SMOOTH_BRICK)
Block(1,1,-3,SMOOTH_BRICK)
Block(1,1,-2,SMOOTH_BRICK)
Block(1,1,-1,SMOOTH_BRICK)
Block(1,1,0,SMOOTH_BRICK)
Block(1,1,1,SMOOTH_BRICK)
Block(1,1,2,SMOOTH_BRICK)
Block(1,1,3,SMOOTH_BRICK)
Block(1,1,4,SMOOTH_BRICK)
Block(1,1,5,SMOOTH_BRICK)
Block(1,1,6,SMOOTH_BRICK)
Block(1,1,7,SMOOTH_BRICK)
Block(1,1,8,SMOOTH_BRICK)
Block(1,2,-7,SMOOTH_BRICK)
Block(1,2,-6,SMOOTH_BRICK)
Block(1,2,-5,SMOOTH_BRICK)
Block(1,2,-4,SMOOTH_BRICK)
Block(1,2,-3,SMOOTH_BRICK)
Block(1,2,-2,SMOOTH_BRICK)
Block(1,2,-1,SMOOTH_BRICK)
Block(1,2,0,SMOOTH_BRICK)
Block(1,2,1,SMOOTH_BRICK)
Block(1,2,2,SMOOTH_BRICK)
Block(1,2,3,SMOOTH_BRICK)
Block(1,2,4,SMOOTH_BRICK)
Block(1,2,5,SMOOTH_BRICK)
Block(1,2,6,SMOOTH_BRICK)
Block(1,2,7,SMOOTH_BRICK)
Block(1,2,8,SMOOTH_BRICK)
Block(1,3,-7,MOSSY_COBBLESTONE,50,COBBLESTONE,100)
Block(1,3,-6,MOSSY_COBBLESTONE,50,COBBLESTONE,100)
Block(1,3,-5,MOSSY_COBBLESTONE,50,COBBLESTONE,100)
Block(1,3,-4,MOSSY_COBBLESTONE,50,COBBLESTONE,100)
Block(1,3,-3,MOSSY_COBBLESTONE,50,COBBLESTONE,100)
Block(1,3,-2,MOSSY_COBBLESTONE,50,COBBLESTONE,100)
Block(1,3,-1,MOSSY_COBBLESTONE,50,COBBLESTONE,100)
Block(1,3,0,MOSSY_COBBLESTONE,50,COBBLESTONE,100)
Block(1,3,1,MOSSY_COBBLESTONE,50,COBBLESTONE,100)
Block(1,3,2,MOSSY_COBBLESTONE,50,COBBLESTONE,100)
Block(1,3,3,MOSSY_COBBLESTONE,50,COBBLESTONE,100)
Block(1,3,4,MOSSY_COBBLESTONE,50,COBBLESTONE,100)
Block(1,3,5,MOSSY_COBBLESTONE,50,COBBLESTONE,100)
Block(1,3,6,MOSSY_COBBLESTONE,50,COBBLESTONE,100)
Block(1,3,7,MOSSY_COBBLESTONE,50,COBBLESTONE,100)
Block(1,3,8,MOSSY_COBBLESTONE,50,COBBLESTONE,100)
Block(1,4,-7,MOSSY_COBBLESTONE,50,COBBLESTONE,100)
Block(1,4,-6,MOSSY_COBBLESTONE,50,COBBLESTONE,100)
Block(1,4,-5,MOSSY_COBBLESTONE,50,COBBLESTONE,100)
Block(1,4,-4,MOSSY_COBBLESTONE,50,COBBLESTONE,100)
Block(1,4,-3,MOSSY_COBBLESTONE,50,COBBLESTONE,100)
Block(1,4,-2,MOSSY_COBBLESTONE,50,COBBLESTONE,100)
Block(1,4,-1,MOSSY_COBBLESTONE,50,COBBLESTONE,100)
Block(1,4,0,MOSSY_COBBLESTONE,50,COBBLESTONE,100)
Block(1,4,1,MOSSY_COBBLESTONE,50,COBBLESTONE,100)
Block(1,4,2,MOSSY_COBBLESTONE,50,COBBLESTONE,100)
Block(1,4,3,MOSSY_COBBLESTONE,50,COBBLESTONE,100)
Block(1,4,4,MOSSY_COBBLESTONE,50,COBBLESTONE,100)
Block(1,4,5,MOSSY_COBBLESTONE,50,COBBLESTONE,100)
Block(1,4,6,MOSSY_COBBLESTONE,50,COBBLESTONE,100)
Block(1,4,7,MOSSY_COBBLESTONE,50,COBBLESTONE,100)
Block(1,4,8,MOSSY_COBBLESTONE,50,COBBLESTONE,100)
Block(1,5,-7,MOSSY_COBBLESTONE,50,COBBLESTONE,100)
Block(1,5,-6,MOSSY_COBBLESTONE,50,COBBLESTONE,100)
Block(1,5,-5,MOSSY_COBBLESTONE,50,COBBLESTONE,100)
Block(1,5,-4,MOSSY_COBBLESTONE,50,COBBLESTONE,100)
Block(1,5,-3,MOSSY_COBBLESTONE,50,COBBLESTONE,100)
Block(1,5,-2,MOSSY_COBBLESTONE,50,COBBLESTONE,100)
Block(1,5,-1,MOSSY_COBBLESTONE,50,COBBLESTONE,100)
Block(1,5,0,MOSSY_COBBLESTONE,50,COBBLESTONE,100)
Block(1,5,1,MOSSY_COBBLESTONE,50,COBBLESTONE,100)
Block(1,5,2,MOSSY_COBBLESTONE,50,COBBLESTONE,100)
Block(1,5,3,MOSSY_COBBLESTONE,50,COBBLESTONE,100)
Block(1,5,4,MOSSY_COBBLESTONE,50,COBBLESTONE,100)
Block(1,5,5,MOSSY_COBBLESTONE,50,COBBLESTONE,100)
Block(1,5,6,MOSSY_COBBLESTONE,50,COBBLESTONE,100)
Block(1,5,7,MOSSY_COBBLESTONE,50,COBBLESTONE,100)
Block(1,5,8,MOSSY_COBBLESTONE,50,COBBLESTONE,100)
Block(1,6,-7,STONE)
Block(1,6,-6,STONE)
Block(1,6,-5,STONE)
Block(1,6,-4,STONE)
Block(1,6,-3,STONE)
Block(1,6,-2,STONE)
Block(1,6,-1,STONE)
Block(1,6,0,STONE)
Block(1,6,1,STONE)
Block(1,6,2,STONE)
Block(1,6,3,STONE)
Block(1,6,4,STONE)
Block(1,6,5,STONE)
Block(1,6,6,STONE)
Block(1,6,7,STONE)
Block(1,6,8,STONE)
Block(1,7,-7,SMOOTH_BRICK)
Block(1,7,-6,MOSSY_COBBLESTONE,50,COBBLESTONE,100)
Block(1,7,-5,MOSSY_COBBLESTONE,50,COBBLESTONE,100)
Block(1,7,-4,MOSSY_COBBLESTONE,50,COBBLESTONE,100)
Block(1,7,-3,MOSSY_COBBLESTONE,50,COBBLESTONE,100)
Block(1,7,-2,MOSSY_COBBLESTONE,50,COBBLESTONE,100)
Block(1,7,-1,MOSSY_COBBLESTONE,50,COBBLESTONE,100)
Block(1,7,0,MOSSY_COBBLESTONE,50,COBBLESTONE,100)
Block(1,7,1,MOSSY_COBBLESTONE,50,COBBLESTONE,100)
Block(1,7,2,MOSSY_COBBLESTONE,50,COBBLESTONE,100)
Block(1,7,3,MOSSY_COBBLESTONE,50,COBBLESTONE,100)
Block(1,7,4,MOSSY_COBBLESTONE,50,COBBLESTONE,100)
Block(1,7,5,MOSSY_COBBLESTONE,50,COBBLESTONE,100)
Block(1,7,6,MOSSY_COBBLESTONE,50,COBBLESTONE,100)
Block(1,7,7,MOSSY_COBBLESTONE,50,COBBLESTONE,100)
Block(1,7,8,MOSSY_COBBLESTONE,50,COBBLESTONE,100)
Block(1,8,-7,AIR,25,VINE:1,100)
Block(1,8,-6,COBBLE_WALL:1,50,COBBLE_WALL,100)
Block(1,8,-5,MOSSY_COBBLESTONE,50,COBBLESTONE,100)
Block(1,8,-4,MOSSY_COBBLESTONE,50,COBBLESTONE,100)
Block(1,8,-3,MOSSY_COBBLESTONE,50,COBBLESTONE,100)
Block(1,8,-2,MOSSY_COBBLESTONE,50,COBBLESTONE,100)
Block(1,8,-1,MOSSY_COBBLESTONE,50,COBBLESTONE,100)
Block(1,8,0,MOSSY_COBBLESTONE,50,COBBLESTONE,100)
Block(1,8,1,MOSSY_COBBLESTONE,50,COBBLESTONE,100)
Block(1,8,2,MOSSY_COBBLESTONE,50,COBBLESTONE,100)
Block(1,8,3,MOSSY_COBBLESTONE,50,COBBLESTONE,100)
Block(1,8,4,MOSSY_COBBLESTONE,50,COBBLESTONE,100)
Block(1,8,5,MOSSY_COBBLESTONE,50,COBBLESTONE,100)
Block(1,8,6,MOSSY_COBBLESTONE,50,COBBLESTONE,100)
Block(1,8,7,MOSSY_COBBLESTONE,50,COBBLESTONE,100)
Block(1,8,8,MOSSY_COBBLESTONE,50,COBBLESTONE,100)
Block(1,9,-7,AIR,25,VINE:1,100)
Block(1,9,-6,AIR,25,VINE:1,100)
Block(1,9,-5,SMOOTH_BRICK:3)
Block(1,9,-4,MOSSY_COBBLESTONE,50,COBBLESTONE,100)
Block(1,9,-3,MOSSY_COBBLESTONE,50,COBBLESTONE,100)
Block(1,9,-2,MOSSY_COBBLESTONE,50,COBBLESTONE,100)
Block(1,9,-1,MOSSY_COBBLESTONE,50,COBBLESTONE,100)
Block(1,9,0,MOSSY_COBBLESTONE,50,COBBLESTONE,100)
Block(1,9,1,MOSSY_COBBLESTONE,50,COBBLESTONE,100)
Block(1,9,2,MOSSY_COBBLESTONE,50,COBBLESTONE,100)
Block(1,9,3,MOSSY_COBBLESTONE,50,COBBLESTONE,100)
Block(1,9,4,MOSSY_COBBLESTONE,50,COBBLESTONE,100)
Block(1,9,5,MOSSY_COBBLESTONE,50,COBBLESTONE,100)
Block(1,9,6,MOSSY_COBBLESTONE,50,COBBLESTONE,100)
Block(1,9,7,MOSSY_COBBLESTONE,50,COBBLESTONE,100)
Block(1,9,8,MOSSY_COBBLESTONE,50,COBBLESTONE,100)
Block(1,10,-7,AIR,25,VINE:1,100)
Block(1,10,-6,AIR,25,VINE:1,100)
Block(1,10,-5,SMOOTH_BRICK:3)
Block(1,10,-4,MOSSY_COBBLESTONE,50,COBBLESTONE,100)
Block(1,10,-3,MOSSY_COBBLESTONE,50,COBBLESTONE,100)
Block(1,10,-2,MOSSY_COBBLESTONE,50,COBBLESTONE,100)
Block(1,10,-1,MOSSY_COBBLESTONE,50,COBBLESTONE,100)
Block(1,10,0,MOSSY_COBBLESTONE,50,COBBLESTONE,100)
Block(1,10,1,MOSSY_COBBLESTONE,50,COBBLESTONE,100)
Block(1,10,2,MOSSY_COBBLESTONE,50,COBBLESTONE,100)
Block(1,10,3,MOSSY_COBBLESTONE,50,COBBLESTONE,100)
Block(1,10,4,MOSSY_COBBLESTONE,50,COBBLESTONE,100)
Block(1,10,5,MOSSY_COBBLESTONE,50,COBBLESTONE,100)
Block(1,10,6,MOSSY_COBBLESTONE,50,COBBLESTONE,100)
Block(1,10,7,MOSSY_COBBLESTONE,50,COBBLESTONE,100)
Block(1,10,8,MOSSY_COBBLESTONE,50,COBBLESTONE,100)
Block(1,11,-7,AIR,25,VINE:1,100)
Block(1,11,-6,COBBLE_WALL:1,50,COBBLE_WALL,100)
Block(1,11,-5,SMOOTH_BRICK)
Block(1,11,-4,SMOOTH_BRICK)
Block(1,11,-3,SMOOTH_BRICK)
Block(1,11,-2,MOSSY_COBBLESTONE,50,COBBLESTONE,100)
Block(1,11,-1,MOSSY_COBBLESTONE,50,COBBLESTONE,100)
Block(1,11,0,MOSSY_COBBLESTONE,50,COBBLESTONE,100)
Block(1,11,1,MOSSY_COBBLESTONE,50,COBBLESTONE,100)
Block(1,11,2,MOSSY_COBBLESTONE,50,COBBLESTONE,100)
Block(1,11,3,MOSSY_COBBLESTONE,50,COBBLESTONE,100)
Block(1,11,4,MOSSY_COBBLESTONE,50,COBBLESTONE,100)
Block(1,11,5,MOSSY_COBBLESTONE,50,COBBLESTONE,100)
Block(1,11,6,MOSSY_COBBLESTONE,50,COBBLESTONE,100)
Block(1,11,7,MOSSY_COBBLESTONE,50,COBBLESTONE,100)
Block(1,11,8,MOSSY_COBBLESTONE,50,COBBLESTONE,100)
Block(1,12,-7,AIR,25,VINE:1,100)
Block(1,12,-6,MOSSY_COBBLESTONE,50,COBBLESTONE,100)
Block(1,12,-3,COBBLE_WALL:1,50,COBBLE_WALL,100)
Block(1,12,-2,MOSSY_COBBLESTONE,50,COBBLESTONE,100)
Block(1,12,-1,MOSSY_COBBLESTONE,50,COBBLESTONE,100)
Block(1,12,0,MOSSY_COBBLESTONE,50,COBBLESTONE,100)
Block(1,12,1,MOSSY_COBBLESTONE,50,COBBLESTONE,100)
Block(1,12,2,MOSSY_COBBLESTONE,50,COBBLESTONE,100)
Block(1,12,3,MOSSY_COBBLESTONE,50,COBBLESTONE,100)
Block(1,12,4,MOSSY_COBBLESTONE,50,COBBLESTONE,100)
Block(1,12,5,MOSSY_COBBLESTONE,50,COBBLESTONE,100)
Block(1,12,6,MOSSY_COBBLESTONE,50,COBBLESTONE,100)
Block(1,12,7,MOSSY_COBBLESTONE,50,COBBLESTONE,100)
Block(1,12,8,MOSSY_COBBLESTONE,50,COBBLESTONE,100)
Block(1,13,-2,COBBLE_WALL:1,50,COBBLE_WALL,100)
Block(1,13,-1,SMOOTH_BRICK:3)
Block(1,13,0,MOSSY_COBBLESTONE,50,COBBLESTONE,100)
Block(1,13,1,MOSSY_COBBLESTONE,50,COBBLESTONE,100)
Block(1,13,2,MOSSY_COBBLESTONE,50,COBBLESTONE,100)
Block(1,13,3,MOSSY_COBBLESTONE,50,COBBLESTONE,100)
Block(1,13,4,MOSSY_COBBLESTONE,50,COBBLESTONE,100)
Block(1,13,5,MOSSY_COBBLESTONE,50,COBBLESTONE,100)
Block(1,13,6,MOSSY_COBBLESTONE,50,COBBLESTONE,100)
Block(1,13,7,MOSSY_COBBLESTONE,50,COBBLESTONE,100)
Block(1,13,8,MOSSY_COBBLESTONE,50,COBBLESTONE,100)
Block(1,14,-2,COBBLE_WALL:1,50,COBBLE_WALL,100)
Block(1,14,-1,SMOOTH_BRICK:3)
Block(1,14,0,MOSSY_COBBLESTONE,50,COBBLESTONE,100)
Block(1,14,1,MOSSY_COBBLESTONE,50,COBBLESTONE,100)
Block(1,14,2,MOSSY_COBBLESTONE,50,COBBLESTONE,100)
Block(1,14,3,MOSSY_COBBLESTONE,50,COBBLESTONE,100)
Block(1,14,4,MOSSY_COBBLESTONE,50,COBBLESTONE,100)
Block(1,14,5,MOSSY_COBBLESTONE,50,COBBLESTONE,100)
Block(1,14,6,MOSSY_COBBLESTONE,50,COBBLESTONE,100)
Block(1,14,7,MOSSY_COBBLESTONE,50,COBBLESTONE,100)
Block(1,14,8,MOSSY_COBBLESTONE,50,COBBLESTONE,100)
Block(1,15,-3,COBBLESTONE_STAIRS:6)
Block(1,15,-2,MOSSY_COBBLESTONE,50,COBBLESTONE,100)
Block(1,15,-1,SMOOTH_BRICK)
Block(1,15,0,SMOOTH_BRICK)
Block(1,15,1,SMOOTH_BRICK)
Block(1,15,2,MOSSY_COBBLESTONE,50,COBBLESTONE,100)
Block(1,15,3,MOSSY_COBBLESTONE,50,COBBLESTONE,100)
Block(1,15,4,MOSSY_COBBLESTONE,50,COBBLESTONE,100)
Block(1,15,5,MOSSY_COBBLESTONE,50,COBBLESTONE,100)
Block(1,15,6,MOSSY_COBBLESTONE,50,COBBLESTONE,100)
Block(1,15,7,MOSSY_COBBLESTONE,50,COBBLESTONE,100)
Block(1,15,8,MOSSY_COBBLESTONE,50,COBBLESTONE,100)
Block(1,16,-3,76:5)
Block(1,16,-2,COBBLE_WALL:1,50,COBBLE_WALL,100)
Block(1,16,1,AIR,25,VINE:1,100)
Block(1,16,2,COBBLE_WALL:1,50,COBBLE_WALL,100)
Block(1,16,3,MOSSY_COBBLESTONE,50,COBBLESTONE,100)
Block(1,16,4,COBBLE_WALL:1,50,COBBLE_WALL,100)
Block(1,16,5,COBBLE_WALL:1,50,COBBLE_WALL,100)
Block(1,16,6,MOSSY_COBBLESTONE,50,COBBLESTONE,100)
Block(1,16,7,COBBLE_WALL:1,50,COBBLE_WALL,100)
Block(1,16,8,COBBLE_WALL:1,50,COBBLE_WALL,100)
Block(1,17,1,AIR,25,VINE:1,100)
Block(1,17,3,COBBLE_WALL:1,50,COBBLE_WALL,100)
Block(1,17,4,AIR,25,VINE:8,100)
Block(1,17,5,AIR,25,VINE:8,100)
Block(1,17,6,COBBLE_WALL:1,50,COBBLE_WALL,100)
Block(1,17,7,AIR,25,VINE:8,100)
Block(1,17,8,AIR,25,VINE:8,100)
Block(1,18,1,AIR,25,VINE:1,100)
Block(1,18,3,COBBLE_WALL:1,50,COBBLE_WALL,100)
Block(1,18,4,AIR,25,VINE:8,100)
Block(1,18,5,AIR,25,VINE:8,100)
Block(1,18,6,COBBLE_WALL:1,50,COBBLE_WALL,100)
Block(1,18,7,AIR,25,VINE:8,100)
Block(1,18,8,AIR,25,VINE:8,100)
Block(1,19,1,AIR,25,VINE:1,100)
Block(1,19,2,COBBLE_WALL:1,50,COBBLE_WALL,100)
Block(1,19,3,MOSSY_COBBLESTONE,50,COBBLESTONE,100)
Block(1,19,4,COBBLE_WALL:1,50,COBBLE_WALL,100)
Block(1,19,5,COBBLE_WALL:1,50,COBBLE_WALL,100)
Block(1,19,6,MOSSY_COBBLESTONE,50,COBBLESTONE,100)
Block(1,19,7,COBBLE_WALL:1,50,COBBLE_WALL,100)
Block(1,19,8,COBBLE_WALL:1,50,COBBLE_WALL,100)
Block(1,20,1,AIR,25,VINE:1,100)
Block(1,20,2,MOSSY_COBBLESTONE,50,COBBLESTONE,100)
Block(1,20,3,COBBLE_WALL:1,50,COBBLE_WALL,100)
Block(1,20,4,MOSSY_COBBLESTONE,50,COBBLESTONE,100)
Block(1,20,5,MOSSY_COBBLESTONE,50,COBBLESTONE,100)
Block(1,20,6,COBBLE_WALL:1,50,COBBLE_WALL,100)
Block(1,20,7,MOSSY_COBBLESTONE,50,COBBLESTONE,100)
Block(1,20,8,MOSSY_COBBLESTONE,50,COBBLESTONE,100)
Block(2,0,-7,SMOOTH_BRICK)
Block(2,0,-6,SMOOTH_BRICK)
Block(2,0,-5,SMOOTH_BRICK)
Block(2,0,-4,SMOOTH_BRICK)
Block(2,0,-3,SMOOTH_BRICK)
Block(2,0,-2,SMOOTH_BRICK)
Block(2,0,-1,SMOOTH_BRICK)
Block(2,0,0,SMOOTH_BRICK)
Block(2,0,1,SMOOTH_BRICK)
Block(2,0,2,SMOOTH_BRICK)
Block(2,0,3,SMOOTH_BRICK)
Block(2,0,4,SMOOTH_BRICK)
Block(2,0,5,SMOOTH_BRICK)
Block(2,0,6,SMOOTH_BRICK)
Block(2,0,7,SMOOTH_BRICK)
Block(2,0,8,SMOOTH_BRICK)
Block(2,1,-7,SMOOTH_BRICK)
Block(2,1,-6,SMOOTH_BRICK)
Block(2,1,-5,SMOOTH_BRICK)
Block(2,1,-4,SMOOTH_BRICK)
Block(2,1,-3,SMOOTH_BRICK)
Block(2,1,-2,SMOOTH_BRICK)
Block(2,1,-1,SMOOTH_BRICK)
Block(2,1,0,SMOOTH_BRICK)
Block(2,1,1,SMOOTH_BRICK)
Block(2,1,2,SMOOTH_BRICK)
Block(2,1,3,SMOOTH_BRICK)
Block(2,1,4,SMOOTH_BRICK)
Block(2,1,5,SMOOTH_BRICK)
Block(2,1,6,SMOOTH_BRICK)
Block(2,1,7,SMOOTH_BRICK)
Block(2,1,8,SMOOTH_BRICK)
Block(2,2,-7,SMOOTH_BRICK)
Block(2,2,-6,SMOOTH_BRICK)
Block(2,2,-5,SMOOTH_BRICK)
Block(2,2,-4,SMOOTH_BRICK)
Block(2,2,-3,SMOOTH_BRICK)
Block(2,2,-2,SMOOTH_BRICK)
Block(2,2,-1,SMOOTH_BRICK)
Block(2,2,0,SMOOTH_BRICK)
Block(2,2,1,SMOOTH_BRICK)
Block(2,2,2,SMOOTH_BRICK)
Block(2,2,3,SMOOTH_BRICK)
Block(2,2,4,SMOOTH_BRICK)
Block(2,2,5,SMOOTH_BRICK)
Block(2,2,6,SMOOTH_BRICK)
Block(2,2,7,SMOOTH_BRICK)
Block(2,2,8,SMOOTH_BRICK)
Block(2,3,-7,MOSSY_COBBLESTONE,50,COBBLESTONE,100)
Block(2,3,-6,MOSSY_COBBLESTONE,50,COBBLESTONE,100)
Block(2,3,-5,MOSSY_COBBLESTONE,50,COBBLESTONE,100)
Block(2,3,-4,MOSSY_COBBLESTONE,50,COBBLESTONE,100)
Block(2,3,-3,MOSSY_COBBLESTONE,50,COBBLESTONE,100)
Block(2,3,-2,MOSSY_COBBLESTONE,50,COBBLESTONE,100)
Block(2,3,-1,MOSSY_COBBLESTONE,50,COBBLESTONE,100)
Block(2,3,0,MOSSY_COBBLESTONE,50,COBBLESTONE,100)
Block(2,3,1,MOSSY_COBBLESTONE,50,COBBLESTONE,100)
Block(2,3,2,MOSSY_COBBLESTONE,50,COBBLESTONE,100)
Block(2,3,3,MOSSY_COBBLESTONE,50,COBBLESTONE,100)
Block(2,3,4,MOSSY_COBBLESTONE,50,COBBLESTONE,100)
Block(2,3,5,MOSSY_COBBLESTONE,50,COBBLESTONE,100)
Block(2,3,6,MOSSY_COBBLESTONE,50,COBBLESTONE,100)
Block(2,3,7,MOSSY_COBBLESTONE,50,COBBLESTONE,100)
Block(2,3,8,MOSSY_COBBLESTONE,50,COBBLESTONE,100)
Block(2,4,-7,MOSSY_COBBLESTONE,50,COBBLESTONE,100)
Block(2,4,-6,MOSSY_COBBLESTONE,50,COBBLESTONE,100)
Block(2,4,-5,MOSSY_COBBLESTONE,50,COBBLESTONE,100)
Block(2,4,-4,MOSSY_COBBLESTONE,50,COBBLESTONE,100)
Block(2,4,-3,MOSSY_COBBLESTONE,50,COBBLESTONE,100)
Block(2,4,-2,MOSSY_COBBLESTONE,50,COBBLESTONE,100)
Block(2,4,-1,MOSSY_COBBLESTONE,50,COBBLESTONE,100)
Block(2,4,0,MOSSY_COBBLESTONE,50,COBBLESTONE,100)
Block(2,4,1,MOSSY_COBBLESTONE,50,COBBLESTONE,100)
Block(2,4,2,MOSSY_COBBLESTONE,50,COBBLESTONE,100)
Block(2,4,3,MOSSY_COBBLESTONE,50,COBBLESTONE,100)
Block(2,4,4,MOSSY_COBBLESTONE,50,COBBLESTONE,100)
Block(2,4,5,MOSSY_COBBLESTONE,50,COBBLESTONE,100)
Block(2,4,6,MOSSY_COBBLESTONE,50,COBBLESTONE,100)
Block(2,4,7,MOSSY_COBBLESTONE,50,COBBLESTONE,100)
Block(2,4,8,MOSSY_COBBLESTONE,50,COBBLESTONE,100)
Block(2,5,-7,MOSSY_COBBLESTONE,50,COBBLESTONE,100)
Block(2,5,-6,MOSSY_COBBLESTONE,50,COBBLESTONE,100)
Block(2,5,-5,MOSSY_COBBLESTONE,50,COBBLESTONE,100)
Block(2,5,-4,MOSSY_COBBLESTONE,50,COBBLESTONE,100)
Block(2,5,-3,MOSSY_COBBLESTONE,50,COBBLESTONE,100)
Block(2,5,-2,MOSSY_COBBLESTONE,50,COBBLESTONE,100)
Block(2,5,-1,MOSSY_COBBLESTONE,50,COBBLESTONE,100)
Block(2,5,0,MOSSY_COBBLESTONE,50,COBBLESTONE,100)
Block(2,5,1,MOSSY_COBBLESTONE,50,COBBLESTONE,100)
Block(2,5,2,MOSSY_COBBLESTONE,50,COBBLESTONE,100)
Block(2,5,3,MOSSY_COBBLESTONE,50,COBBLESTONE,100)
Block(2,5,4,MOSSY_COBBLESTONE,50,COBBLESTONE,100)
Block(2,5,5,MOSSY_COBBLESTONE,50,COBBLESTONE,100)
Block(2,5,6,MOSSY_COBBLESTONE,50,COBBLESTONE,100)
Block(2,5,7,MOSSY_COBBLESTONE,50,COBBLESTONE,100)
Block(2,5,8,MOSSY_COBBLESTONE,50,COBBLESTONE,100)
Block(2,6,-7,STONE)
Block(2,6,-6,STONE)
Block(2,6,-5,STONE)
Block(2,6,-4,STONE)
Block(2,6,-3,STONE)
Block(2,6,-2,STONE)
Block(2,6,-1,STONE)
Block(2,6,0,STONE)
Block(2,6,1,STONE)
Block(2,6,2,STONE)
Block(2,6,3,STONE)
Block(2,6,4,STONE)
Block(2,6,5,STONE)
Block(2,6,6,STONE)
Block(2,6,7,STONE)
Block(2,6,8,STONE)
Block(2,7,-7,SMOOTH_BRICK)
Block(2,7,-6,MOSSY_COBBLESTONE,50,COBBLESTONE,100)
Block(2,7,-5,MOSSY_COBBLESTONE,50,COBBLESTONE,100)
Block(2,7,-4,MOSSY_COBBLESTONE,50,COBBLESTONE,100)
Block(2,7,-3,MOSSY_COBBLESTONE,50,COBBLESTONE,100)
Block(2,7,-2,MOSSY_COBBLESTONE,50,COBBLESTONE,100)
Block(2,7,-1,MOSSY_COBBLESTONE,50,COBBLESTONE,100)
Block(2,7,0,MOSSY_COBBLESTONE,50,COBBLESTONE,100)
Block(2,7,1,MOSSY_COBBLESTONE,50,COBBLESTONE,100)
Block(2,7,2,MOSSY_COBBLESTONE,50,COBBLESTONE,100)
Block(2,7,3,MOSSY_COBBLESTONE,50,COBBLESTONE,100)
Block(2,7,4,MOSSY_COBBLESTONE,50,COBBLESTONE,100)
Block(2,7,5,MOSSY_COBBLESTONE,50,COBBLESTONE,100)
Block(2,7,6,MOSSY_COBBLESTONE,50,COBBLESTONE,100)
Block(2,7,7,MOSSY_COBBLESTONE,50,COBBLESTONE,100)
Block(2,7,8,MOSSY_COBBLESTONE,50,COBBLESTONE,100)
Block(2,8,-7,AIR,25,VINE:1,100)
Block(2,8,-6,COBBLE_WALL:1,50,COBBLE_WALL,100)
Block(2,8,-5,MOSSY_COBBLESTONE,50,COBBLESTONE,100)
Block(2,8,-4,MOSSY_COBBLESTONE,50,COBBLESTONE,100)
Block(2,8,-3,MOSSY_COBBLESTONE,50,COBBLESTONE,100)
Block(2,8,-2,MOSSY_COBBLESTONE,50,COBBLESTONE,100)
Block(2,8,-1,MOSSY_COBBLESTONE,50,COBBLESTONE,100)
Block(2,8,0,MOSSY_COBBLESTONE,50,COBBLESTONE,100)
Block(2,8,1,MOSSY_COBBLESTONE,50,COBBLESTONE,100)
Block(2,8,2,MOSSY_COBBLESTONE,50,COBBLESTONE,100)
Block(2,8,3,MOSSY_COBBLESTONE,50,COBBLESTONE,100)
Block(2,8,4,MOSSY_COBBLESTONE,50,COBBLESTONE,100)
Block(2,8,5,MOSSY_COBBLESTONE,50,COBBLESTONE,100)
Block(2,8,6,MOSSY_COBBLESTONE,50,COBBLESTONE,100)
Block(2,8,7,MOSSY_COBBLESTONE,50,COBBLESTONE,100)
Block(2,8,8,MOSSY_COBBLESTONE,50,COBBLESTONE,100)
Block(2,9,-7,AIR,25,VINE:1,100)
Block(2,9,-6,AIR,25,VINE:1,100)
Block(2,9,-5,SMOOTH_BRICK:3)
Block(2,9,-4,MOSSY_COBBLESTONE,50,COBBLESTONE,100)
Block(2,9,-3,MOSSY_COBBLESTONE,50,COBBLESTONE,100)
Block(2,9,-2,MOSSY_COBBLESTONE,50,COBBLESTONE,100)
Block(2,9,-1,MOSSY_COBBLESTONE,50,COBBLESTONE,100)
Block(2,9,0,MOSSY_COBBLESTONE,50,COBBLESTONE,100)
Block(2,9,1,MOSSY_COBBLESTONE,50,COBBLESTONE,100)
