IsOTGPlus:true

Author: PG85

Description: No description given

Version: MCW104

SettingsMode: WriteDisable

Tree: false

Frequency: 1

RotateRandomly: false

SpawnHeight: highestBlock

MinHeight: 0

MaxHeight: 256

ExcludedBiomes: All

SourceBlocks: AIR

MaxPercentageOutsideSourceBlock: 100

OutsideSourceBlock: placeAnyway

InheritBO3: 

OverrideChildSettings: true

CanOverride: true

MustBeBelowOther: false

MustBeInside: we-jungletempledungeon16x16x84exitsNoRoof, we-jungletempledungeon16x16x83exitsNoRoof, we-jungletempledungeon16x16x82exitscornerNoRoof, we-jungletempledungeon16x16x82exitsoppositeNoRoof, we-jungletempledungeon16x16x81exitNoRoof

CannotBeInside:

CanSpawnOnWater: true

SpawnOnWaterOnly: false

SpawnUnderWater: false

SpawnAtWaterLevel: false

HeightOffset: 0

RemoveAir: false

ReplaceAbove: NONE

ReplaceBelow: 

ReplaceWithBiomeBlocks: true

ReplaceWithGroundBlock: DIRT

ReplaceWithSurfaceBlock: GRASS

SmoothRadius: -1

SmoothHeightOffset: 0

SmoothStartTop: false

SmoothStartWood: false

SmoothingSurfaceBlock: 

SmoothingGroundBlock: 

BO3Group: 

IsSpawnPoint: false

SpawnPointX: 8

SpawnPointY: -1

SpawnPointZ: 7

Block(-6,0,4,67:1)
Block(-6,0,5,67:1)
Block(-6,0,6,67:1)
Block(-6,0,7,MOSSY_COBBLESTONE,50,COBBLESTONE,100)
Block(-6,0,8,MOSSY_COBBLESTONE,50,COBBLESTONE,100)
Block(-6,1,4,0)
Block(-6,1,5,0)
Block(-6,1,6,0)
Block(-6,1,7,98:3)
Block(-6,1,8,MOSSY_COBBLESTONE,50,COBBLESTONE,100)
Block(-6,2,4,0)
Block(-6,2,5,0)
Block(-6,2,6,0)
Block(-6,2,7,MOSSY_COBBLESTONE,50,COBBLESTONE,100)
Block(-6,2,8,MOSSY_COBBLESTONE,50,COBBLESTONE,100)
Block(-6,3,4,0)
Block(-6,3,5,0)
Block(-6,3,6,0)
Block(-5,0,4,0)
Block(-5,0,5,0)
Block(-5,0,6,67:2)
Block(-5,0,7,MOSSY_COBBLESTONE,50,COBBLESTONE,100)
Block(-5,0,8,MOSSY_COBBLESTONE,50,COBBLESTONE,100)
Block(-5,1,4,0)
Block(-5,1,5,0)
Block(-5,1,6,0)
Block(-5,1,7,98:3)
Block(-5,1,8,MOSSY_COBBLESTONE,50,COBBLESTONE,100)
Block(-5,2,4,0)
Block(-5,2,5,0)
Block(-5,2,6,0)
Block(-5,2,7,MOSSY_COBBLESTONE,50,COBBLESTONE,100)
Block(-5,2,8,MOSSY_COBBLESTONE,50,COBBLESTONE,100)
Block(-5,3,4,0)
Block(-5,3,5,0)
Block(-5,3,6,0)
Block(-4,0,4,0)
Block(-4,0,5,0)
Block(-4,0,6,67:2)
Block(-4,0,7,MOSSY_COBBLESTONE,50,COBBLESTONE,100)
Block(-4,0,8,MOSSY_COBBLESTONE,50,COBBLESTONE,100)
Block(-4,1,4,0)
Block(-4,1,5,0)
Block(-4,1,6,0)
Block(-4,1,7,98:3)
Block(-4,1,8,MOSSY_COBBLESTONE,50,COBBLESTONE,100)
Block(-4,2,4,0)
Block(-4,2,5,0)
Block(-4,2,6,0)
Block(-4,2,7,MOSSY_COBBLESTONE,50,COBBLESTONE,100)
RandomBlock(-4,2,8,STONEBRICK:1,50,STONEBRICK:2,100)
Block(-4,3,4,0)
Block(-4,3,5,0)
Block(-4,3,6,0)
Block(-3,0,4,0)
Block(-3,0,5,0)
Block(-3,0,6,67:2)
Block(-3,0,7,MOSSY_COBBLESTONE,50,COBBLESTONE,100)
Block(-3,0,8,MOSSY_COBBLESTONE,50,COBBLESTONE,100)
Block(-3,1,4,0)
Block(-3,1,5,0)
Block(-3,1,6,0)
Block(-3,1,7,98:3)
Block(-3,1,8,MOSSY_COBBLESTONE,50,COBBLESTONE,100)
Block(-3,2,4,0)
Block(-3,2,5,0)
Block(-3,2,6,67:4)
Block(-3,2,7,MOSSY_COBBLESTONE,50,COBBLESTONE,100)
RandomBlock(-3,2,8,STONEBRICK:1,50,STONEBRICK:2,100)
Block(-3,3,4,0)
Block(-3,3,5,0)
Block(-3,3,6,0)
Block(-2,0,4,98:3)
Block(-2,0,5,MOSSY_COBBLESTONE,50,COBBLESTONE,100)
Block(-2,0,6,MOSSY_COBBLESTONE,50,COBBLESTONE,100)
Block(-2,0,7,MOSSY_COBBLESTONE,50,COBBLESTONE,100)
Block(-2,0,8,MOSSY_COBBLESTONE,50,COBBLESTONE,100)
Block(-2,1,4,98:3)
Block(-2,1,5,MOSSY_COBBLESTONE,50,COBBLESTONE,100)
Block(-2,1,6,MOSSY_COBBLESTONE,50,COBBLESTONE,100)
Block(-2,1,7,MOSSY_COBBLESTONE,50,COBBLESTONE,100)
Block(-2,1,8,MOSSY_COBBLESTONE,50,COBBLESTONE,100)
Block(-2,2,4,67:2)
Block(-2,2,5,MOSSY_COBBLESTONE,50,COBBLESTONE,100)
Block(-2,2,6,MOSSY_COBBLESTONE,50,COBBLESTONE,100)
RandomBlock(-2,2,7,STONEBRICK:1,50,STONEBRICK:2,100)
RandomBlock(-2,2,8,STONEBRICK:1,50,STONEBRICK:2,100)
Block(-2,3,4,0)
Block(-2,3,5,118)
Block(-2,3,6,0)
Block(-1,0,4,0)
Block(-1,0,5,67:2)
Block(-1,0,6,MOSSY_COBBLESTONE,50,COBBLESTONE,100)
Block(-1,0,7,MOSSY_COBBLESTONE,50,COBBLESTONE,100)
Block(-1,0,8,MOSSY_COBBLESTONE,50,COBBLESTONE,100)
Block(-1,1,4,0)
Block(-1,1,5,0)
Block(-1,1,6,MOSSY_COBBLESTONE,50,COBBLESTONE,100)
Block(-1,1,7,MOSSY_COBBLESTONE,50,COBBLESTONE,100)
Block(-1,1,8,MOSSY_COBBLESTONE,50,COBBLESTONE,100)
RandomBlock(-1,2,6,STONEBRICK:1,50,STONEBRICK:2,100)
RandomBlock(-1,2,7,STONEBRICK:1,50,STONEBRICK:2,100)
RandomBlock(-1,2,8,STONEBRICK:1,50,STONEBRICK:2,100)
Block(-1,3,4,0)
Block(-1,3,5,0)
Block(-1,3,6,AIR)
Block(0,0,4,0)
Block(0,0,5,67:2)
Block(0,0,6,MOSSY_COBBLESTONE,50,COBBLESTONE,100)
Block(0,0,7,MOSSY_COBBLESTONE,50,COBBLESTONE,100)
Block(0,0,8,MOSSY_COBBLESTONE,50,COBBLESTONE,100)
Block(0,1,4,0)
Block(0,1,5,0)
Block(0,1,6,MOSSY_COBBLESTONE,50,COBBLESTONE,100)
Block(0,1,7,MOSSY_COBBLESTONE,50,COBBLESTONE,100)
Block(0,1,8,MOSSY_COBBLESTONE,50,COBBLESTONE,100)
RandomBlock(0,2,6,STONEBRICK:1,50,STONEBRICK:2,100)
RandomBlock(0,2,7,STONEBRICK:1,50,STONEBRICK:2,100)
RandomBlock(0,2,8,STONEBRICK:1,50,STONEBRICK:2,100)
Block(0,3,4,0)
Block(0,3,5,0)
Block(0,3,6,AIR)
Block(1,0,4,98:3)
Block(1,0,5,MOSSY_COBBLESTONE,50,COBBLESTONE,100)
Block(1,0,6,MOSSY_COBBLESTONE,50,COBBLESTONE,100)
Block(1,0,7,MOSSY_COBBLESTONE,50,COBBLESTONE,100)
Block(1,0,8,MOSSY_COBBLESTONE,50,COBBLESTONE,100)
Block(1,1,4,98:3)
Block(1,1,5,MOSSY_COBBLESTONE,50,COBBLESTONE,100)
Block(1,1,6,MOSSY_COBBLESTONE,50,COBBLESTONE,100)
Block(1,1,7,MOSSY_COBBLESTONE,50,COBBLESTONE,100)
Block(1,1,8,MOSSY_COBBLESTONE,50,COBBLESTONE,100)
Block(1,2,4,67:2)
Block(1,2,5,MOSSY_COBBLESTONE,50,COBBLESTONE,100)
Block(1,2,6,MOSSY_COBBLESTONE,50,COBBLESTONE,100)
RandomBlock(1,2,7,STONEBRICK:1,50,STONEBRICK:2,100)
RandomBlock(1,2,8,STONEBRICK:1,50,STONEBRICK:2,100)
Block(1,3,4,0)
Block(1,3,5,118)
Block(1,3,6,0)
Block(2,0,4,0)
Block(2,0,5,0)
Block(2,0,6,67:2)
Block(2,0,7,MOSSY_COBBLESTONE,50,COBBLESTONE,100)
Block(2,0,8,MOSSY_COBBLESTONE,50,COBBLESTONE,100)
Block(2,1,4,0)
Block(2,1,5,0)
Block(2,1,6,0)
Block(2,1,7,98:3)
Block(2,1,8,MOSSY_COBBLESTONE,50,COBBLESTONE,100)
Block(2,2,4,0)
Block(2,2,5,0)
Block(2,2,6,67:5)
Block(2,2,7,MOSSY_COBBLESTONE,50,COBBLESTONE,100)
RandomBlock(2,2,8,STONEBRICK:1,50,STONEBRICK:2,100)
Block(2,3,4,0)
Block(2,3,5,0)
Block(2,3,6,0)
Block(3,0,4,0)
Block(3,0,5,0)
Block(3,0,6,67:2)
Block(3,0,7,MOSSY_COBBLESTONE,50,COBBLESTONE,100)
Block(3,0,8,MOSSY_COBBLESTONE,50,COBBLESTONE,100)
Block(3,1,4,0)
Block(3,1,5,0)
Block(3,1,6,0)
Block(3,1,7,98:3)
Block(3,1,8,MOSSY_COBBLESTONE,50,COBBLESTONE,100)
Block(3,2,4,0)
Block(3,2,5,0)
Block(3,2,6,0)
Block(3,2,7,MOSSY_COBBLESTONE,50,COBBLESTONE,100)
RandomBlock(3,2,8,STONEBRICK:1,50,STONEBRICK:2,100)
Block(3,3,4,0)
Block(3,3,5,0)
Block(3,3,6,0)
Block(4,0,4,0)
Block(4,0,5,0)
Block(4,0,6,67:2)
Block(4,0,7,MOSSY_COBBLESTONE,50,COBBLESTONE,100)
Block(4,0,8,MOSSY_COBBLESTONE,50,COBBLESTONE,100)
Block(4,1,4,0)
Block(4,1,5,0)
Block(4,1,6,0)
Block(4,1,7,98:3)
Block(4,1,8,MOSSY_COBBLESTONE,50,COBBLESTONE,100)
Block(4,2,4,0)
Block(4,2,5,0)
Block(4,2,6,0)
Block(4,2,7,MOSSY_COBBLESTONE,50,COBBLESTONE,100)
Block(4,2,8,MOSSY_COBBLESTONE,50,COBBLESTONE,100)
Block(4,3,4,0)
Block(4,3,5,0)
Block(4,3,6,0)
Block(5,0,4,67)
Block(5,0,5,67)
Block(5,0,6,67)
Block(5,0,7,MOSSY_COBBLESTONE,50,COBBLESTONE,100)
Block(5,0,8,MOSSY_COBBLESTONE,50,COBBLESTONE,100)
Block(5,1,4,0)
Block(5,1,5,0)
Block(5,1,6,0)
Block(5,1,7,98:3)
Block(5,1,8,MOSSY_COBBLESTONE,50,COBBLESTONE,100)
Block(5,2,4,0)
Block(5,2,5,0)
Block(5,2,6,0)
Block(5,2,7,MOSSY_COBBLESTONE,50,COBBLESTONE,100)
Block(5,2,8,MOSSY_COBBLESTONE,50,COBBLESTONE,100)
Block(5,3,4,0)
Block(5,3,5,0)
Block(5,3,6,0)
