IsOTGPlus:true

Author: PG85

Description: No description given

Version: MCW104

SettingsMode: WriteDisable

Tree: false

Frequency: 1

RotateRandomly: false

SpawnHeight: highestBlock

MinHeight: 0

MaxHeight: 256

ExcludedBiomes: All

SourceBlocks: AIR

MaxPercentageOutsideSourceBlock: 100

OutsideSourceBlock: placeAnyway

InheritBO3: 

OverrideChildSettings: true

CanOverride: true

MustBeBelowOther: false

MustBeInside: we-jungletempledungeon16x16x8, we-jungletempledungeon16x16x8B

CanSpawnOnWater: true

SpawnOnWaterOnly: false

SpawnUnderWater: false

SpawnAtWaterLevel: false

HeightOffset: 0

RemoveAir: false

ReplaceAbove: NONE

ReplaceBelow: 

ReplaceWithBiomeBlocks: true

ReplaceWithGroundBlock: DIRT

ReplaceWithSurfaceBlock: GRASS

SmoothRadius: -1

SmoothHeightOffset: 0

SmoothStartTop: false

SmoothStartWood: false

SmoothingSurfaceBlock: 

SmoothingGroundBlock: 

BO3Group: 

IsSpawnPoint: false

SpawnPointX: 8

SpawnPointY: -1

SpawnPointZ: 7

Block(-8,1,-7,MOSSY_COBBLESTONE,50,COBBLESTONE,100)
Block(-8,1,-6,MOSSY_COBBLESTONE,50,COBBLESTONE,100)
Block(-8,1,-5,MOSSY_COBBLESTONE,50,COBBLESTONE,100)
Block(-8,1,-4,MOSSY_COBBLESTONE,50,COBBLESTONE,100)
Block(-8,1,-3,MOSSY_COBBLESTONE,50,COBBLESTONE,100)
Block(-8,1,-2,MOSSY_COBBLESTONE,50,COBBLESTONE,100)
Block(-8,1,-1,MOSSY_COBBLESTONE,50,COBBLESTONE,100)
Block(-8,1,0,MOSSY_COBBLESTONE,50,COBBLESTONE,100)
Block(-8,1,1,MOSSY_COBBLESTONE,50,COBBLESTONE,100)
Block(-8,1,2,MOSSY_COBBLESTONE,50,COBBLESTONE,100)
Block(-8,1,3,MOSSY_COBBLESTONE,50,COBBLESTONE,100)
Block(-8,1,4,MOSSY_COBBLESTONE,50,COBBLESTONE,100)
Block(-8,1,5,MOSSY_COBBLESTONE,50,COBBLESTONE,100)
Block(-8,1,6,MOSSY_COBBLESTONE,50,COBBLESTONE,100)
Block(-8,1,7,MOSSY_COBBLESTONE,50,COBBLESTONE,100)
Block(-8,1,8,MOSSY_COBBLESTONE,50,COBBLESTONE,100)
Block(-8,2,-7,MOSSY_COBBLESTONE,50,COBBLESTONE,100)
Block(-8,2,-6,MOSSY_COBBLESTONE,50,COBBLESTONE,100)
Block(-8,2,-5,MOSSY_COBBLESTONE,50,COBBLESTONE,100)
Block(-8,2,-4,MOSSY_COBBLESTONE,50,COBBLESTONE,100)
Block(-8,2,-3,MOSSY_COBBLESTONE,50,COBBLESTONE,100)
Block(-8,2,-2,MOSSY_COBBLESTONE,50,COBBLESTONE,100)
Block(-8,2,-1,MOSSY_COBBLESTONE,50,COBBLESTONE,100)
Block(-8,2,0,MOSSY_COBBLESTONE,50,COBBLESTONE,100)
Block(-8,2,1,MOSSY_COBBLESTONE,50,COBBLESTONE,100)
Block(-8,2,2,MOSSY_COBBLESTONE,50,COBBLESTONE,100)
Block(-8,2,3,MOSSY_COBBLESTONE,50,COBBLESTONE,100)
Block(-8,2,4,MOSSY_COBBLESTONE,50,COBBLESTONE,100)
Block(-8,2,5,MOSSY_COBBLESTONE,50,COBBLESTONE,100)
Block(-8,2,6,MOSSY_COBBLESTONE,50,COBBLESTONE,100)
Block(-8,2,7,MOSSY_COBBLESTONE,50,COBBLESTONE,100)
Block(-8,2,8,MOSSY_COBBLESTONE,50,COBBLESTONE,100)
Block(-8,3,-7,MOSSY_COBBLESTONE,50,COBBLESTONE,100)
Block(-8,3,-6,MOSSY_COBBLESTONE,50,COBBLESTONE,100)
Block(-8,3,-5,MOSSY_COBBLESTONE,50,COBBLESTONE,100)
Block(-8,3,-4,MOSSY_COBBLESTONE,50,COBBLESTONE,100)
Block(-8,3,-3,MOSSY_COBBLESTONE,50,COBBLESTONE,100)
Block(-8,3,-2,MOSSY_COBBLESTONE,50,COBBLESTONE,100)
Block(-8,3,-1,MOSSY_COBBLESTONE,50,COBBLESTONE,100)
RandomBlock(-8,3,0,STONEBRICK:1,50,STONEBRICK:2,100)
RandomBlock(-8,3,1,STONEBRICK:1,50,STONEBRICK:2,100)
Block(-8,3,2,MOSSY_COBBLESTONE,50,COBBLESTONE,100)
Block(-8,3,3,MOSSY_COBBLESTONE,50,COBBLESTONE,100)
Block(-8,3,4,MOSSY_COBBLESTONE,50,COBBLESTONE,100)
Block(-8,3,5,MOSSY_COBBLESTONE,50,COBBLESTONE,100)
Block(-8,3,6,MOSSY_COBBLESTONE,50,COBBLESTONE,100)
Block(-8,3,7,MOSSY_COBBLESTONE,50,COBBLESTONE,100)
Block(-8,3,8,MOSSY_COBBLESTONE,50,COBBLESTONE,100)
Block(-7,1,-7,MOSSY_COBBLESTONE,50,COBBLESTONE,100)
Block(-7,1,-6,MOSSY_COBBLESTONE,50,COBBLESTONE,100)
Block(-7,1,-5,MOSSY_COBBLESTONE,50,COBBLESTONE,100)
Block(-7,1,-4,MOSSY_COBBLESTONE,50,COBBLESTONE,100)
Block(-7,1,-3,MOSSY_COBBLESTONE,50,COBBLESTONE,100)
Block(-7,1,-2,MOSSY_COBBLESTONE,50,COBBLESTONE,100)
Block(-7,1,-1,MOSSY_COBBLESTONE,50,COBBLESTONE,100)
Block(-7,1,0,MOSSY_COBBLESTONE,50,COBBLESTONE,100)
Block(-7,1,1,MOSSY_COBBLESTONE,50,COBBLESTONE,100)
Block(-7,1,2,MOSSY_COBBLESTONE,50,COBBLESTONE,100)
Block(-7,1,3,MOSSY_COBBLESTONE,50,COBBLESTONE,100)
Block(-7,1,4,MOSSY_COBBLESTONE,50,COBBLESTONE,100)
Block(-7,1,5,MOSSY_COBBLESTONE,50,COBBLESTONE,100)
Block(-7,1,6,0)
Block(-7,1,7,MOSSY_COBBLESTONE,50,COBBLESTONE,100)
Block(-7,1,8,MOSSY_COBBLESTONE,50,COBBLESTONE,100)
Block(-7,2,-7,MOSSY_COBBLESTONE,50,COBBLESTONE,100)
Block(-7,2,-6,MOSSY_COBBLESTONE,50,COBBLESTONE,100)
Block(-7,2,-5,98:3)
Block(-7,2,-4,98:3)
Block(-7,2,-3,98:3)
Block(-7,2,-2,98:3)
Block(-7,2,-1,MOSSY_COBBLESTONE,50,COBBLESTONE,100)
Block(-7,2,0,MOSSY_COBBLESTONE,50,COBBLESTONE,100)
Block(-7,2,1,MOSSY_COBBLESTONE,50,COBBLESTONE,100)
Block(-7,2,2,MOSSY_COBBLESTONE,50,COBBLESTONE,100)
Block(-7,2,3,98:3)
Block(-7,2,4,98:3)
Block(-7,2,5,98:3)
Block(-7,2,6,98:3)
Block(-7,2,7,MOSSY_COBBLESTONE,50,COBBLESTONE,100)
Block(-7,2,8,MOSSY_COBBLESTONE,50,COBBLESTONE,100)
Block(-7,3,-7,MOSSY_COBBLESTONE,50,COBBLESTONE,100)
Block(-7,3,-6,MOSSY_COBBLESTONE,50,COBBLESTONE,100)
Block(-7,3,-5,MOSSY_COBBLESTONE,50,COBBLESTONE,100)
Block(-7,3,-4,MOSSY_COBBLESTONE,50,COBBLESTONE,100)
Block(-7,3,-3,MOSSY_COBBLESTONE,50,COBBLESTONE,100)
Block(-7,3,-2,MOSSY_COBBLESTONE,50,COBBLESTONE,100)
Block(-7,3,-1,MOSSY_COBBLESTONE,50,COBBLESTONE,100)
RandomBlock(-7,3,0,STONEBRICK:1,50,STONEBRICK:2,100)
RandomBlock(-7,3,1,STONEBRICK:1,50,STONEBRICK:2,100)
Block(-7,3,2,MOSSY_COBBLESTONE,50,COBBLESTONE,100)
Block(-7,3,3,MOSSY_COBBLESTONE,50,COBBLESTONE,100)
Block(-7,3,4,MOSSY_COBBLESTONE,50,COBBLESTONE,100)
Block(-7,3,5,MOSSY_COBBLESTONE,50,COBBLESTONE,100)
Block(-7,3,6,MOSSY_COBBLESTONE,50,COBBLESTONE,100)
Block(-7,3,7,MOSSY_COBBLESTONE,50,COBBLESTONE,100)
Block(-7,3,8,MOSSY_COBBLESTONE,50,COBBLESTONE,100)
Block(-6,1,-7,MOSSY_COBBLESTONE,50,COBBLESTONE,100)
Block(-6,1,-6,MOSSY_COBBLESTONE,50,COBBLESTONE,100)
Block(-6,1,-5,67:1)
Block(-6,1,-4,67:1)
Block(-6,1,-3,67:1)
Block(-6,1,-2,67:1)
Block(-6,1,-1,MOSSY_COBBLESTONE,50,COBBLESTONE,100)
Block(-6,1,0,MOSSY_COBBLESTONE,50,COBBLESTONE,100)
Block(-6,1,1,MOSSY_COBBLESTONE,50,COBBLESTONE,100)
Block(-6,1,2,MOSSY_COBBLESTONE,50,COBBLESTONE,100)
Block(-6,1,3,67:1)
Block(-6,1,4,67:1)
Block(-6,1,5,67:1)
Block(-6,1,6,67:2)
Block(-6,1,7,MOSSY_COBBLESTONE,50,COBBLESTONE,100)
Block(-6,1,8,MOSSY_COBBLESTONE,50,COBBLESTONE,100)
Block(-6,2,-7,MOSSY_COBBLESTONE,50,COBBLESTONE,100)
Block(-6,2,-6,98:3)
Block(-6,2,-5,0)
Block(-6,2,-4,0)
Block(-6,2,-3,0)
Block(-6,2,-2,0)
Block(-6,2,-1,MOSSY_COBBLESTONE,50,COBBLESTONE,100)
Block(-6,2,0,MOSSY_COBBLESTONE,50,COBBLESTONE,100)
Block(-6,2,1,MOSSY_COBBLESTONE,50,COBBLESTONE,100)
Block(-6,2,2,MOSSY_COBBLESTONE,50,COBBLESTONE,100)
Block(-6,2,3,0)
Block(-6,2,4,0)
Block(-6,2,5,0)
Block(-6,2,6,0)
Block(-6,2,7,98:3)
Block(-6,2,8,MOSSY_COBBLESTONE,50,COBBLESTONE,100)
Block(-6,3,-7,MOSSY_COBBLESTONE,50,COBBLESTONE,100)
Block(-6,3,-6,MOSSY_COBBLESTONE,50,COBBLESTONE,100)
Block(-6,3,-5,0)
Block(-6,3,-4,0)
Block(-6,3,-3,0)
Block(-6,3,-2,0)
Block(-6,3,-1,MOSSY_COBBLESTONE,50,COBBLESTONE,100)
RandomBlock(-6,3,0,STONEBRICK:1,50,STONEBRICK:2,100)
RandomBlock(-6,3,1,STONEBRICK:1,50,STONEBRICK:2,100)
Block(-6,3,2,MOSSY_COBBLESTONE,50,COBBLESTONE,100)
Block(-6,3,3,0)
Block(-6,3,4,0)
Block(-6,3,5,0)
Block(-6,3,6,0)
Block(-6,3,7,MOSSY_COBBLESTONE,50,COBBLESTONE,100)
Block(-6,3,8,MOSSY_COBBLESTONE,50,COBBLESTONE,100)
Block(-6,4,-5,0)
Block(-6,4,-4,0)
Block(-6,4,-3,0)
Block(-6,4,-2,0)
Block(-6,4,3,0)
Block(-6,4,4,0)
Block(-6,4,5,0)
Block(-6,4,6,0)
Block(-5,0,-4,0)
Block(-5,0,-3,0)
Block(-5,0,-2,0)
Block(-5,0,0,44:13)
Block(-5,0,1,44:13)
Block(-5,0,3,0)
Block(-5,0,4,0)
Block(-5,0,5,0)
Block(-5,1,-7,MOSSY_COBBLESTONE,50,COBBLESTONE,100)
Block(-5,1,-6,MOSSY_COBBLESTONE,50,COBBLESTONE,100)
Block(-5,1,-5,67:3)
Block(-5,1,-4,0)
Block(-5,1,-3,0)
Block(-5,1,-2,0)
Block(-5,1,-1,MOSSY_COBBLESTONE,50,COBBLESTONE,100)
Block(-5,1,0,67:1)
Block(-5,1,1,67:1)
Block(-5,1,2,MOSSY_COBBLESTONE,50,COBBLESTONE,100)
Block(-5,1,3,0)
Block(-5,1,4,0)
Block(-5,1,5,0)
Block(-5,1,6,67:2)
Block(-5,1,7,MOSSY_COBBLESTONE,50,COBBLESTONE,100)
Block(-5,1,8,MOSSY_COBBLESTONE,50,COBBLESTONE,100)
Block(-5,2,-7,MOSSY_COBBLESTONE,50,COBBLESTONE,100)
Block(-5,2,-6,98:3)
Block(-5,2,-5,0)
Block(-5,2,-4,0)
Block(-5,2,-3,0)
Block(-5,2,-2,0)
Block(-5,2,-1,MOSSY_COBBLESTONE,50,COBBLESTONE,100)
Block(-5,2,0,0)
Block(-5,2,1,0)
Block(-5,2,2,MOSSY_COBBLESTONE,50,COBBLESTONE,100)
Block(-5,2,3,0)
Block(-5,2,4,0)
Block(-5,2,5,0)
Block(-5,2,6,0)
Block(-5,2,7,98:3)
Block(-5,2,8,MOSSY_COBBLESTONE,50,COBBLESTONE,100)
Block(-5,3,-7,MOSSY_COBBLESTONE,50,COBBLESTONE,100)
Block(-5,3,-6,MOSSY_COBBLESTONE,50,COBBLESTONE,100)
Block(-5,3,-5,0)
Block(-5,3,-4,0)
Block(-5,3,-3,0)
Block(-5,3,-2,0)
Block(-5,3,-1,MOSSY_COBBLESTONE,50,COBBLESTONE,100)
Block(-5,3,0,STONEBRICK:3)
Block(-5,3,1,STONEBRICK:3)
Block(-5,3,2,MOSSY_COBBLESTONE,50,COBBLESTONE,100)
Block(-5,3,3,0)
Block(-5,3,4,0)
Block(-5,3,5,0)
Block(-5,3,6,0)
Block(-5,3,7,MOSSY_COBBLESTONE,50,COBBLESTONE,100)
Block(-5,3,8,MOSSY_COBBLESTONE,50,COBBLESTONE,100)
Block(-5,4,-5,0)
Block(-5,4,-4,0)
Block(-5,4,-3,0)
Block(-5,4,-2,0)
Block(-5,4,-1,118)
Block(-5,4,0,0)
Block(-5,4,1,0)
Block(-5,4,2,118)
Block(-5,4,3,0)
Block(-5,4,4,0)
Block(-5,4,5,0)
Block(-5,4,6,0)
Block(-4,0,-4,0)
Block(-4,0,-2,0)
Block(-4,0,-1,44:11)
Block(-4,0,0,0)
Block(-4,0,1,0)
Block(-4,0,2,44:11)
Block(-4,0,3,0)
Block(-4,0,5,0)
Block(-4,1,-7,MOSSY_COBBLESTONE,50,COBBLESTONE,100)
Block(-4,1,-6,MOSSY_COBBLESTONE,50,COBBLESTONE,100)
Block(-4,1,-5,67:3)
Block(-4,1,-4,0)
Block(-4,1,-3,0)
Block(-4,1,-2,0)
Block(-4,1,-1,98:3)
Block(-4,1,0,0)
Block(-4,1,1,0)
Block(-4,1,2,98:3)
Block(-4,1,3,0)
Block(-4,1,4,0)
Block(-4,1,5,0)
Block(-4,1,6,67:2)
Block(-4,1,7,MOSSY_COBBLESTONE,50,COBBLESTONE,100)
Block(-4,1,8,MOSSY_COBBLESTONE,50,COBBLESTONE,100)
Block(-4,2,-7,MOSSY_COBBLESTONE,50,COBBLESTONE,100)
Block(-4,2,-6,98:3)
Block(-4,2,-5,0)
Block(-4,2,-4,0)
Block(-4,2,-3,0)
Block(-4,2,-2,0)
Block(-4,2,-1,98:3)
Block(-4,2,0,0)
Block(-4,2,1,0)
Block(-4,2,2,98:3)
Block(-4,2,3,0)
Block(-4,2,4,0)
Block(-4,2,5,0)
Block(-4,2,6,0)
Block(-4,2,7,98:3)
Block(-4,2,8,MOSSY_COBBLESTONE,50,COBBLESTONE,100)
Block(-4,3,-7,MOSSY_COBBLESTONE,50,COBBLESTONE,100)
Block(-4,3,-6,MOSSY_COBBLESTONE,50,COBBLESTONE,100)
Block(-4,3,-5,0)
Block(-4,3,-4,0)
Block(-4,3,-3,0)
Block(-4,3,-2,0)
Block(-4,3,-1,67:1)
RandomBlock(-4,3,0,COBBLE_WALL:1,50,COBBLE_WALL,100)
RandomBlock(-4,3,1,COBBLE_WALL:1,50,COBBLE_WALL,100)
Block(-4,3,2,67:1)
Block(-4,3,3,0)
Block(-4,3,4,0)
Block(-4,3,5,0)
Block(-4,3,6,0)
Block(-4,3,7,MOSSY_COBBLESTONE,50,COBBLESTONE,100)
Block(-4,3,8,MOSSY_COBBLESTONE,50,COBBLESTONE,100)
Block(-4,4,-5,0)
Block(-4,4,-4,0)
Block(-4,4,-3,0)
Block(-4,4,-2,0)
Block(-4,4,-1,0)
Block(-4,4,0,0)
Block(-4,4,1,0)
Block(-4,4,2,0)
Block(-4,4,3,0)
Block(-4,4,4,0)
Block(-4,4,5,0)
Block(-4,4,6,0)
Block(-3,0,-4,0)
Block(-3,0,-3,0)
Block(-3,0,-2,0)
Block(-3,0,-1,0)
Block(-3,0,0,0)
Block(-3,0,1,0)
Block(-3,0,2,0)
Block(-3,0,3,0)
Block(-3,0,5,0)
Block(-3,1,-7,MOSSY_COBBLESTONE,50,COBBLESTONE,100)
Block(-3,1,-6,MOSSY_COBBLESTONE,50,COBBLESTONE,100)
Block(-3,1,-5,67:3)
Block(-3,1,-4,0)
Block(-3,1,-3,0)
Block(-3,1,-2,0)
Block(-3,1,-1,0)
Block(-3,1,0,0)
Block(-3,1,1,0)
Block(-3,1,2,0)
Block(-3,1,3,0)
Block(-3,1,4,0)
Block(-3,1,5,0)
Block(-3,1,6,67:2)
Block(-3,1,7,MOSSY_COBBLESTONE,50,COBBLESTONE,100)
Block(-3,1,8,MOSSY_COBBLESTONE,50,COBBLESTONE,100)
Block(-3,2,-7,MOSSY_COBBLESTONE,50,COBBLESTONE,100)
Block(-3,2,-6,98:3)
Block(-3,2,-5,0)
Block(-3,2,-4,0)
Block(-3,2,-3,0)
Block(-3,2,-2,0)
Block(-3,2,-1,0)
Block(-3,2,0,0)
Block(-3,2,1,0)
Block(-3,2,2,0)
Block(-3,2,3,0)
Block(-3,2,4,0)
Block(-3,2,5,0)
Block(-3,2,6,0)
Block(-3,2,7,98:3)
Block(-3,2,8,MOSSY_COBBLESTONE,50,COBBLESTONE,100)
Block(-3,3,-7,MOSSY_COBBLESTONE,50,COBBLESTONE,100)
Block(-3,3,-6,MOSSY_COBBLESTONE,50,COBBLESTONE,100)
Block(-3,3,-5,0)
Block(-3,3,-4,0)
Block(-3,3,-3,0)
Block(-3,3,-2,0)
Block(-3,3,-1,0)
RandomBlock(-3,3,0,COBBLE_WALL:1,50,COBBLE_WALL,100)
RandomBlock(-3,3,1,COBBLE_WALL:1,50,COBBLE_WALL,100)
Block(-3,3,2,0)
Block(-3,3,3,0)
Block(-3,3,4,0)
Block(-3,3,5,0)
Block(-3,3,6,0)
Block(-3,3,7,MOSSY_COBBLESTONE,50,COBBLESTONE,100)
Block(-3,3,8,MOSSY_COBBLESTONE,50,COBBLESTONE,100)
Block(-3,4,-5,0)
Block(-3,4,-4,0)
Block(-3,4,-3,0)
Block(-3,4,-2,0)
Block(-3,4,-1,0)
Block(-3,4,0,0)
Block(-3,4,1,0)
Block(-3,4,2,0)
Block(-3,4,3,0)
Block(-3,4,4,0)
Block(-3,4,5,0)
Block(-3,4,6,0)
Block(-2,0,-3,44:11)
Block(-2,0,-2,0)
Block(-2,0,-1,0)
Block(-2,0,0,0)
Block(-2,0,1,0)
Block(-2,0,2,0)
Block(-2,0,3,0)
Block(-2,0,4,0)
Block(-2,1,-7,MOSSY_COBBLESTONE,50,COBBLESTONE,100)
Block(-2,1,-6,MOSSY_COBBLESTONE,50,COBBLESTONE,100)
Block(-2,1,-5,MOSSY_COBBLESTONE,50,COBBLESTONE,100)
Block(-2,1,-4,MOSSY_COBBLESTONE,50,COBBLESTONE,100)
Block(-2,1,-3,98:3)
Block(-2,1,-2,0)
Block(-2,1,0,0)
Block(-2,1,1,0)
Block(-2,1,3,0)
Block(-2,1,4,0)
Block(-2,1,5,0)
Block(-2,1,6,98:3)
Block(-2,1,7,MOSSY_COBBLESTONE,50,COBBLESTONE,100)
Block(-2,1,8,MOSSY_COBBLESTONE,50,COBBLESTONE,100)
Block(-2,2,-7,MOSSY_COBBLESTONE,50,COBBLESTONE,100)
Block(-2,2,-6,MOSSY_COBBLESTONE,50,COBBLESTONE,100)
Block(-2,2,-5,MOSSY_COBBLESTONE,50,COBBLESTONE,100)
Block(-2,2,-4,MOSSY_COBBLESTONE,50,COBBLESTONE,100)
Block(-2,2,-3,98:3)
Block(-2,2,-2,0)
Block(-2,2,-1,0)
Block(-2,2,0,0)
Block(-2,2,1,0)
Block(-2,2,2,0)
Block(-2,2,3,0)
Block(-2,2,4,0)
Block(-2,2,5,0)
Block(-2,2,6,98:3)
Block(-2,2,7,MOSSY_COBBLESTONE,50,COBBLESTONE,100)
Block(-2,2,8,MOSSY_COBBLESTONE,50,COBBLESTONE,100)
Block(-2,3,-7,MOSSY_COBBLESTONE,50,COBBLESTONE,100)
Block(-2,3,-6,MOSSY_COBBLESTONE,50,COBBLESTONE,100)
Block(-2,3,-5,MOSSY_COBBLESTONE,50,COBBLESTONE,100)
Block(-2,3,-4,MOSSY_COBBLESTONE,50,COBBLESTONE,100)
Block(-2,3,-3,67:3)
Block(-2,3,-2,0)
Block(-2,3,-1,0)
RandomBlock(-2,3,0,COBBLE_WALL:1,50,COBBLE_WALL,100)
RandomBlock(-2,3,1,COBBLE_WALL:1,50,COBBLE_WALL,100)
Block(-2,3,2,0)
Block(-2,3,3,0)
Block(-2,3,4,0)
Block(-2,3,5,67:4)
Block(-2,3,6,MOSSY_COBBLESTONE,50,COBBLESTONE,100)
Block(-2,3,7,MOSSY_COBBLESTONE,50,COBBLESTONE,100)
Block(-2,3,8,MOSSY_COBBLESTONE,50,COBBLESTONE,100)
Block(-2,4,-4,118)
Block(-2,4,-3,0)
Block(-2,4,-2,0)
Block(-2,4,-1,0)
Block(-2,4,0,0)
Block(-2,4,1,0)
Block(-2,4,2,0)
Block(-2,4,3,0)
Block(-2,4,4,0)
Block(-2,4,5,0)
Block(-1,0,-4,44:13)
Block(-1,0,-3,0)
Block(-1,0,-2,0)
Block(-1,0,-1,0)
Block(-1,0,0,0)
Block(-1,0,1,0)
Block(-1,0,2,0)
Block(-1,0,3,0)
Block(-1,0,5,0)
Block(-1,1,-7,MOSSY_COBBLESTONE,50,COBBLESTONE,100)
Block(-1,1,-6,MOSSY_COBBLESTONE,50,COBBLESTONE,100)
Block(-1,1,-5,MOSSY_COBBLESTONE,50,COBBLESTONE,100)
Block(-1,1,-4,67:3)
Block(-1,1,-3,0)
Block(-1,1,-2,0)
Block(-1,1,0,0)
Block(-1,1,1,0)
Block(-1,1,3,0)
Block(-1,1,4,0)
Block(-1,1,5,0)
Block(-1,1,6,67:2)
Block(-1,1,7,MOSSY_COBBLESTONE,50,COBBLESTONE,100)
Block(-1,1,8,MOSSY_COBBLESTONE,50,COBBLESTONE,100)
Block(-1,2,-7,MOSSY_COBBLESTONE,50,COBBLESTONE,100)
Block(-1,2,-6,MOSSY_COBBLESTONE,50,COBBLESTONE,100)
Block(-1,2,-5,MOSSY_COBBLESTONE,50,COBBLESTONE,100)
Block(-1,2,-4,0)
Block(-1,2,-3,0)
Block(-1,2,-2,0)
Block(-1,2,-1,0)
Block(-1,2,0,67:6)
Block(-1,2,1,67:7)
Block(-1,2,2,0)
Block(-1,2,3,0)
Block(-1,2,4,0)
Block(-1,2,5,0)
Block(-1,2,6,0)
Block(-1,2,7,MOSSY_COBBLESTONE,50,COBBLESTONE,100)
Block(-1,2,8,MOSSY_COBBLESTONE,50,COBBLESTONE,100)
RandomBlock(-1,3,-7,STONEBRICK:1,50,STONEBRICK:2,100)
RandomBlock(-1,3,-6,STONEBRICK:1,50,STONEBRICK:2,100)
RandomBlock(-1,3,-5,STONEBRICK:1,50,STONEBRICK:2,100)
Block(-1,3,-4,STONEBRICK:3)
RandomBlock(-1,3,-3,COBBLE_WALL:1,50,COBBLE_WALL,100)
RandomBlock(-1,3,-2,COBBLE_WALL:1,50,COBBLE_WALL,100)
RandomBlock(-1,3,-1,COBBLE_WALL:1,50,COBBLE_WALL,100)
Block(-1,3,0,STONEBRICK:3)
Block(-1,3,1,STONEBRICK:3)
Block(-1,3,3,0)
Block(-1,3,4,0)
Block(-1,3,5,67:6)
RandomBlock(-1,3,6,STONEBRICK:1,50,STONEBRICK:2,100)
RandomBlock(-1,3,7,STONEBRICK:1,50,STONEBRICK:2,100)
RandomBlock(-1,3,8,STONEBRICK:1,50,STONEBRICK:2,100)
Block(-1,4,-4,0)
Block(-1,4,-3,0)
Block(-1,4,-2,0)
Block(-1,4,-1,0)
Block(-1,4,0,AIR)
Block(-1,4,1,AIR)
Block(-1,4,2,0)
Block(-1,4,3,0)
Block(-1,4,4,0)
Block(-1,4,5,0)
Block(0,0,-4,44:13)
Block(0,0,-3,0)
Block(0,0,-2,0)
Block(0,0,-1,0)
Block(0,0,0,0)
Block(0,0,1,0)
Block(0,0,2,0)
Block(0,0,3,0)
Block(0,0,5,0)
Block(0,1,-7,MOSSY_COBBLESTONE,50,COBBLESTONE,100)
Block(0,1,-6,MOSSY_COBBLESTONE,50,COBBLESTONE,100)
Block(0,1,-5,MOSSY_COBBLESTONE,50,COBBLESTONE,100)
Block(0,1,-4,67:3)
Block(0,1,-3,0)
Block(0,1,-2,0)
Block(0,1,0,0)
Block(0,1,1,0)
Block(0,1,3,0)
Block(0,1,4,0)
Block(0,1,5,0)
Block(0,1,6,67:2)
Block(0,1,7,MOSSY_COBBLESTONE,50,COBBLESTONE,100)
Block(0,1,8,MOSSY_COBBLESTONE,50,COBBLESTONE,100)
Block(0,2,-7,MOSSY_COBBLESTONE,50,COBBLESTONE,100)
Block(0,2,-6,MOSSY_COBBLESTONE,50,COBBLESTONE,100)
Block(0,2,-5,MOSSY_COBBLESTONE,50,COBBLESTONE,100)
Block(0,2,-4,0)
Block(0,2,-3,0)
Block(0,2,-2,0)
Block(0,2,-1,0)
Block(0,2,0,67:6)
Block(0,2,1,67:7)
Block(0,2,2,0)
Block(0,2,3,0)
Block(0,2,4,0)
Block(0,2,5,0)
Block(0,2,6,0)
Block(0,2,7,MOSSY_COBBLESTONE,50,COBBLESTONE,100)
Block(0,2,8,MOSSY_COBBLESTONE,50,COBBLESTONE,100)
RandomBlock(0,3,-7,STONEBRICK:1,50,STONEBRICK:2,100)
RandomBlock(0,3,-6,STONEBRICK:1,50,STONEBRICK:2,100)
RandomBlock(0,3,-5,STONEBRICK:1,50,STONEBRICK:2,100)
Block(0,3,-4,STONEBRICK:3)
RandomBlock(0,3,-3,COBBLE_WALL:1,50,COBBLE_WALL,100)
RandomBlock(0,3,-2,COBBLE_WALL:1,50,COBBLE_WALL,100)
RandomBlock(0,3,-1,COBBLE_WALL:1,50,COBBLE_WALL,100)
Block(0,3,0,STONEBRICK:3)
Block(0,3,1,STONEBRICK:3)
Block(0,3,3,0)
Block(0,3,4,0)
Block(0,3,5,67:6)
RandomBlock(0,3,6,STONEBRICK:1,50,STONEBRICK:2,100)
RandomBlock(0,3,7,STONEBRICK:1,50,STONEBRICK:2,100)
RandomBlock(0,3,8,STONEBRICK:1,50,STONEBRICK:2,100)
Block(0,4,-4,0)
Block(0,4,-3,0)
Block(0,4,-2,0)
Block(0,4,-1,0)
Block(0,4,0,AIR)
Block(0,4,1,AIR)
Block(0,4,2,0)
Block(0,4,3,0)
Block(0,4,4,0)
Block(0,4,5,0)
Block(1,0,-3,44:11)
Block(1,0,-2,0)
Block(1,0,-1,0)
Block(1,0,0,0)
Block(1,0,1,0)
Block(1,0,2,0)
Block(1,0,3,0)
Block(1,0,4,0)
Block(1,1,-7,MOSSY_COBBLESTONE,50,COBBLESTONE,100)
Block(1,1,-6,MOSSY_COBBLESTONE,50,COBBLESTONE,100)
Block(1,1,-5,MOSSY_COBBLESTONE,50,COBBLESTONE,100)
Block(1,1,-4,MOSSY_COBBLESTONE,50,COBBLESTONE,100)
Block(1,1,-3,98:3)
Block(1,1,-2,0)
Block(1,1,0,0)
Block(1,1,1,0)
Block(1,1,3,0)
Block(1,1,4,0)
Block(1,1,5,0)
Block(1,1,6,98:3)
Block(1,1,7,MOSSY_COBBLESTONE,50,COBBLESTONE,100)
Block(1,1,8,MOSSY_COBBLESTONE,50,COBBLESTONE,100)
Block(1,2,-7,MOSSY_COBBLESTONE,50,COBBLESTONE,100)
Block(1,2,-6,MOSSY_COBBLESTONE,50,COBBLESTONE,100)
Block(1,2,-5,MOSSY_COBBLESTONE,50,COBBLESTONE,100)
Block(1,2,-4,MOSSY_COBBLESTONE,50,COBBLESTONE,100)
Block(1,2,-3,98:3)
Block(1,2,-2,0)
Block(1,2,-1,0)
Block(1,2,0,0)
Block(1,2,1,0)
Block(1,2,2,0)
Block(1,2,3,0)
Block(1,2,4,0)
Block(1,2,5,0)
Block(1,2,6,98:3)
Block(1,2,7,MOSSY_COBBLESTONE,50,COBBLESTONE,100)
Block(1,2,8,MOSSY_COBBLESTONE,50,COBBLESTONE,100)
Block(1,3,-7,MOSSY_COBBLESTONE,50,COBBLESTONE,100)
Block(1,3,-6,MOSSY_COBBLESTONE,50,COBBLESTONE,100)
Block(1,3,-5,MOSSY_COBBLESTONE,50,COBBLESTONE,100)
Block(1,3,-4,MOSSY_COBBLESTONE,50,COBBLESTONE,100)
Block(1,3,-3,67:3)
Block(1,3,-2,0)
Block(1,3,-1,0)
RandomBlock(1,3,0,COBBLE_WALL:1,50,COBBLE_WALL,100)
RandomBlock(1,3,1,COBBLE_WALL:1,50,COBBLE_WALL,100)
Block(1,3,2,0)
Block(1,3,3,0)
Block(1,3,4,0)
Block(1,3,5,67:5)
Block(1,3,6,MOSSY_COBBLESTONE,50,COBBLESTONE,100)
Block(1,3,7,MOSSY_COBBLESTONE,50,COBBLESTONE,100)
Block(1,3,8,MOSSY_COBBLESTONE,50,COBBLESTONE,100)
Block(1,4,-4,118)
Block(1,4,-3,0)
Block(1,4,-2,0)
Block(1,4,-1,0)
Block(1,4,0,0)
Block(1,4,1,0)
Block(1,4,2,0)
Block(1,4,3,0)
Block(1,4,4,0)
Block(1,4,5,0)
Block(2,0,-4,0)
Block(2,0,-3,0)
Block(2,0,-2,0)
Block(2,0,-1,0)
Block(2,0,0,0)
Block(2,0,1,0)
Block(2,0,2,0)
Block(2,0,3,0)
Block(2,0,5,0)
Block(2,1,-7,MOSSY_COBBLESTONE,50,COBBLESTONE,100)
Block(2,1,-6,MOSSY_COBBLESTONE,50,COBBLESTONE,100)
Block(2,1,-5,67:3)
Block(2,1,-4,0)
Block(2,1,-3,0)
Block(2,1,-2,0)
Block(2,1,-1,0)
Block(2,1,0,0)
Block(2,1,1,0)
Block(2,1,2,0)
Block(2,1,3,0)
Block(2,1,4,0)
Block(2,1,5,0)
Block(2,1,6,67:2)
Block(2,1,7,MOSSY_COBBLESTONE,50,COBBLESTONE,100)
Block(2,1,8,MOSSY_COBBLESTONE,50,COBBLESTONE,100)
Block(2,2,-7,MOSSY_COBBLESTONE,50,COBBLESTONE,100)
Block(2,2,-6,98:3)
Block(2,2,-5,0)
Block(2,2,-4,0)
Block(2,2,-3,0)
Block(2,2,-2,0)
Block(2,2,-1,0)
Block(2,2,0,0)
Block(2,2,1,0)
Block(2,2,2,0)
Block(2,2,3,0)
Block(2,2,4,0)
Block(2,2,5,0)
Block(2,2,6,0)
Block(2,2,7,98:3)
Block(2,2,8,MOSSY_COBBLESTONE,50,COBBLESTONE,100)
Block(2,3,-7,MOSSY_COBBLESTONE,50,COBBLESTONE,100)
Block(2,3,-6,MOSSY_COBBLESTONE,50,COBBLESTONE,100)
Block(2,3,-5,0)
Block(2,3,-4,0)
Block(2,3,-3,0)
Block(2,3,-2,0)
Block(2,3,-1,0)
RandomBlock(2,3,0,COBBLE_WALL:1,50,COBBLE_WALL,100)
RandomBlock(2,3,1,COBBLE_WALL:1,50,COBBLE_WALL,100)
Block(2,3,2,0)
Block(2,3,3,0)
Block(2,3,4,0)
Block(2,3,5,0)
Block(2,3,6,0)
Block(2,3,7,MOSSY_COBBLESTONE,50,COBBLESTONE,100)
Block(2,3,8,MOSSY_COBBLESTONE,50,COBBLESTONE,100)
Block(2,4,-5,0)
Block(2,4,-4,0)
Block(2,4,-3,0)
Block(2,4,-2,0)
Block(2,4,-1,0)
Block(2,4,0,0)
Block(2,4,1,0)
Block(2,4,2,0)
Block(2,4,3,0)
Block(2,4,4,0)
Block(2,4,5,0)
Block(2,4,6,0)
Block(3,0,-4,0)
Block(3,0,-2,0)
Block(3,0,-1,44:11)
Block(3,0,0,0)
Block(3,0,1,0)
Block(3,0,2,44:11)
Block(3,0,3,0)
Block(3,0,5,0)
Block(3,1,-7,MOSSY_COBBLESTONE,50,COBBLESTONE,100)
Block(3,1,-6,MOSSY_COBBLESTONE,50,COBBLESTONE,100)
Block(3,1,-5,67:3)
Block(3,1,-4,0)
Block(3,1,-3,0)
Block(3,1,-2,0)
Block(3,1,-1,98:3)
Block(3,1,0,0)
Block(3,1,1,0)
Block(3,1,2,98:3)
Block(3,1,3,0)
Block(3,1,4,0)
Block(3,1,5,0)
Block(3,1,6,67:2)
Block(3,1,7,MOSSY_COBBLESTONE,50,COBBLESTONE,100)
Block(3,1,8,MOSSY_COBBLESTONE,50,COBBLESTONE,100)
Block(3,2,-7,MOSSY_COBBLESTONE,50,COBBLESTONE,100)
Block(3,2,-6,98:3)
Block(3,2,-5,0)
Block(3,2,-4,0)
Block(3,2,-3,0)
Block(3,2,-2,0)
Block(3,2,-1,98:3)
Block(3,2,0,0)
Block(3,2,1,0)
Block(3,2,2,98:3)
Block(3,2,3,0)
Block(3,2,4,0)
Block(3,2,5,0)
Block(3,2,6,0)
Block(3,2,7,98:3)
Block(3,2,8,MOSSY_COBBLESTONE,50,COBBLESTONE,100)
Block(3,3,-7,MOSSY_COBBLESTONE,50,COBBLESTONE,100)
Block(3,3,-6,MOSSY_COBBLESTONE,50,COBBLESTONE,100)
Block(3,3,-5,0)
Block(3,3,-4,0)
Block(3,3,-3,0)
Block(3,3,-2,0)
Block(3,3,-1,67)
RandomBlock(3,3,0,COBBLE_WALL:1,50,COBBLE_WALL,100)
RandomBlock(3,3,1,COBBLE_WALL:1,50,COBBLE_WALL,100)
Block(3,3,2,67)
Block(3,3,3,0)
Block(3,3,4,0)
Block(3,3,5,0)
Block(3,3,6,0)
Block(3,3,7,MOSSY_COBBLESTONE,50,COBBLESTONE,100)
Block(3,3,8,MOSSY_COBBLESTONE,50,COBBLESTONE,100)
Block(3,4,-5,0)
Block(3,4,-4,0)
Block(3,4,-3,0)
Block(3,4,-2,0)
Block(3,4,-1,0)
Block(3,4,0,0)
Block(3,4,1,0)
Block(3,4,2,0)
Block(3,4,3,0)
Block(3,4,4,0)
Block(3,4,5,0)
Block(3,4,6,0)
Block(4,0,-4,0)
Block(4,0,-3,0)
Block(4,0,-2,0)
Block(4,0,0,44:13)
Block(4,0,1,44:13)
Block(4,0,3,0)
Block(4,0,4,0)
Block(4,0,5,0)
Block(4,1,-7,MOSSY_COBBLESTONE,50,COBBLESTONE,100)
Block(4,1,-6,MOSSY_COBBLESTONE,50,COBBLESTONE,100)
Block(4,1,-5,67:3)
Block(4,1,-4,0)
Block(4,1,-3,0)
Block(4,1,-2,0)
Block(4,1,-1,MOSSY_COBBLESTONE,50,COBBLESTONE,100)
Block(4,1,0,67)
Block(4,1,1,67)
Block(4,1,2,MOSSY_COBBLESTONE,50,COBBLESTONE,100)
Block(4,1,3,0)
Block(4,1,4,0)
Block(4,1,5,0)
Block(4,1,6,67:2)
Block(4,1,7,MOSSY_COBBLESTONE,50,COBBLESTONE,100)
Block(4,1,8,MOSSY_COBBLESTONE,50,COBBLESTONE,100)
Block(4,2,-7,MOSSY_COBBLESTONE,50,COBBLESTONE,100)
Block(4,2,-6,98:3)
Block(4,2,-5,0)
Block(4,2,-4,0)
Block(4,2,-3,0)
Block(4,2,-2,0)
Block(4,2,-1,MOSSY_COBBLESTONE,50,COBBLESTONE,100)
Block(4,2,0,0)
Block(4,2,1,0)
Block(4,2,2,MOSSY_COBBLESTONE,50,COBBLESTONE,100)
Block(4,2,3,0)
Block(4,2,4,0)
Block(4,2,5,0)
Block(4,2,6,0)
Block(4,2,7,98:3)
Block(4,2,8,MOSSY_COBBLESTONE,50,COBBLESTONE,100)
Block(4,3,-7,MOSSY_COBBLESTONE,50,COBBLESTONE,100)
Block(4,3,-6,MOSSY_COBBLESTONE,50,COBBLESTONE,100)
Block(4,3,-5,0)
Block(4,3,-4,0)
Block(4,3,-3,0)
Block(4,3,-2,0)
Block(4,3,-1,MOSSY_COBBLESTONE,50,COBBLESTONE,100)
Block(4,3,0,STONEBRICK:3)
Block(4,3,1,STONEBRICK:3)
Block(4,3,2,MOSSY_COBBLESTONE,50,COBBLESTONE,100)
Block(4,3,3,0)
Block(4,3,4,0)
Block(4,3,5,0)
Block(4,3,6,0)
Block(4,3,7,MOSSY_COBBLESTONE,50,COBBLESTONE,100)
Block(4,3,8,MOSSY_COBBLESTONE,50,COBBLESTONE,100)
Block(4,4,-5,0)
Block(4,4,-4,0)
Block(4,4,-3,0)
Block(4,4,-2,0)
Block(4,4,-1,118)
Block(4,4,0,0)
Block(4,4,1,0)
Block(4,4,2,118)
Block(4,4,3,0)
Block(4,4,4,0)
Block(4,4,5,0)
Block(4,4,6,0)
Block(5,1,-7,MOSSY_COBBLESTONE,50,COBBLESTONE,100)
Block(5,1,-6,MOSSY_COBBLESTONE,50,COBBLESTONE,100)
Block(5,1,-5,67)
Block(5,1,-4,67)
Block(5,1,-3,67)
Block(5,1,-2,67)
Block(5,1,-1,MOSSY_COBBLESTONE,50,COBBLESTONE,100)
Block(5,1,0,MOSSY_COBBLESTONE,50,COBBLESTONE,100)
Block(5,1,1,MOSSY_COBBLESTONE,50,COBBLESTONE,100)
Block(5,1,2,MOSSY_COBBLESTONE,50,COBBLESTONE,100)
Block(5,1,3,67)
Block(5,1,4,67)
Block(5,1,5,67)
Block(5,1,6,67:2)
Block(5,1,7,MOSSY_COBBLESTONE,50,COBBLESTONE,100)
Block(5,1,8,MOSSY_COBBLESTONE,50,COBBLESTONE,100)
Block(5,2,-7,MOSSY_COBBLESTONE,50,COBBLESTONE,100)
Block(5,2,-6,98:3)
Block(5,2,-5,0)
Block(5,2,-4,0)
Block(5,2,-3,0)
Block(5,2,-2,0)
Block(5,2,-1,MOSSY_COBBLESTONE,50,COBBLESTONE,100)
Block(5,2,0,MOSSY_COBBLESTONE,50,COBBLESTONE,100)
Block(5,2,1,MOSSY_COBBLESTONE,50,COBBLESTONE,100)
Block(5,2,2,MOSSY_COBBLESTONE,50,COBBLESTONE,100)
Block(5,2,3,0)
Block(5,2,4,0)
Block(5,2,5,0)
Block(5,2,6,0)
Block(5,2,7,98:3)
Block(5,2,8,MOSSY_COBBLESTONE,50,COBBLESTONE,100)
Block(5,3,-7,MOSSY_COBBLESTONE,50,COBBLESTONE,100)
Block(5,3,-6,MOSSY_COBBLESTONE,50,COBBLESTONE,100)
Block(5,3,-5,0)
Block(5,3,-4,0)
Block(5,3,-3,0)
Block(5,3,-2,0)
Block(5,3,-1,MOSSY_COBBLESTONE,50,COBBLESTONE,100)
RandomBlock(5,3,0,STONEBRICK:1,50,STONEBRICK:2,100)
RandomBlock(5,3,1,STONEBRICK:1,50,STONEBRICK:2,100)
Block(5,3,2,MOSSY_COBBLESTONE,50,COBBLESTONE,100)
Block(5,3,3,0)
Block(5,3,4,0)
Block(5,3,5,0)
Block(5,3,6,0)
Block(5,3,7,MOSSY_COBBLESTONE,50,COBBLESTONE,100)
Block(5,3,8,MOSSY_COBBLESTONE,50,COBBLESTONE,100)
Block(5,4,-5,0)
Block(5,4,-4,0)
Block(5,4,-3,0)
Block(5,4,-2,0)
Block(5,4,3,0)
Block(5,4,4,0)
Block(5,4,5,0)
Block(5,4,6,0)
Block(6,1,-7,MOSSY_COBBLESTONE,50,COBBLESTONE,100)
Block(6,1,-6,MOSSY_COBBLESTONE,50,COBBLESTONE,100)
Block(6,1,-5,MOSSY_COBBLESTONE,50,COBBLESTONE,100)
Block(6,1,-4,MOSSY_COBBLESTONE,50,COBBLESTONE,100)
Block(6,1,-3,MOSSY_COBBLESTONE,50,COBBLESTONE,100)
Block(6,1,-2,MOSSY_COBBLESTONE,50,COBBLESTONE,100)
Block(6,1,-1,MOSSY_COBBLESTONE,50,COBBLESTONE,100)
Block(6,1,0,MOSSY_COBBLESTONE,50,COBBLESTONE,100)
Block(6,1,1,MOSSY_COBBLESTONE,50,COBBLESTONE,100)
Block(6,1,2,MOSSY_COBBLESTONE,50,COBBLESTONE,100)
Block(6,1,3,MOSSY_COBBLESTONE,50,COBBLESTONE,100)
Block(6,1,4,MOSSY_COBBLESTONE,50,COBBLESTONE,100)
Block(6,1,5,MOSSY_COBBLESTONE,50,COBBLESTONE,100)
Block(6,1,6,MOSSY_COBBLESTONE,50,COBBLESTONE,100)
Block(6,1,7,MOSSY_COBBLESTONE,50,COBBLESTONE,100)
Block(6,1,8,MOSSY_COBBLESTONE,50,COBBLESTONE,100)
Block(6,2,-7,MOSSY_COBBLESTONE,50,COBBLESTONE,100)
Block(6,2,-6,MOSSY_COBBLESTONE,50,COBBLESTONE,100)
Block(6,2,-5,98:3)
Block(6,2,-4,98:3)
Block(6,2,-3,98:3)
Block(6,2,-2,98:3)
Block(6,2,-1,MOSSY_COBBLESTONE,50,COBBLESTONE,100)
Block(6,2,0,MOSSY_COBBLESTONE,50,COBBLESTONE,100)
Block(6,2,1,MOSSY_COBBLESTONE,50,COBBLESTONE,100)
Block(6,2,2,MOSSY_COBBLESTONE,50,COBBLESTONE,100)
Block(6,2,3,98:3)
Block(6,2,4,98:3)
Block(6,2,5,98:3)
Block(6,2,6,98:3)
Block(6,2,7,MOSSY_COBBLESTONE,50,COBBLESTONE,100)
Block(6,2,8,MOSSY_COBBLESTONE,50,COBBLESTONE,100)
Block(6,3,-7,MOSSY_COBBLESTONE,50,COBBLESTONE,100)
Block(6,3,-6,MOSSY_COBBLESTONE,50,COBBLESTONE,100)
Block(6,3,-5,MOSSY_COBBLESTONE,50,COBBLESTONE,100)
Block(6,3,-4,MOSSY_COBBLESTONE,50,COBBLESTONE,100)
Block(6,3,-3,MOSSY_COBBLESTONE,50,COBBLESTONE,100)
Block(6,3,-2,MOSSY_COBBLESTONE,50,COBBLESTONE,100)
Block(6,3,-1,MOSSY_COBBLESTONE,50,COBBLESTONE,100)
RandomBlock(6,3,0,STONEBRICK:1,50,STONEBRICK:2,100)
RandomBlock(6,3,1,STONEBRICK:1,50,STONEBRICK:2,100)
Block(6,3,2,MOSSY_COBBLESTONE,50,COBBLESTONE,100)
Block(6,3,3,MOSSY_COBBLESTONE,50,COBBLESTONE,100)
Block(6,3,4,MOSSY_COBBLESTONE,50,COBBLESTONE,100)
Block(6,3,5,MOSSY_COBBLESTONE,50,COBBLESTONE,100)
Block(6,3,6,MOSSY_COBBLESTONE,50,COBBLESTONE,100)
Block(6,3,7,MOSSY_COBBLESTONE,50,COBBLESTONE,100)
Block(6,3,8,MOSSY_COBBLESTONE,50,COBBLESTONE,100)
Block(7,1,-7,MOSSY_COBBLESTONE,50,COBBLESTONE,100)
Block(7,1,-6,MOSSY_COBBLESTONE,50,COBBLESTONE,100)
Block(7,1,-5,MOSSY_COBBLESTONE,50,COBBLESTONE,100)
Block(7,1,-4,MOSSY_COBBLESTONE,50,COBBLESTONE,100)
Block(7,1,-3,MOSSY_COBBLESTONE,50,COBBLESTONE,100)
Block(7,1,-2,MOSSY_COBBLESTONE,50,COBBLESTONE,100)
Block(7,1,-1,MOSSY_COBBLESTONE,50,COBBLESTONE,100)
Block(7,1,0,MOSSY_COBBLESTONE,50,COBBLESTONE,100)
Block(7,1,1,MOSSY_COBBLESTONE,50,COBBLESTONE,100)
Block(7,1,2,MOSSY_COBBLESTONE,50,COBBLESTONE,100)
Block(7,1,3,MOSSY_COBBLESTONE,50,COBBLESTONE,100)
Block(7,1,4,MOSSY_COBBLESTONE,50,COBBLESTONE,100)
Block(7,1,5,MOSSY_COBBLESTONE,50,COBBLESTONE,100)
Block(7,1,6,MOSSY_COBBLESTONE,50,COBBLESTONE,100)
Block(7,1,7,MOSSY_COBBLESTONE,50,COBBLESTONE,100)
Block(7,1,8,MOSSY_COBBLESTONE,50,COBBLESTONE,100)
Block(7,2,-7,MOSSY_COBBLESTONE,50,COBBLESTONE,100)
Block(7,2,-6,MOSSY_COBBLESTONE,50,COBBLESTONE,100)
Block(7,2,-5,MOSSY_COBBLESTONE,50,COBBLESTONE,100)
Block(7,2,-4,MOSSY_COBBLESTONE,50,COBBLESTONE,100)
Block(7,2,-3,MOSSY_COBBLESTONE,50,COBBLESTONE,100)
Block(7,2,-2,MOSSY_COBBLESTONE,50,COBBLESTONE,100)
Block(7,2,-1,MOSSY_COBBLESTONE,50,COBBLESTONE,100)
Block(7,2,0,MOSSY_COBBLESTONE,50,COBBLESTONE,100)
Block(7,2,1,MOSSY_COBBLESTONE,50,COBBLESTONE,100)
Block(7,2,2,MOSSY_COBBLESTONE,50,COBBLESTONE,100)
Block(7,2,3,MOSSY_COBBLESTONE,50,COBBLESTONE,100)
Block(7,2,4,MOSSY_COBBLESTONE,50,COBBLESTONE,100)
Block(7,2,5,MOSSY_COBBLESTONE,50,COBBLESTONE,100)
Block(7,2,6,MOSSY_COBBLESTONE,50,COBBLESTONE,100)
Block(7,2,7,MOSSY_COBBLESTONE,50,COBBLESTONE,100)
Block(7,2,8,MOSSY_COBBLESTONE,50,COBBLESTONE,100)
Block(7,3,-7,MOSSY_COBBLESTONE,50,COBBLESTONE,100)
Block(7,3,-6,MOSSY_COBBLESTONE,50,COBBLESTONE,100)
Block(7,3,-5,MOSSY_COBBLESTONE,50,COBBLESTONE,100)
Block(7,3,-4,MOSSY_COBBLESTONE,50,COBBLESTONE,100)
Block(7,3,-3,MOSSY_COBBLESTONE,50,COBBLESTONE,100)
Block(7,3,-2,MOSSY_COBBLESTONE,50,COBBLESTONE,100)
Block(7,3,-1,MOSSY_COBBLESTONE,50,COBBLESTONE,100)
RandomBlock(7,3,0,STONEBRICK:1,50,STONEBRICK:2,100)
RandomBlock(7,3,1,STONEBRICK:1,50,STONEBRICK:2,100)
Block(7,3,2,MOSSY_COBBLESTONE,50,COBBLESTONE,100)
Block(7,3,3,MOSSY_COBBLESTONE,50,COBBLESTONE,100)
Block(7,3,4,MOSSY_COBBLESTONE,50,COBBLESTONE,100)
Block(7,3,5,MOSSY_COBBLESTONE,50,COBBLESTONE,100)
Block(7,3,6,MOSSY_COBBLESTONE,50,COBBLESTONE,100)
Block(7,3,7,MOSSY_COBBLESTONE,50,COBBLESTONE,100)
Block(7,3,8,MOSSY_COBBLESTONE,50,COBBLESTONE,100)

Block(0,3,2,REDSTONE_TORCH:3)
Block(-1,3,2,REDSTONE_TORCH:3)
