IsOTGPlus:true

Author: PG85

Description: No description given

Version: MCW104

SettingsMode: WriteDisable

Tree: false

Frequency: 1

RotateRandomly: false

SpawnHeight: highestBlock

MinHeight: 0

MaxHeight: 256

ExcludedBiomes: All

SourceBlocks: AIR

MaxPercentageOutsideSourceBlock: 100

OutsideSourceBlock: placeAnyway

InheritBO3: 

OverrideChildSettings: true

CanOverride: true

MustBeBelowOther: false

CannotBeInside: we-jungletempledungeon16x16x81exitNoRoof, we-jungletempledungeon16x16x82exitscornerNoRoof, we-jungletempledungeon16x16x82exitsoppositeNoRoof, we-jungletempledungeon16x16x83exitsNoRoof, we-jungletempledungeon16x16x84exitsNoRoof

CanSpawnOnWater: true

SpawnOnWaterOnly: false

SpawnUnderWater: false

SpawnAtWaterLevel: false

HeightOffset: 0

RemoveAir: true

ReplaceAbove: NONE

ReplaceBelow: 

ReplaceWithBiomeBlocks: true

ReplaceWithGroundBlock: DIRT

ReplaceWithSurfaceBlock: GRASS

SmoothRadius: -1

SmoothHeightOffset: 0

SmoothStartTop: false

SmoothStartWood: false

SmoothingSurfaceBlock: 

SmoothingGroundBlock: 

BO3Group: 

IsSpawnPoint: false

SpawnPointX: 8

SpawnPointY: -1

SpawnPointZ: 7

Block(-5,1,-3,BOOKSHELF)
Block(-5,1,-2,BOOKSHELF)
Block(-5,1,-1,COBBLE_WALL:1,50,COBBLE_WALL,100)
Block(-5,1,2,COBBLE_WALL:1,50,COBBLE_WALL,100)
Block(-5,1,3,BOOKSHELF)
Block(-5,1,4,BOOKSHELF)
Block(-5,2,-3,BOOKSHELF)
Block(-5,2,-2,BOOKSHELF)
Block(-5,2,-1,COBBLE_WALL:1,50,COBBLE_WALL,100)
Block(-5,2,2,COBBLE_WALL:1,50,COBBLE_WALL,100)
Block(-5,2,3,BOOKSHELF)
Block(-5,2,4,BOOKSHELF)
Block(-5,3,-3,BOOKSHELF)
Block(-5,3,-2,BOOKSHELF)
Block(-5,3,-1,COBBLE_WALL:1,50,COBBLE_WALL,100)
Block(-5,3,2,COBBLE_WALL:1,50,COBBLE_WALL,100)
Block(-5,3,3,BOOKSHELF)
Block(-5,3,4,BOOKSHELF)
Block(-5,4,-3,STEP)
Block(-5,4,-2,STEP)
Block(-5,4,-1,STEP)
Block(-5,4,0,STEP)
Block(-5,4,1,STEP)
Block(-5,4,2,STEP)
Block(-5,4,3,STEP)
Block(-5,4,4,STEP)
Block(-4,1,-4,BOOKSHELF)
Block(-4,1,5,BOOKSHELF)
Block(-4,2,-4,BOOKSHELF)
Block(-4,2,5,BOOKSHELF)
Block(-4,3,-4,BOOKSHELF)
Block(-4,3,5,BOOKSHELF)
Block(-4,4,-4,STEP)
Block(-4,4,5,STEP)
Block(-3,1,-4,BOOKSHELF)
Block(-3,1,-2,COBBLE_WALL:1,50,COBBLE_WALL,100)
Block(-3,1,0,CARPET:14)
Block(-3,1,1,CARPET:14)
Block(-3,1,3,COBBLE_WALL:1,50,COBBLE_WALL,100)
Block(-3,1,5,BOOKSHELF)
Block(-3,2,-4,BOOKSHELF)
Block(-3,2,5,BOOKSHELF)
Block(-3,3,-4,BOOKSHELF)
Block(-3,3,5,BOOKSHELF)
Block(-3,4,-4,STEP)
Block(-3,4,5,STEP)
Block(-2,1,-4,COBBLE_WALL:1,50,COBBLE_WALL,100)
Block(-2,1,-1,CARPET:14)
Block(-2,1,0,CARPET:14)
Block(-2,1,1,CARPET:14)
Block(-2,1,2,CARPET:14)
Block(-2,1,5,COBBLE_WALL:1,50,COBBLE_WALL,100)
Block(-2,2,-4,COBBLE_WALL:1,50,COBBLE_WALL,100)
Block(-2,2,5,COBBLE_WALL:1,50,COBBLE_WALL,100)
Block(-2,3,-4,COBBLE_WALL:1,50,COBBLE_WALL,100)
Block(-2,3,5,COBBLE_WALL:1,50,COBBLE_WALL,100)
Block(-2,4,-4,STEP)
Block(-2,4,5,STEP)
Block(-1,1,-2,CARPET:14)
Block(-1,1,-1,CARPET:14)
Block(-1,1,0,CARPET:14)
Block(-1,1,1,CARPET:14)
Block(-1,1,2,CARPET:14)
Block(-1,1,3,CARPET:14)
Block(-1,4,-4,STEP)
Block(-1,4,5,STEP)
Block(0,1,-2,CARPET:14)
Block(0,1,-1,CARPET:14)
Block(0,1,0,CARPET:14)
Block(0,1,1,CARPET:14)
Block(0,1,2,CARPET:14)
Block(0,1,3,CARPET:14)
Block(0,4,-4,STEP)
Block(0,4,5,STEP)
Block(1,1,-4,COBBLE_WALL:1,50,COBBLE_WALL,100)
Block(1,1,-1,CARPET:14)
Block(1,1,0,CARPET:14)
Block(1,1,1,CARPET:14)
Block(1,1,2,CARPET:14)
Block(1,1,5,COBBLE_WALL:1,50,COBBLE_WALL,100)
Block(1,2,-4,COBBLE_WALL:1,50,COBBLE_WALL,100)
Block(1,2,5,COBBLE_WALL:1,50,COBBLE_WALL,100)
Block(1,3,-4,COBBLE_WALL:1,50,COBBLE_WALL,100)
Block(1,3,5,COBBLE_WALL:1,50,COBBLE_WALL,100)
Block(1,4,-4,STEP)
Block(1,4,5,STEP)
Block(2,1,-4,BOOKSHELF)
Block(2,1,-2,COBBLE_WALL:1,50,COBBLE_WALL,100)
Block(2,1,0,CARPET:14)
Block(2,1,1,CARPET:14)
Block(2,1,3,COBBLE_WALL:1,50,COBBLE_WALL,100)
Block(2,1,5,BOOKSHELF)
Block(2,2,-4,BOOKSHELF)
Block(2,2,5,BOOKSHELF)
Block(2,3,-4,BOOKSHELF)
Block(2,3,5,BOOKSHELF)
Block(2,4,-4,STEP)
Block(2,4,5,STEP)
Block(3,1,-4,BOOKSHELF)
Block(3,1,5,BOOKSHELF)
Block(3,2,-4,BOOKSHELF)
Block(3,2,5,BOOKSHELF)
Block(3,3,-4,BOOKSHELF)
Block(3,3,5,BOOKSHELF)
Block(3,4,-4,STEP)
Block(3,4,5,STEP)
Block(4,1,-3,BOOKSHELF)
Block(4,1,-2,BOOKSHELF)
Block(4,1,-1,COBBLE_WALL:1,50,COBBLE_WALL,100)
Block(4,1,2,COBBLE_WALL:1,50,COBBLE_WALL,100)
Block(4,1,3,BOOKSHELF)
Block(4,1,4,BOOKSHELF)
Block(4,2,-3,BOOKSHELF)
Block(4,2,-2,BOOKSHELF)
Block(4,2,-1,COBBLE_WALL:1,50,COBBLE_WALL,100)
Block(4,2,2,COBBLE_WALL:1,50,COBBLE_WALL,100)
Block(4,2,3,BOOKSHELF)
Block(4,2,4,BOOKSHELF)
Block(4,3,-3,BOOKSHELF)
Block(4,3,-2,BOOKSHELF)
Block(4,3,-1,COBBLE_WALL:1,50,COBBLE_WALL,100)
Block(4,3,2,COBBLE_WALL:1,50,COBBLE_WALL,100)
Block(4,3,3,BOOKSHELF)
Block(4,3,4,BOOKSHELF)
Block(4,4,-3,STEP)
Block(4,4,-2,STEP)
Block(4,4,-1,STEP)
Block(4,4,0,STEP)
Block(4,4,1,STEP)
Block(4,4,2,STEP)
Block(4,4,3,STEP)
Block(4,4,4,STEP)

Spawner(0,2,0,Witch,1,40,75,4,40)